<?xml version=1.0 ?>
<sdf version='1.6'>
  <model name='SIM_CER_ROBOT'>
    <link name='mobile_base_body_link'>
      <pose frame=''>0 0 0 0 -0 0</pose>
      <inertial>
        <pose frame=''>0.003532 0 0.062803 0 -0 0</pose>
        <mass>14</mass>
        <inertia>
          <ixx>0.342401</ixx>
          <ixy>0</ixy>
          <ixz>-0.0396992</ixz>
          <iyy>0.362542</iyy>
          <iyz>0</iyz>
          <izz>0.168981</izz>
        </inertia>
      </inertial>
      <collision name='mobile_base_body_link_collision'>
        <pose frame=''>0 0 -0.16 0 -0 0</pose>
        <geometry>
          <mesh>
            <scale>0.001 0.001 0.001</scale>
            <uri>model://cer/meshes/obj/sim_cer_mobilebase_body.obj</uri>
          </mesh>
        </geometry>
        <surface>
          <contact>
            <ode/>
          </contact>
          <friction>
            <ode>
              <mu>0</mu>
              <mu2>0</mu2>
            </ode>
          </friction>
        </surface>
      </collision>
      <visual name='mobile_base_body_link_visual'>
        <pose frame=''>0 0 -0.16 0 -0 0</pose>
        <geometry>
          <mesh>
            <scale>0.001 0.001 0.001</scale>
            <uri>model://cer/meshes/obj/sim_cer_mobilebase_body.obj</uri>
          </mesh>
        </geometry>
        <material>
          <script>
            <uri>__default__</uri>
            <name>__default__</name>
          </script>
        </material>
      </visual>
      <velocity_decay/>
      <sensor name='base_laser' type='ray'>
        <always_on>1</always_on>
        <update_rate>40</update_rate>
        <pose frame=''>0.07 0 0.031 0 -0 0</pose>
        <visualize>true</visualize>
        <ray>
          <scan>
            <horizontal>
              <samples>360</samples>
              <resolution>2</resolution>
              <min_angle>0</min_angle>
              <max_angle>6.28</max_angle>
            </horizontal>
          </scan>
          <range>
            <min>0.04</min>
            <max>5</max>
            <resolution>0.01</resolution>
          </range>
          <noise>
            <type>gaussian</type>
            <mean>0</mean>
            <stddev>0.005</stddev>
          </noise>
        </ray>
        <plugin name='lasersensor_front' filename='libgazebo_yarp_lasersensor.so'>
          <yarpConfigurationFile>model://cer/conf/gazebo_cer_lasersensor/gazebo_cer_lasersensor_front.ini</yarpConfigurationFile>
        </plugin>
      </sensor>
      <sensor name='base_laser2' type='ray'>
        <always_on>1</always_on>
        <update_rate>40</update_rate>
        <pose frame=''>-0.085 0 0.031 0 0 3.14159</pose>
        <visualize>true</visualize>
        <ray>
          <scan>
            <horizontal>
              <samples>360</samples>
              <resolution>2</resolution>
              <min_angle>0</min_angle>
              <max_angle>6.28</max_angle>
            </horizontal>
          </scan>
          <range>
            <min>0.04</min>
            <max>5</max>
            <resolution>0.01</resolution>
          </range>
          <noise>
            <type>gaussian</type>
            <mean>0</mean>
            <stddev>0.005</stddev>
          </noise>
        </ray>
        <plugin name='lasersensor_back' filename='libgazebo_yarp_lasersensor.so'>
          <yarpConfigurationFile>model://cer/conf/gazebo_cer_lasersensor/gazebo_cer_lasersensor_back.ini</yarpConfigurationFile>
        </plugin>
      </sensor>
      
      <gravity>1</gravity>
      <velocity_decay/>
    </link>
    <link name='mobile_base_l_tyre_link'>
      <pose frame=''>0 0.139 0 0 -0 0</pose>
      <inertial>
        <pose frame=''>0 0.034425 9e-06 0 -0 0</pose>
        <mass>3</mass>
        <inertia>
          <ixx>0.0200196</ixx>
          <ixy>0</ixy>
          <ixz>0</ixz>
          <iyy>0.0376169</iyy>
          <iyz>-8.28446e-07</iyz>
          <izz>0.0200156</izz>
        </inertia>
      </inertial>
      <collision name='mobile_base_l_tyre_link_collision'>
        <pose frame=''>0 0.03 0 1.5708 -0 0</pose>
        <geometry>
          <cylinder>
            <length>0.005</length>
            <radius>0.16</radius>
          </cylinder>
        </geometry>
      </collision>
      <visual name='mobile_base_l_tyre_link_visual'>
        <pose frame=''>0 -0.139 -0.16 0 -0 0</pose>
        <geometry>
          <mesh>
            <scale>0.001 0.001 0.001</scale>
            <uri>model://cer/meshes/dae/sim_cer_mobilebase_l_tyre.dae</uri>
          </mesh>
        </geometry>
      </visual>
    </link>
    <joint name='mobile_base_l_wheel_joint' type='revolute'>
      <child>mobile_base_l_tyre_link</child>
      <parent>mobile_base_body_link</parent>
      <axis>
        <xyz>0 1 0</xyz>
        <limit>
          <lower>-1e+16</lower>
          <upper>1e+16</upper>
        </limit>
        <dynamics>
          <damping>0.5</damping>
          <friction>0</friction>
          <spring_reference>0</spring_reference>
          <spring_stiffness>0</spring_stiffness>
        </dynamics>
        <use_parent_model_frame>1</use_parent_model_frame>
      </axis>
      <physics>
        <ode>
          <implicit_spring_damper>1</implicit_spring_damper>
          <cfm_damping>1</cfm_damping>
          <limit>
            <cfm>0</cfm>
            <erp>0.2</erp>
          </limit>
        </ode>
      </physics>
    </joint>
    <link name='mobile_base_r_tyre_link'>
      <pose frame=''>0 -0.139 0 0 -0 0</pose>
      <inertial>
        <pose frame=''>0 -0.034425 9e-06 0 -0 0</pose>
        <mass>3</mass>
        <inertia>
          <ixx>0.0200196</ixx>
          <ixy>0</ixy>
          <ixz>0</ixz>
          <iyy>0.0376169</iyy>
          <iyz>8.28101e-07</iyz>
          <izz>0.0200156</izz>
        </inertia>
      </inertial>
      <collision name='mobile_base_r_tyre_link_collision'>
        <pose frame=''>0 -0.03 0 1.5708 -0 0</pose>
        <geometry>
          <cylinder>
            <length>0.005</length>
            <radius>0.16</radius>
          </cylinder>
        </geometry>
      </collision>
      <visual name='mobile_base_r_tyre_link_visual'>
        <pose frame=''>0 0.139 -0.16 0 -0 0</pose>
        <geometry>
          <mesh>
            <scale>0.001 0.001 0.001</scale>
            <uri>model://cer/meshes/dae/sim_cer_mobilebase_r_tyre.dae</uri>
          </mesh>
        </geometry>
      </visual>
    </link>
    <joint name='mobile_base_r_wheel_joint' type='revolute'>
      <child>mobile_base_r_tyre_link</child>
      <parent>mobile_base_body_link</parent>
      <axis>
        <xyz>0 1 0</xyz>
        <limit>
          <lower>-1e+16</lower>
          <upper>1e+16</upper>
        </limit>
        <dynamics>
          <damping>0.5</damping>
          <friction>0</friction>
          <spring_reference>0</spring_reference>
          <spring_stiffness>0</spring_stiffness>
        </dynamics>
        <use_parent_model_frame>1</use_parent_model_frame>
      </axis>
      <physics>
        <ode>
          <implicit_spring_damper>1</implicit_spring_damper>
          <cfm_damping>1</cfm_damping>
          <limit>
            <cfm>0</cfm>
            <erp>0.2</erp>
          </limit>
        </ode>
      </physics>
    </joint>
    <link name='torso_slider_eq_link'>
      <pose frame=''>0.044 0 0.071 0 -0 0</pose>
      <inertial>
        <pose frame=''>0.015175 3e-06 0.244533 0 -0 0</pose>
        <mass>7.5</mass>
        <inertia>
          <ixx>0.0978792</ixx>
          <ixy>-1.83466e-06</ixy>
          <ixz>0.00625726</ixz>
          <iyy>0.0969511</iyy>
          <iyz>0</iyz>
          <izz>0.0746114</izz>
        </inertia>
      </inertial>
      <collision name='torso_slider_eq_link_collision'>
        <pose frame=''>-0.044 0 -0.231 0 -0 0</pose>
        <geometry>
          <mesh>
            <scale>0.001 0.001 0.001</scale>
            <uri>model://cer/meshes/dae/sim_cer_torso_slider_eq.dae</uri>
          </mesh>
        </geometry>
      </collision>
      <visual name='torso_slider_eq_link_visual'>
        <pose frame=''>-0.044 0 -0.231 0 -0 0</pose>
        <geometry>
          <mesh>
            <scale>0.001 0.001 0.001</scale>
            <uri>model://cer/meshes/dae/sim_cer_torso_slider_eq.dae</uri>
          </mesh>
        </geometry>
      </visual>
    </link>
    <joint name='torso_heave_eq_joint' type='prismatic'>
      <child>torso_slider_eq_link</child>
      <parent>mobile_base_body_link</parent>
      <axis>
        <xyz>0 0 1</xyz>
        <limit>
          <lower>0</lower>
          <upper>0.17</upper>
          <effort>1200</effort>
          <velocity>0.5</velocity>
        </limit>
        <dynamics>
          <damping>1000</damping>
          <friction>0</friction>
          <spring_reference>0</spring_reference>
          <spring_stiffness>0</spring_stiffness>
        </dynamics>
        <use_parent_model_frame>1</use_parent_model_frame>
      </axis>
      <physics>
        <ode>
          <implicit_spring_damper>1</implicit_spring_damper>
          <cfm_damping>1</cfm_damping>
          <limit>
            <cfm>0</cfm>
            <erp>0.2</erp>
          </limit>
        </ode>
      </physics>
    </joint>
    <link name='torso_pin_eq_link'>
      <pose frame=''>0.044 0 0.47 -3.14159 -0 0</pose>
      <inertial>
        <pose frame=''>0 0 0 0 -0 0</pose>
        <mass>1.5</mass>
        <inertia>
          <ixx>0.000379688</ixx>
          <ixy>0</ixy>
          <ixz>0</ixz>
          <iyy>0.00143984</iyy>
          <iyz>0</iyz>
          <izz>0.00143984</izz>
        </inertia>
      </inertial>
      <collision name='torso_pin_eq_link_collision'>
        <pose frame=''>0 0 0 0 -0 0</pose>
        <geometry>
          <mesh>
            <scale>0.001 0.001 0.001</scale>
            <uri>model://cer/meshes/dae/sim_cer_torso_pin_eq.dae</uri>
          </mesh>
        </geometry>
      </collision>
      <visual name='torso_pin_eq_link_visual'>
        <pose frame=''>0 0 0 0 -0 0</pose>
        <geometry>
          <mesh>
            <scale>0.001 0.001 0.001</scale>
            <uri>model://cer/meshes/dae/sim_cer_torso_pin_eq.dae</uri>
          </mesh>
        </geometry>
      </visual>
    </link>
    <joint name='torso_roll_eq_joint' type='revolute'>
      <child>torso_pin_eq_link</child>
      <parent>torso_slider_eq_link</parent>
      <axis>
        <xyz>1 0 0</xyz>
        <limit>
          <lower>-0.523599</lower>
          <upper>0.523599</upper>
          <effort>50</effort>
          <velocity>3.14</velocity>
        </limit>
        <dynamics>
          <damping>100</damping>
          <friction>0</friction>
          <spring_reference>0</spring_reference>
          <spring_stiffness>0</spring_stiffness>
        </dynamics>
        <use_parent_model_frame>1</use_parent_model_frame>
      </axis>
      <physics>
        <ode>
          <implicit_spring_damper>1</implicit_spring_damper>
          <cfm_damping>1</cfm_damping>
          <limit>
            <cfm>0</cfm>
            <erp>0.2</erp>
          </limit>
        </ode>
      </physics>
    </joint>
    <link name='torso_platform_link'>
      <pose frame=''>0.044 0 0.47 0 -0 0</pose>
      <inertial>
        <pose frame=''>0 0 0 0 -0 0</pose>
        <mass>1.5</mass>
        <inertia>
          <ixx>0.00153125</ixx>
          <ixy>0</ixy>
          <ixz>0</ixz>
          <iyy>0.00153125</iyy>
          <iyz>0</iyz>
          <izz>0.0030375</izz>
        </inertia>
      </inertial>
      <collision name='torso_platform_link_collision'>
        <pose frame=''>-0.044 0 -0.63 0 -0 0</pose>
        <geometry>
          <mesh>
            <scale>0.001 0.001 0.001</scale>
            <uri>model://cer/meshes/dae/sim_cer_torso_platform.dae</uri>
          </mesh>
        </geometry>
      </collision>
      <visual name='torso_platform_link_visual'>
        <pose frame=''>-0.044 0 -0.63 0 -0 0</pose>
        <geometry>
          <mesh>
            <scale>0.001 0.001 0.001</scale>
            <uri>model://cer/meshes/dae/sim_cer_torso_platform.dae</uri>
          </mesh>
        </geometry>
      </visual>
    </link>
    <joint name='torso_pitch_eq_joint' type='revolute'>
      <child>torso_platform_link</child>
      <parent>torso_pin_eq_link</parent>
      <axis>
        <xyz>0 1 0</xyz>
        <limit>
          <lower>-0.523599</lower>
          <upper>0.523599</upper>
          <effort>50</effort>
          <velocity>3.14</velocity>
        </limit>
        <dynamics>
          <damping>100</damping>
          <friction>0</friction>
          <spring_reference>0</spring_reference>
          <spring_stiffness>0</spring_stiffness>
        </dynamics>
        <use_parent_model_frame>1</use_parent_model_frame>
      </axis>
      <physics>
        <ode>
          <implicit_spring_damper>1</implicit_spring_damper>
          <cfm_damping>1</cfm_damping>
          <limit>
            <cfm>0</cfm>
            <erp>0.2</erp>
          </limit>
        </ode>
      </physics>
    </joint>
    <link name='chest_link'>
      <pose frame=''>0.044 0 0.47 0 -0 0</pose>
      <inertial>
        <pose frame=''>-0.033031 0 0.220198 0 -0 0</pose>
        <mass>13</mass>
        <inertia>
          <ixx>0.275816</ixx>
          <ixy>0</ixy>
          <ixz>0.0564476</ixz>
          <iyy>0.253579</iyy>
          <iyz>0</iyz>
          <izz>0.127156</izz>
        </inertia>
      </inertial>
      <collision name='chest_link_collision'>
        <pose frame=''>-0.044 0 -0.63 0 -0 0</pose>
        <geometry>
          <mesh>
            <scale>0.001 0.001 0.001</scale>
            <uri>model://cer/meshes/dae/sim_cer_chest.dae</uri>
          </mesh>
        </geometry>
      </collision>
      <visual name='chest_link_visual'>
        <pose frame=''>-0.044 0 -0.63 0 -0 0</pose>
        <geometry>
          <mesh>
            <scale>0.001 0.001 0.001</scale>
            <uri>model://cer/meshes/dae/sim_cer_chest.dae</uri>
          </mesh>
        </geometry>
      </visual>
    </link>
    <joint name='torso_yaw_joint' type='revolute'>
      <child>chest_link</child>
      <parent>torso_platform_link</parent>
      <axis>
        <xyz>-0 -0 1</xyz>
        <limit>
          <lower>-1.0472</lower>
          <upper>1.0472</upper>
          <effort>30</effort>
          <velocity>3.14</velocity>
        </limit>
        <dynamics>
          <damping>10</damping>
          <friction>0</friction>
          <spring_reference>0</spring_reference>
          <spring_stiffness>0</spring_stiffness>
        </dynamics>
        <use_parent_model_frame>1</use_parent_model_frame>
      </axis>
      <physics>
        <ode>
          <implicit_spring_damper>1</implicit_spring_damper>
          <cfm_damping>1</cfm_damping>
          <limit>
            <cfm>0</cfm>
            <erp>0.2</erp>
          </limit>
        </ode>
      </physics>
    </joint>
    <link name='neck_link'>
      <pose frame=''>-0.05 -0 0.87 0 -0 0</pose>
      <inertial>
        <pose frame=''>-0.000322 0 0.07756 0 -0 0</pose>
        <mass>1.4</mass>
        <inertia>
          <ixx>0.00429793</ixx>
          <ixy>0</ixy>
          <ixz>-0.000592817</ixz>
          <iyy>0.00443784</iyy>
          <iyz>-6.85477e-08</iyz>
          <izz>0.000419904</izz>
        </inertia>
      </inertial>
      <collision name='neck_link_collision'>
        <pose frame=''>0.05 0 -1.03 0 -0 0</pose>
        <geometry>
          <mesh>
            <scale>0.001 0.001 0.001</scale>
            <uri>model://cer/meshes/dae/sim_cer_neck.dae</uri>
          </mesh>
        </geometry>
      </collision>
      <visual name='neck_link_visual'>
        <pose frame=''>0.05 0 -1.03 0 -0 0</pose>
        <geometry>
          <mesh>
            <scale>0.001 0.001 0.001</scale>
            <uri>model://cer/meshes/dae/sim_cer_neck.dae</uri>
          </mesh>
        </geometry>
      </visual>
    </link>
    <joint name='neck_pitch_joint' type='revolute'>
      <child>neck_link</child>
      <parent>chest_link</parent>
      <axis>
        <xyz>0 1 0</xyz>
        <limit>
          <lower>-0.523599</lower>
          <upper>0.872665</upper>
          <effort>10</effort>
          <velocity>3.14</velocity>
        </limit>
        <dynamics>
          <damping>10</damping>
          <friction>0</friction>
          <spring_reference>0</spring_reference>
          <spring_stiffness>0</spring_stiffness>
        </dynamics>
        <use_parent_model_frame>1</use_parent_model_frame>
      </axis>
      <physics>
        <ode>
          <implicit_spring_damper>1</implicit_spring_damper>
          <cfm_damping>1</cfm_damping>
          <limit>
            <cfm>0</cfm>
            <erp>0.2</erp>
          </limit>
        </ode>
      </physics>
    </joint>
    <link name='head_link'>
      <pose frame=''>-0.038321 -0 1.02838 0 -0 0</pose>
      <inertial>
        <pose frame=''>0.030149 -2e-06 -0.00035 0 -0 0</pose>
        <mass>2</mass>
        <inertia>
          <ixx>0.0106536</ixx>
          <ixy>-7.34817e-08</ixy>
          <ixz>0.000274098</ixz>
          <iyy>0.00398482</iyy>
          <iyz>1.64063e-07</iyz>
          <izz>0.00944369</izz>
        </inertia>
      </inertial>
      <collision name='head_link_collision'>
        <pose frame=''>0.038321 0 -1.18838 0 -0 0</pose>
        <geometry>
          <mesh>
            <scale>0.001 0.001 0.001</scale>
            <uri>model://cer/meshes/dae/sim_cer_head.dae</uri>
          </mesh>
        </geometry>
        <surface>
          <contact>
            <ode/>
          </contact>
          <friction>
            <ode/>
          </friction>
        </surface>
      </collision>
      <visual name='head_link_visual'>
        <pose frame=''>0.038321 0 -1.18838 0 -0 0</pose>
        <geometry>
          <mesh>
            <scale>0.001 0.001 0.001</scale>
            <uri>model://cer/meshes/dae/sim_cer_head.dae</uri>
          </mesh>
        </geometry>
        <material>
          <script>
            <uri>__default__</uri>
            <name>__default__</name>
          </script>
        </material>
      </visual>
      <velocity_decay/>
      <sensor name='multicamera_sensor' type='multicamera'>
        <always_on>1</always_on>
        <update_rate>30</update_rate>
        <pose frame=''>0.052167 0 -0.06748 -1.5708 -0 -1.5708</pose>
        <camera name='left_camera'>
          <pose frame=''>-0.0325 0 0 -1.57079 -1.57079 3.14159</pose>
          <horizontal_fov>1.5708</horizontal_fov>
          <image>
            <width>640</width>
            <height>480</height>
          </image>
          <clip>
            <near>0.1</near>
            <far>100</far>
          </clip>
        </camera>
        <camera name='right_camera'>
          <pose frame=''>0.0325 0 0 -1.57079 -1.57079 3.14159</pose>
          <horizontal_fov>1.5708</horizontal_fov>
          <image>
            <width>640</width>
            <height>480</height>
          </image>
          <clip>
            <near>0.1</near>
            <far>100</far>
          </clip>
        </camera>
        <plugin name='multicamera_plugin' filename='libgazebo_yarp_multicamera.so'>
          <yarpConfigurationFile>model://cer/conf/gazebo_cer_multicamera.ini</yarpConfigurationFile>
        </plugin>
      </sensor>
      <velocity_decay/>
      <sensor name='asus_xtion_depth' type='depth'>
        <always_on>1</always_on>
        <update_rate>30</update_rate>
        <pose frame=''>0.059881 0.044487 0.04402 -1.5708 -0 -1.5708</pose>
        <camera name='asus_xtion_depth_camera'>
          <pose frame=''>0 0 0 -1.57079 -1.57079 3.14159</pose>
          <horizontal_fov>1.02259</horizontal_fov>
          <distortion>
            <k1>0</k1>
            <k2>0</k2>
            <k3>0</k3>
            <p1>0</p1>
            <p2>0</p2>
            <center>319.5 239.5</center>
          </distortion>
          <image>
            <width>640</width>
            <height>480</height>
            <format>R8G8B8</format>
          </image>
          <clip>
            <near>0.02</near>
            <far>3000</far>
          </clip>
        </camera>
        <plugin name='depth_camera_plugin' filename='libgazebo_yarp_depthCamera.so'>
          <yarpConfigurationFile>model://cer/conf/gazebo_cer_depthcamera/gazebo_cer_depthcamera.ini</yarpConfigurationFile>
        </plugin>
      </sensor>
      <gravity>1</gravity>
      <velocity_decay/>
      <sensor name='asus_xtion_rgb' type='camera'>
        <always_on>1</always_on>
        <update_rate>30</update_rate>
        <pose frame=''>0.059881 0.018487 0.04402 -1.5708 -0 -1.5708</pose>
        <camera name='asus_xtion_rgb_camera'>
          <pose frame=''>0 0 0 -1.57079 -1.57079 3.14159</pose>
          <horizontal_fov>1.02259</horizontal_fov>
          <distortion>
            <k1>0</k1>
            <k2>0</k2>
            <k3>0</k3>
            <p1>0</p1>
            <p2>0</p2>
            <center>319.5 239.5</center>
          </distortion>
          <image>
            <width>640</width>
            <height>480</height>
            <format>R8G8B8</format>
          </image>
          <clip>
            <near>0.02</near>
            <far>3000</far>
          </clip>
        </camera>
        <plugin name='xtion_camera_rgb_plugin' filename='libgazebo_yarp_camera.so'>
          <yarpConfigurationFile>model://cer/conf/gazebo_cer_xtion_camera_rgb.ini</yarpConfigurationFile>
        </plugin>
      </sensor>
    </link>
    <joint name='neck_yaw_joint' type='revolute'>
      <child>head_link</child>
      <parent>neck_link</parent>
      <axis>
        <xyz>0.173648 -0 0.984808</xyz>
        <limit>
          <lower>-1.39626</lower>
          <upper>1.39626</upper>
          <effort>10</effort>
          <velocity>3.14</velocity>
        </limit>
        <dynamics>
          <damping>10</damping>
          <friction>0</friction>
          <spring_reference>0</spring_reference>
          <spring_stiffness>0</spring_stiffness>
        </dynamics>
        <use_parent_model_frame>1</use_parent_model_frame>
      </axis>
      <physics>
        <ode>
          <implicit_spring_damper>1</implicit_spring_damper>
          <cfm_damping>1</cfm_damping>
          <limit>
            <cfm>0</cfm>
            <erp>0.2</erp>
          </limit>
        </ode>
      </physics>
    </joint>
    <plugin name='controlboard_torso' filename='libgazebo_yarp_controlboard.so'>
      <yarpConfigurationFile>model://cer/conf/gazebo_cer_torso/gazebo_cer_torso.ini</yarpConfigurationFile>
    </plugin>
    <plugin name='controlboard_torso_tripod' filename='libgazeboTripod.so'>
      <yarpConfigurationFile>model://cer/conf/gazebo_cer_torso/gazebo_cer_torso_tripod.ini</yarpConfigurationFile>
    </plugin>
    <plugin name='controlboard_head' filename='libgazebo_yarp_controlboard.so'>
      <yarpConfigurationFile>model://cer/conf/gazebo_cer_head/gazebo_cer_head.ini</yarpConfigurationFile>
    </plugin>
    <plugin name='controlboard_mobile_base' filename='libgazebo_yarp_controlboard.so'>
      <yarpConfigurationFile>model://cer/conf/gazebo_cer_mobile_base/gazebo_cer_mobile_base.ini</yarpConfigurationFile>
    </plugin>
    <plugin name='world_interface' filename='libgazebo_yarp_worldinterface.so'>
      <yarpConfigurationFile>model://cer/conf/worldInterface.ini</yarpConfigurationFile>
    </plugin>
    <plugin name='double_laser' filename='libgazebo_yarp_doublelaser.so'>
      <yarpConfigurationFile>model://cer/conf/gazebo_cer_doublelaser/gazebo_cer_doublelaser.ini</yarpConfigurationFile>
    </plugin>
    <plugin name="robotinterface" filename="libgazebo_yarp_robotinterface.so">
      <yarpRobotInterfaceConfigurationFile>model://cer_no_arms/cer_no_arms.xml</yarpRobotInterfaceConfigurationFile>
    </plugin>
    <static>0</static>
    <pose frame=''>0 0 0.16 0 -0 0</pose>
  </model>
</sdf>
