<?xml version="1.0"?>
<robot name="SIM_CER_ROBOT">
  <link name="mobile_base_body">
    <inertial>
      <origin xyz="0 0 0.16" rpy="0 0 0"/>
      <mass value="4.0"/>
      <inertia ixx="0.051025" ixy="0.0" ixz="0.0" iyy="0.04205" iyz="0.0" izz="0.051025"/>
    </inertial>
    <visual>
      <origin xyz="0 0 0" rpy="0 0 0"/>
      <geometry>
        <mesh filename="package://urdf_tutorial/cer/meshes/dae/colorful_fixed/sim_cer_mobilebase_body_prt.dae" scale="0.001 0.001 0.001"/>
      </geometry>
      <material name="green">
        <color rgba="0 1 0 1"/>
      </material>
    </visual>
    <collision>
      <origin xyz="0 0 0" rpy="0 0 0"/>
      <geometry>
        <mesh filename="package://urdf_tutorial/cer/meshes/dae/colorful_fixed/sim_cer_mobilebase_body_prt.dae" scale="0.001 0.001 0.001"/>
      </geometry>
    </collision>
  </link>
  <link name="base_link"/>
  <joint name="base_link_fixed_joint" type="fixed">
    <origin xyz="0 0 0.16" rpy="0 0 0"/>
    <parent link="mobile_base_body"/>
    <child link="base_link"/>
    <dynamics damping="0.1"/>
  </joint>
  <link name="mobile_base_l_tyre">
    <inertial>
      <origin xyz="0 0.03 0" rpy="0 0 0"/>
      <mass value="3.0"/>
      <inertia ixx="0.0201" ixy="0.0" ixz="0.0" iyy="0.0384" iyz="0.0" izz="0.0201"/>
    </inertial>
    <visual>
      <origin xyz="0 -0.15 -0.16" rpy="0 0 0"/>
      <geometry>
        <mesh filename="package://urdf_tutorial/cer/meshes/dae/colorful_fixed/sim_cer_mobilebase_l_tyre_prt.dae" scale="0.001 0.001 0.001"/>
      </geometry>
      <material name="black">
        <color rgba="0 0 0 1"/>
      </material>
    </visual>
    <collision>
      <origin xyz="0 -0.15 -0.16" rpy="0 0 0"/>
      <geometry>
        <mesh filename="package://urdf_tutorial/cer/meshes/dae/colorful_fixed/sim_cer_mobilebase_l_tyre_prt.dae" scale="0.001 0.001 0.001"/>
      </geometry>
    </collision>
  </link>
  <joint name="mobile_base_l_wheel" type="continuous">
    <origin xyz="0 0.15 0.16" rpy="0 0 0"/>
    <axis xyz="0.0 1.0 0.0"/>
    <parent link="mobile_base_body"/>
    <child link="mobile_base_l_tyre"/>
    <dynamics damping="0.1"/>
  </joint>
  <link name="mobile_base_r_tyre">
    <inertial>
      <origin xyz="0 -0.03 0" rpy="0 0 0"/>
      <mass value="3.0"/>
      <inertia ixx="0.0201" ixy="0.0" ixz="0.0" iyy="0.0384" iyz="0.0" izz="0.0201"/>
    </inertial>
    <visual>
      <origin xyz="0 0.15 -0.16" rpy="0 0 0"/>
      <geometry>
        <mesh filename="package://urdf_tutorial/cer/meshes/dae/colorful_fixed/sim_cer_mobilebase_r_tyre_prt.dae" scale="0.001 0.001 0.001"/>
      </geometry>
      <material name="red">
        <color rgba="1 0 0 1"/>
      </material>
    </visual>
    <collision>
      <origin xyz="0 0.15 -0.16" rpy="0 0 0"/>
      <geometry>
        <mesh filename="package://urdf_tutorial/cer/meshes/dae/colorful_fixed/sim_cer_mobilebase_r_tyre_prt.dae" scale="0.001 0.001 0.001"/>
      </geometry>
    </collision>
  </link>
  <joint name="mobile_base_r_wheel" type="continuous">
    <origin xyz="0 -0.15 0.16" rpy="0 0 0"/>
    <axis xyz="0.0 1.0 0.0"/>
    <parent link="mobile_base_body"/>
    <child link="mobile_base_r_tyre"/>
    <dynamics damping="0.1"/>
  </joint>
  <link name="torso_tripod_slider_dummy">
    <inertial>
      <origin xyz="0 0 0.204" rpy="0 0 0"/>
      <mass value="5.0"/>
      <inertia ixx="0.0801667" ixy="0.0" ixz="0.0" iyy="0.0801667" iyz="0.0" izz="0.02025"/>
    </inertial>
    <visual>
      <origin xyz="-0.074 0 -0.221" rpy="0 0 0"/>
      <geometry>
        <mesh filename="package://urdf_tutorial/cer/meshes/dae/colorful_fixed/sim_cer_torso_tripod_slider_prt.dae" scale="0.001 0.001 0.001"/>
      </geometry>
      <material name="blue">
        <color rgba="0 0 1 1"/>
      </material>
    </visual>
    <collision>
      <origin xyz="-0.074 0 -0.221" rpy="0 0 0"/>
      <geometry>
        <mesh filename="package://urdf_tutorial/cer/meshes/dae/colorful_fixed/sim_cer_torso_tripod_slider_prt.dae" scale="0.001 0.001 0.001"/>
      </geometry>
    </collision>
  </link>
  <joint name="torso_tripod_heave_dummy" type="prismatic">
    <origin xyz="0.074 0 0.221" rpy="0 0 0"/>
    <axis xyz="0.0 0.0 1.0"/>
    <parent link="mobile_base_body"/>
    <child link="torso_tripod_slider_dummy"/>
    <limit effort="50000" lower="-0.05" upper="0.15" velocity="50000"/>
    <dynamics damping="0.1"/>
  </joint>
  <link name="torso_tripod_pin_dummy">
    <inertial>
      <origin xyz="0 0 0" rpy="0 0 0"/>
      <mass value="0.0883573"/>
      <inertia ixx="9.9402e-06" ixy="0.0" ixz="0.0" iyy="7.86012e-05" iyz="0.0" izz="7.86012e-05"/>
    </inertial>
    <visual>
      <origin xyz="0 0 0" rpy="0 0 0"/>
      <geometry>
        <mesh filename="package://urdf_tutorial/cer/meshes/dae/sim_cer_torso_tripod_pin_dummy_prt.dae" scale="0.001 0.001 0.001"/>
      </geometry>
      <material name="yellow">
        <color rgba="1 1 0 1"/>
      </material>
    </visual>
    <collision>
      <origin xyz="0 0 0" rpy="0 0 0"/>
      <geometry>
        <mesh filename="package://urdf_tutorial/cer/meshes/dae/sim_cer_torso_tripod_pin_dummy_prt.dae" scale="0.001 0.001 0.001"/>
      </geometry>
    </collision>
  </link>
  <joint name="torso_tripod_roll_dummy" type="revolute">
    <origin xyz="0 0 0.409" rpy="3.141592653589793 0 0"/>
    <axis xyz="1.0 0.0 0.0"/>
    <parent link="torso_tripod_slider_dummy"/>
    <child link="torso_tripod_pin_dummy"/>
    <limit effort="50000" lower="-0.5235987755982988" upper="0.5235987755982988" velocity="50000"/>
    <dynamics damping="0.1"/>
  </joint>
  <link name="torso_tripod_platform">
    <inertial>
      <origin xyz="0 0 0" rpy="0 0 0"/>
      <mass value="0.131528"/>
      <inertia ixx="0.000134268" ixy="0.0" ixz="0.0" iyy="0.000134268" iyz="0.0" izz="0.000266343"/>
    </inertial>
    <visual>
      <origin xyz="-0.074 0 -0.63" rpy="0 0 0"/>
      <geometry>
        <mesh filename="package://urdf_tutorial/cer/meshes/dae/sim_cer_torso_tripod_platform_prt.dae" scale="0.001 0.001 0.001"/>
      </geometry>
      <material name="pink">
        <color rgba="1 0 1 1"/>
      </material>
    </visual>
    <collision>
      <origin xyz="-0.074 0 -0.63" rpy="0 0 0"/>
      <geometry>
        <mesh filename="package://urdf_tutorial/cer/meshes/dae/sim_cer_torso_tripod_platform_prt.dae" scale="0.001 0.001 0.001"/>
      </geometry>
    </collision>
  </link>
  <joint name="torso_tripod_pitch_dummy" type="revolute">
    <origin xyz="0 0 0" rpy="3.141592653589793 0 0"/>
    <axis xyz="0.0 1.0 0.0"/>
    <parent link="torso_tripod_pin_dummy"/>
    <child link="torso_tripod_platform"/>
    <limit effort="50000" lower="-0.5235987755982988" upper="0.5235987755982988" velocity="50000"/>
    <dynamics damping="0.1"/>
  </joint>
  <link name="oriented_xfw_ylf_zup_torso_tripod_platform"/>
  <joint name="oriented_xfw_ylf_zup_torso_tripod_platform_fixed_joint" type="fixed">
    <origin xyz="0 0 0" rpy="0 0 0"/>
    <parent link="torso_tripod_platform"/>
    <child link="oriented_xfw_ylf_zup_torso_tripod_platform"/>
    <dynamics damping="0.1"/>
  </joint>
  <link name="oriented_xbk_yrg_zup_torso_tripod_platform"/>
  <joint name="oriented_xbk_yrg_zup_torso_tripod_platform_fixed_joint" type="fixed">
    <origin xyz="0 0 0" rpy="0 0 3.141592653589793"/>
    <parent link="torso_tripod_platform"/>
    <child link="oriented_xbk_yrg_zup_torso_tripod_platform"/>
    <dynamics damping="0.1"/>
  </joint>
  <link name="torso_chest">
    <inertial>
      <origin xyz="-0.0195 0 0.189068" rpy="0 0 0"/>
      <mass value="10.0"/>
      <inertia ixx="0.143904" ixy="0.0" ixz="0.0" iyy="0.106565" iyz="0.0" izz="0.0650742"/>
    </inertial>
    <visual>
      <origin xyz="-0.074 0 -0.63" rpy="0 0 0"/>
      <geometry>
        <mesh filename="package://urdf_tutorial/cer/meshes/dae/colorful_fixed/sim_cer_torso_chest_prt.dae" scale="0.001 0.001 0.001"/>
      </geometry>
      <material name="cyan">
        <color rgba="0 1 1 1"/>
      </material>
    </visual>
    <collision>
      <origin xyz="-0.074 0 -0.63" rpy="0 0 0"/>
      <geometry>
        <mesh filename="package://urdf_tutorial/cer/meshes/dae/colorful_fixed/sim_cer_torso_chest_prt.dae" scale="0.001 0.001 0.001"/>
      </geometry>
    </collision>
  </link>
  <joint name="torso_yaw" type="revolute">
    <origin xyz="0 0 0" rpy="0 0 0"/>
    <axis xyz="0.0 0.0 1.0"/>
    <parent link="torso_tripod_platform"/>
    <child link="torso_chest"/>
    <limit effort="50000" lower="-1.5707963267948966" upper="1.5707963267948966" velocity="50000"/>
    <dynamics damping="0.1"/>
  </joint>
  <link name="torso"/>
  <joint name="torso_fixed_joint" type="fixed">
    <origin xyz="-0.042 0 0.17" rpy="0 0 0"/>
    <parent link="torso_chest"/>
    <child link="torso"/>
    <dynamics damping="0.1"/>
  </joint>
  <link name="l_clavicle">
    <inertial>
      <origin xyz="0 0 0" rpy="0 0 0"/>
      <mass value="0.0793454"/>
      <inertia ixx="1.92382e-05" ixy="0.0" ixz="0.0" iyy="1.95373e-05" iyz="0.0" izz="1.95373e-05"/>
    </inertial>
    <visual>
      <origin xyz="0.01 -0.157 -0.97" rpy="0 0 0"/>
      <geometry>
        <mesh filename="package://urdf_tutorial/cer/meshes/dae/sim_cer_l_clavicle_prt.dae" scale="0.001 0.001 0.001"/>
      </geometry>
      <material name="green"/>
    </visual>
    <collision>
      <origin xyz="0.01 -0.157 -0.97" rpy="0 0 0"/>
      <geometry>
        <mesh filename="package://urdf_tutorial/cer/meshes/dae/sim_cer_l_clavicle_prt.dae" scale="0.001 0.001 0.001"/>
      </geometry>
    </collision>
  </link>
  <joint name="l_shoulder_pitch" type="revolute">
    <origin xyz="-0.084 0.157 0.34" rpy="0 0 0"/>
    <axis xyz="0.0 -0.984808 -0.173648"/>
    <parent link="torso_chest"/>
    <child link="l_clavicle"/>
    <limit effort="50000" lower="-0.3490658503988659" upper="1.7453292519943295" velocity="50000"/>
    <dynamics damping="0.1"/>
  </joint>
  <link name="l_shoulder">
    <inertial>
      <origin xyz="0 0.034 -0.055" rpy="0 0 0"/>
      <mass value="1.0"/>
      <inertia ixx="0.00140833" ixy="0.0" ixz="0.0" iyy="0.00140833" iyz="0.0" izz="0.0008"/>
    </inertial>
    <visual>
      <origin xyz="0.01 -0.157 -0.97" rpy="0 0 0"/>
      <geometry>
        <mesh filename="package://urdf_tutorial/cer/meshes/dae/sim_cer_l_shoulder_prt.dae" scale="0.001 0.001 0.001"/>
      </geometry>
      <material name="white">
        <color rgba="1 1 1 1"/>
      </material>
    </visual>
    <collision>
      <origin xyz="0.01 -0.157 -0.97" rpy="0 0 0"/>
      <geometry>
        <mesh filename="package://urdf_tutorial/cer/meshes/dae/sim_cer_l_shoulder_prt.dae" scale="0.001 0.001 0.001"/>
      </geometry>
    </collision>
  </link>
  <joint name="l_shoulder_roll" type="revolute">
    <origin xyz="0 0 0" rpy="0 0 0"/>
    <axis xyz="1.0 0.0 0.0"/>
    <parent link="l_clavicle"/>
    <child link="l_shoulder"/>
    <limit effort="50000" lower="-0.17453292519943295" upper="1.7453292519943295" velocity="50000"/>
    <dynamics damping="0.1"/>
  </joint>
  <link name="l_upperarm">
    <inertial>
      <origin xyz="0 0 -0.0705" rpy="0 0 0"/>
      <mass value="1.0"/>
      <inertia ixx="0.00200831" ixy="0.0" ixz="0.0" iyy="0.00200831" iyz="0.0" izz="0.000703125"/>
    </inertial>
    <visual>
      <origin xyz="0.01 -0.191 -0.86" rpy="0 0 0"/>
      <geometry>
        <mesh filename="package://urdf_tutorial/cer/meshes/dae/sim_cer_l_upperarm_prt.dae" scale="0.001 0.001 0.001"/>
      </geometry>
      <material name="dblue">
        <color rgba="0 0 0.8 1"/>
      </material>
    </visual>
    <collision>
      <origin xyz="0.01 -0.191 -0.86" rpy="0 0 0"/>
      <geometry>
        <mesh filename="package://urdf_tutorial/cer/meshes/dae/sim_cer_l_upperarm_prt.dae" scale="0.001 0.001 0.001"/>
      </geometry>
    </collision>
  </link>
  <joint name="l_shoulder_yaw" type="revolute">
    <origin xyz="0 0.034 -0.11" rpy="0 0 0"/>
    <axis xyz="0.0 0.0 1.0"/>
    <parent link="l_shoulder"/>
    <child link="l_upperarm"/>
    <limit effort="50000" lower="-1.5707963267948966" upper="1.5707963267948966" velocity="50000"/>
    <dynamics damping="0.1"/>
  </joint>
  <link name="l_forearm">
    <inertial>
      <origin xyz="0 0 -0.0355" rpy="0 0 0"/>
      <mass value="0.5"/>
      <inertia ixx="0.000363167" ixy="0.0" ixz="0.0" iyy="0.000363167" iyz="0.0" izz="0.00030625"/>
    </inertial>
    <visual>
      <origin xyz="0.01 -0.191 -0.719" rpy="0 0 0"/>
      <geometry>
        <mesh filename="package://urdf_tutorial/cer/meshes/dae/sim_cer_l_forearm_prt.dae" scale="0.001 0.001 0.001"/>
      </geometry>
      <material name="dgreen">
        <color rgba="0.1 0.8 0.1 1"/>
      </material>
    </visual>
    <collision>
      <origin xyz="0.01 -0.191 -0.719" rpy="0 0 0"/>
      <geometry>
        <mesh filename="package://urdf_tutorial/cer/meshes/dae/sim_cer_l_forearm_prt.dae" scale="0.001 0.001 0.001"/>
      </geometry>
    </collision>
  </link>
  <joint name="l_elbow" type="revolute">
    <origin xyz="0 0 -0.141" rpy="0 0 0"/>
    <axis xyz="0.0 -1.0 0.0"/>
    <parent link="l_upperarm"/>
    <child link="l_forearm"/>
    <limit effort="50000" lower="0.0" upper="2.443460952792061" velocity="50000"/>
    <dynamics damping="0.1"/>
  </joint>
  <link name="l_wrist_tripod_base">
    <inertial>
      <origin xyz="0 0 0" rpy="0 0 0"/>
      <mass value="0.0795216"/>
      <inertia ixx="4.09205e-05" ixy="0.0" ixz="0.0" iyy="4.09205e-05" iyz="0.0" izz="8.05156e-05"/>
    </inertial>
    <visual>
      <origin xyz="0.01 -0.191 -0.648" rpy="0 0 0"/>
      <geometry>
        <mesh filename="package://urdf_tutorial/cer/meshes/dae/sim_cer_l_wrist_tripod_base_prt.dae" scale="0.001 0.001 0.001"/>
      </geometry>
      <material name="gray">
        <color rgba="0.5 0.5 0.5 1"/>
      </material>
    </visual>
    <collision>
      <origin xyz="0.01 -0.191 -0.648" rpy="0 0 0"/>
      <geometry>
        <mesh filename="package://urdf_tutorial/cer/meshes/dae/sim_cer_l_wrist_tripod_base_prt.dae" scale="0.001 0.001 0.001"/>
      </geometry>
    </collision>
  </link>
  <joint name="l_wrist_prosupination" type="revolute">
    <origin xyz="0 0 -0.071" rpy="0 0 0"/>
    <axis xyz="0.0 0.0 1.0"/>
    <parent link="l_forearm"/>
    <child link="l_wrist_tripod_base"/>
    <limit effort="50000" lower="-1.5707963267948966" upper="1.5707963267948966" velocity="50000"/>
    <dynamics damping="0.1"/>
  </joint>
  <link name="oriented_l_wrist_tripodbase"/>
  <joint name="oriented_l_wrist_tripodbase_fixed_joint" type="fixed">
    <origin xyz="0 0 0" rpy="3.141592653589793 0 -1.5707963267948966"/>
    <parent link="l_wrist_tripod_base"/>
    <child link="oriented_l_wrist_tripodbase"/>
    <dynamics damping="0.1"/>
  </joint>
  <link name="l_wrist_tripod_slider_dummy">
    <inertial>
      <origin xyz="0 0 -0.181" rpy="0 0 0"/>
      <mass value="0.2"/>
      <inertia ixx="0.000886667" ixy="0.0" ixz="0.0" iyy="0.000886667" iyz="0.0" izz="0.00016"/>
    </inertial>
    <visual>
      <origin xyz="0.01 -0.191 -0.719" rpy="0 0 0"/>
      <geometry>
        <mesh filename="package://urdf_tutorial/cer/meshes/dae/sim_cer_l_wrist_tripod_slider_prt.dae" scale="0.001 0.001 0.001"/>
      </geometry>
      <material name="green"/>
    </visual>
    <collision>
      <origin xyz="0.01 -0.191 -0.719" rpy="0 0 0"/>
      <geometry>
        <mesh filename="package://urdf_tutorial/cer/meshes/dae/sim_cer_l_wrist_tripod_slider_prt.dae" scale="0.001 0.001 0.001"/>
      </geometry>
    </collision>
  </link>
  <joint name="l_wrist_tripod_heave_dummy" type="prismatic">
    <origin xyz="0 0 0.071" rpy="0 0 0"/>
    <axis xyz="0.0 0.0 -1.0"/>
    <parent link="l_wrist_tripod_base"/>
    <child link="l_wrist_tripod_slider_dummy"/>
    <limit effort="50000" lower="0.0" upper="0.12" velocity="50000"/>
    <dynamics damping="0.1"/>
  </joint>
  <link name="l_wrist_tripod_pin_dummy">
    <inertial>
      <origin xyz="0 0 0" rpy="0 0 0"/>
      <mass value="0.0314159"/>
      <inertia ixx="1.75406e-05" ixy="0.0" ixz="0.0" iyy="1.75406e-05" iyz="0.0" izz="1.5708e-06"/>
    </inertial>
    <visual>
      <origin xyz="0 0 0" rpy="0 0 0"/>
      <geometry>
        <mesh filename="package://urdf_tutorial/cer/meshes/dae/sim_cer_l_wrist_tripod_pin_prt.dae" scale="0.001 0.001 0.001"/>
      </geometry>
      <material name="black"/>
    </visual>
    <collision>
      <origin xyz="0 0 0" rpy="0 0 0"/>
      <geometry>
        <mesh filename="package://urdf_tutorial/cer/meshes/dae/sim_cer_l_wrist_tripod_pin_prt.dae" scale="0.001 0.001 0.001"/>
      </geometry>
    </collision>
  </link>
  <joint name="l_wrist_tripod_roll_dummy" type="revolute">
    <origin xyz="0 0 -0.291" rpy="3.141592653589793 1.5707963267948966 0"/>
    <axis xyz="0.0 0.0 -1.0"/>
    <parent link="l_wrist_tripod_slider_dummy"/>
    <child link="l_wrist_tripod_pin_dummy"/>
    <limit effort="50000" lower="-0.5235987755982988" upper="0.5235987755982988" velocity="50000"/>
    <dynamics damping="0.1"/>
  </joint>
  <link name="l_hand">
    <inertial>
      <origin xyz="0 0.001 -0.029806" rpy="0 0 0"/>
      <mass value="0.5"/>
      <inertia ixx="0.000273315" ixy="0.0" ixz="0.0" iyy="0.000273315" iyz="0.0" izz="0.000141352"/>
    </inertial>
    <visual>
      <origin xyz="0.01 -0.19 -0.428" rpy="0 0 0"/>
      <geometry>
        <mesh filename="package://urdf_tutorial/cer/meshes/dae/sim_cer_l_hand_prt.dae" scale="0.001 0.001 0.001"/>
      </geometry>
      <material name="red"/>
    </visual>
    <collision>
      <origin xyz="0.01 -0.19 -0.428" rpy="0 0 0"/>
      <geometry>
        <mesh filename="package://urdf_tutorial/cer/meshes/dae/sim_cer_l_hand_prt.dae" scale="0.001 0.001 0.001"/>
      </geometry>
    </collision>
  </link>
  <joint name="l_wrist_tripod_pitch_dummy" type="revolute">
    <origin xyz="0 0.001 0" rpy="3.141592653589793 1.5707963267948966 0"/>
    <axis xyz="0.0 -1.0 0.0"/>
    <parent link="l_wrist_tripod_pin_dummy"/>
    <child link="l_hand"/>
    <limit effort="50000" lower="-0.5235987755982988" upper="0.5235987755982988" velocity="50000"/>
    <dynamics damping="0.1"/>
  </joint>
  <link name="l_wrist"/>
  <joint name="l_wrist_fixed_joint" type="fixed">
    <origin xyz="0 0.001 0" rpy="0 0 0"/>
    <parent link="l_hand"/>
    <child link="l_wrist"/>
    <dynamics damping="0.1"/>
  </joint>
  <link name="l_gripper"/>
  <joint name="l_gripper_fixed_joint" type="fixed">
    <origin xyz="0 0.001 -0.065" rpy="-1.5707963267948961 1.570796326794896 0"/>
    <parent link="l_hand"/>
    <child link="l_gripper"/>
    <dynamics damping="0.1"/>
  </joint>
  <link name="r_clavicle">
    <inertial>
      <origin xyz="0 0 0" rpy="0 0 0"/>
      <mass value="0.0793454"/>
      <inertia ixx="1.92382e-05" ixy="0.0" ixz="0.0" iyy="1.95373e-05" iyz="0.0" izz="1.95373e-05"/>
    </inertial>
    <visual>
      <origin xyz="0.01 0.157 -0.97" rpy="0 0 0"/>
      <geometry>
        <mesh filename="package://urdf_tutorial/cer/meshes/dae/sim_cer_r_clavicle_prt.dae" scale="0.001 0.001 0.001"/>
      </geometry>
      <material name="blue"/>
    </visual>
    <collision>
      <origin xyz="0.01 0.157 -0.97" rpy="0 0 0"/>
      <geometry>
        <mesh filename="package://urdf_tutorial/cer/meshes/dae/sim_cer_r_clavicle_prt.dae" scale="0.001 0.001 0.001"/>
      </geometry>
    </collision>
  </link>
  <joint name="r_shoulder_pitch" type="revolute">
    <origin xyz="-0.084 -0.157 0.34" rpy="0 0 0"/>
    <axis xyz="0.0 -0.984808 0.173648"/>
    <parent link="torso_chest"/>
    <child link="r_clavicle"/>
    <limit effort="50000" lower="-0.3490658503988659" upper="1.7453292519943295" velocity="50000"/>
    <dynamics damping="0.1"/>
  </joint>
  <link name="r_shoulder">
    <inertial>
      <origin xyz="0 -0.034 -0.055" rpy="0 0 0"/>
      <mass value="1.0"/>
      <inertia ixx="0.00140833" ixy="0.0" ixz="0.0" iyy="0.00140833" iyz="0.0" izz="0.0008"/>
    </inertial>
    <visual>
      <origin xyz="0.01 0.157 -0.97" rpy="0 0 0"/>
      <geometry>
        <mesh filename="package://urdf_tutorial/cer/meshes/dae/sim_cer_r_shoulder_prt.dae" scale="0.001 0.001 0.001"/>
      </geometry>
      <material name="yellow"/>
    </visual>
    <collision>
      <origin xyz="0.01 0.157 -0.97" rpy="0 0 0"/>
      <geometry>
        <mesh filename="package://urdf_tutorial/cer/meshes/dae/sim_cer_r_shoulder_prt.dae" scale="0.001 0.001 0.001"/>
      </geometry>
    </collision>
  </link>
  <joint name="r_shoulder_roll" type="revolute">
    <origin xyz="0 0 0" rpy="0 0 0"/>
    <axis xyz="-1.0 0.0 0.0"/>
    <parent link="r_clavicle"/>
    <child link="r_shoulder"/>
    <limit effort="50000" lower="-0.17453292519943295" upper="1.7453292519943295" velocity="50000"/>
    <dynamics damping="0.1"/>
  </joint>
  <link name="r_upperarm">
    <inertial>
      <origin xyz="0 0 -0.0705" rpy="0 0 0"/>
      <mass value="1.0"/>
      <inertia ixx="0.00200831" ixy="0.0" ixz="0.0" iyy="0.00200831" iyz="0.0" izz="0.000703125"/>
    </inertial>
    <visual>
      <origin xyz="0.01 0.191 -0.86" rpy="0 0 0"/>
      <geometry>
        <mesh filename="package://urdf_tutorial/cer/meshes/dae/sim_cer_r_upperarm_prt.dae" scale="0.001 0.001 0.001"/>
      </geometry>
      <material name="pink"/>
    </visual>
    <collision>
      <origin xyz="0.01 0.191 -0.86" rpy="0 0 0"/>
      <geometry>
        <mesh filename="package://urdf_tutorial/cer/meshes/dae/sim_cer_r_upperarm_prt.dae" scale="0.001 0.001 0.001"/>
      </geometry>
    </collision>
  </link>
  <joint name="r_shoulder_yaw" type="revolute">
    <origin xyz="0 -0.034 -0.11" rpy="0 0 0"/>
    <axis xyz="0.0 0.0 -1.0"/>
    <parent link="r_shoulder"/>
    <child link="r_upperarm"/>
    <limit effort="50000" lower="-1.5707963267948966" upper="1.5707963267948966" velocity="50000"/>
    <dynamics damping="0.1"/>
  </joint>
  <link name="r_forearm">
    <inertial>
      <origin xyz="0 0 -0.0355" rpy="0 0 0"/>
      <mass value="0.5"/>
      <inertia ixx="0.000363167" ixy="0.0" ixz="0.0" iyy="0.000363167" iyz="0.0" izz="0.00030625"/>
    </inertial>
    <visual>
      <origin xyz="0.01 0.191 -0.719" rpy="0 0 0"/>
      <geometry>
        <mesh filename="package://urdf_tutorial/cer/meshes/dae/sim_cer_r_forearm_prt.dae" scale="0.001 0.001 0.001"/>
      </geometry>
      <material name="cyan"/>
    </visual>
    <collision>
      <origin xyz="0.01 0.191 -0.719" rpy="0 0 0"/>
      <geometry>
        <mesh filename="package://urdf_tutorial/cer/meshes/dae/sim_cer_r_forearm_prt.dae" scale="0.001 0.001 0.001"/>
      </geometry>
    </collision>
  </link>
  <joint name="r_elbow" type="revolute">
    <origin xyz="0 0 -0.141" rpy="0 0 0"/>
    <axis xyz="0.0 -1.0 0.0"/>
    <parent link="r_upperarm"/>
    <child link="r_forearm"/>
    <limit effort="50000" lower="0.0" upper="2.443460952792061" velocity="50000"/>
    <dynamics damping="0.1"/>
  </joint>
  <link name="r_wrist_tripod_base">
    <inertial>
      <origin xyz="0 0 0" rpy="0 0 0"/>
      <mass value="0.0795216"/>
      <inertia ixx="4.09205e-05" ixy="0.0" ixz="0.0" iyy="4.09205e-05" iyz="0.0" izz="8.05156e-05"/>
    </inertial>
    <visual>
      <origin xyz="0.01 0.191 -0.648" rpy="0 0 0"/>
      <geometry>
        <mesh filename="package://urdf_tutorial/cer/meshes/dae/sim_cer_r_wrist_tripod_base_prt.dae" scale="0.001 0.001 0.001"/>
      </geometry>
      <material name="green"/>
    </visual>
    <collision>
      <origin xyz="0.01 0.191 -0.648" rpy="0 0 0"/>
      <geometry>
        <mesh filename="package://urdf_tutorial/cer/meshes/dae/sim_cer_r_wrist_tripod_base_prt.dae" scale="0.001 0.001 0.001"/>
      </geometry>
    </collision>
  </link>
  <joint name="r_wrist_prosupination" type="revolute">
    <origin xyz="0 0 -0.071" rpy="0 0 0"/>
    <axis xyz="0.0 0.0 -1.0"/>
    <parent link="r_forearm"/>
    <child link="r_wrist_tripod_base"/>
    <limit effort="50000" lower="-1.5707963267948966" upper="1.5707963267948966" velocity="50000"/>
    <dynamics damping="0.1"/>
  </joint>
  <link name="oriented_r_wrist_tripodbase"/>
  <joint name="oriented_r_wrist_tripodbase_fixed_joint" type="fixed">
    <origin xyz="0 0 0" rpy="3.141592653589793 0 1.5707963267948966"/>
    <parent link="r_wrist_tripod_base"/>
    <child link="oriented_r_wrist_tripodbase"/>
    <dynamics damping="0.1"/>
  </joint>
  <link name="r_wrist_tripod_slider_dummy">
    <inertial>
      <origin xyz="0 0 -0.181" rpy="0 0 0"/>
      <mass value="0.2"/>
      <inertia ixx="0.000886667" ixy="0.0" ixz="0.0" iyy="0.000886667" iyz="0.0" izz="0.00016"/>
    </inertial>
    <visual>
      <origin xyz="0.01 0.191 -0.719" rpy="0 0 0"/>
      <geometry>
        <mesh filename="package://urdf_tutorial/cer/meshes/dae/sim_cer_r_wrist_tripod_slider_prt.dae" scale="0.001 0.001 0.001"/>
      </geometry>
      <material name="white"/>
    </visual>
    <collision>
      <origin xyz="0.01 0.191 -0.719" rpy="0 0 0"/>
      <geometry>
        <mesh filename="package://urdf_tutorial/cer/meshes/dae/sim_cer_r_wrist_tripod_slider_prt.dae" scale="0.001 0.001 0.001"/>
      </geometry>
    </collision>
  </link>
  <joint name="r_wrist_tripod_heave_dummy" type="prismatic">
    <origin xyz="0 0 0.071" rpy="0 0 0"/>
    <axis xyz="0.0 0.0 -1.0"/>
    <parent link="r_wrist_tripod_base"/>
    <child link="r_wrist_tripod_slider_dummy"/>
    <limit effort="50000" lower="0.0" upper="0.12" velocity="50000"/>
    <dynamics damping="0.1"/>
  </joint>
  <link name="r_wrist_tripod_pin_dummy">
    <inertial>
      <origin xyz="0 0 0" rpy="0 0 0"/>
      <mass value="0.0314159"/>
      <inertia ixx="1.75406e-05" ixy="0.0" ixz="0.0" iyy="1.5708e-06" iyz="0.0" izz="1.75406e-05"/>
    </inertial>
    <visual>
      <origin xyz="0 0 0" rpy="0 0 0"/>
      <geometry>
        <mesh filename="package://urdf_tutorial/cer/meshes/dae/sim_cer_r_wrist_tripod_pin_prt.dae" scale="0.001 0.001 0.001"/>
      </geometry>
      <material name="dblue"/>
    </visual>
    <collision>
      <origin xyz="0 0 0" rpy="0 0 0"/>
      <geometry>
        <mesh filename="package://urdf_tutorial/cer/meshes/dae/sim_cer_r_wrist_tripod_pin_prt.dae" scale="0.001 0.001 0.001"/>
      </geometry>
    </collision>
  </link>
  <joint name="r_wrist_tripod_roll_dummy" type="revolute">
    <origin xyz="0 0 -0.291" rpy="3.141592653589793 0 1.5707963267948966"/>
    <axis xyz="0.0 -1.0 0.0"/>
    <parent link="r_wrist_tripod_slider_dummy"/>
    <child link="r_wrist_tripod_pin_dummy"/>
    <limit effort="50000" lower="-0.5235987755982988" upper="0.5235987755982988" velocity="50000"/>
    <dynamics damping="0.1"/>
  </joint>
  <link name="r_hand">
    <inertial>
      <origin xyz="0 -0.001 -0.029806" rpy="0 0 0"/>
      <mass value="0.5"/>
      <inertia ixx="0.000273315" ixy="0.0" ixz="0.0" iyy="0.000273315" iyz="0.0" izz="0.000141352"/>
    </inertial>
    <visual>
      <origin xyz="0.01 0.19 -0.428" rpy="0 0 0"/>
      <geometry>
        <mesh filename="package://urdf_tutorial/cer/meshes/dae/sim_cer_r_hand_prt.dae" scale="0.001 0.001 0.001"/>
      </geometry>
      <material name="dgreen"/>
    </visual>
    <collision>
      <origin xyz="0.01 0.19 -0.428" rpy="0 0 0"/>
      <geometry>
        <mesh filename="package://urdf_tutorial/cer/meshes/dae/sim_cer_r_hand_prt.dae" scale="0.001 0.001 0.001"/>
      </geometry>
    </collision>
  </link>
  <joint name="r_wrist_tripod_pitch_dummy" type="revolute">
    <origin xyz="0.001 0 0" rpy="3.141592653589793 0 1.5707963267948966"/>
    <axis xyz="0.0 -1.0 0.0"/>
    <parent link="r_wrist_tripod_pin_dummy"/>
    <child link="r_hand"/>
    <limit effort="50000" lower="-0.5235987755982988" upper="0.5235987755982988" velocity="50000"/>
    <dynamics damping="0.1"/>
  </joint>
  <link name="r_wrist"/>
  <joint name="r_wrist_fixed_joint" type="fixed">
    <origin xyz="0 -0.001 0" rpy="0 0 0"/>
    <parent link="r_hand"/>
    <child link="r_wrist"/>
    <dynamics damping="0.1"/>
  </joint>
  <link name="r_gripper"/>
  <joint name="r_gripper_fixed_joint" type="fixed">
    <origin xyz="0 -0.001 -0.065" rpy="-1.5707963267948961 1.570796326794896 0"/>
    <parent link="r_hand"/>
    <child link="r_gripper"/>
    <dynamics damping="0.1"/>
  </joint>
</robot>
