<?xml version="1.0" ?>
<sdf version="1.5">
  <model name="SIM_CER_ROBOT">
    <link name="mobile_base_body">
      <pose>0 0 0 0 -0 0</pose>
      <inertial>
        <pose>0 0 0.16 0 -0 0</pose>
        <mass>4</mass>
        <inertia>
          <ixx>0.051025</ixx>
          <ixy>0</ixy>
          <ixz>0</ixz>
          <iyy>0.04205</iyy>
          <iyz>0</iyz>
          <izz>0.051025</izz>
        </inertia>
      </inertial>
      <collision name="mobile_base_body_collision">
        <pose>0 0 0 0 -0 0</pose>
        <geometry>
          <mesh>
            <scale>0.001 0.001 0.001</scale>
            <uri>model://cer/meshes/dae/colorful_fixed/sim_cer_mobilebase_body_prt.dae</uri>
          </mesh>
        </geometry>
      </collision>
      <visual name="mobile_base_body_visual">
        <pose>0 0 0 0 -0 0</pose>
        <geometry>
          <mesh>
            <scale>0.001 0.001 0.001</scale>
            <uri>model://cer/meshes/dae/colorful_fixed/sim_cer_mobilebase_body_prt.dae</uri>
          </mesh>
        </geometry>
      </visual>
    </link>
    <link name="mobile_base_l_tyre">
      <pose>0 0.15 0.16 0 -0 0</pose>
      <inertial>
        <pose>0 0.03 0 0 -0 0</pose>
        <mass>3</mass>
        <inertia>
          <ixx>0.0201</ixx>
          <ixy>0</ixy>
          <ixz>0</ixz>
          <iyy>0.0384</iyy>
          <iyz>0</iyz>
          <izz>0.0201</izz>
        </inertia>
      </inertial>
      <collision name="mobile_base_l_tyre_collision">
        <pose>0 -0.15 -0.16 0 -0 0</pose>
        <geometry>
          1e+16
          <mesh>
            <scale>0.001 0.001 0.001</scale>
            <uri>model://cer/meshes/dae/colorful_fixed/sim_cer_mobilebase_l_tyre_prt.dae</uri>
          </mesh>
        </geometry>
      </collision>
      <visual name="mobile_base_l_tyre_visual">
        <pose>0 -0.15 -0.16 0 -0 0</pose>
        <geometry>
          <mesh>
            <scale>0.001 0.001 0.001</scale>
            <uri>model://cer/meshes/dae/colorful_fixed/sim_cer_mobilebase_l_tyre_prt.dae</uri>
          </mesh>
        </geometry>
      </visual>
    </link>
    <joint name="mobile_base_l_wheel" type="revolute">
      <child>mobile_base_l_tyre</child>
      <parent>mobile_base_body</parent>
      <axis>
        <xyz>0 1 0</xyz>
        <limit>
          <lower>-3.14</lower>
          <upper>3.14</upper>
        </limit>
        <dynamics>
          <damping>0.1</damping>
          <friction>0</friction>
          <spring_reference>0</spring_reference>
          <spring_stiffness>0</spring_stiffness>
        </dynamics>
        <use_parent_model_frame>1</use_parent_model_frame>
      </axis>
    </joint>
    <link name="mobile_base_r_tyre">
      <pose>0 -0.15 0.16 0 -0 0</pose>
      <inertial>
        <pose>0 -0.03 0 0 -0 0</pose>
        <mass>3</mass>
        <inertia>
          <ixx>0.0201</ixx>
          <ixy>0</ixy>
          <ixz>0</ixz>
          <iyy>0.0384</iyy>
          <iyz>0</iyz>
          <izz>0.0201</izz>
        </inertia>
      </inertial>
      <collision name="mobile_base_r_tyre_collision">
        <pose>0 0.15 -0.16 0 -0 0</pose>
        <geometry>
          <mesh>
            <scale>0.001 0.001 0.001</scale>
            <uri>model://cer/meshes/dae/colorful_fixed/sim_cer_mobilebase_r_tyre_prt.dae</uri>
          </mesh>
        </geometry>
      </collision>
      <visual name="mobile_base_r_tyre_visual">
        <pose>0 0.15 -0.16 0 -0 0</pose>
        <geometry>
          <mesh>
            <scale>0.001 0.001 0.001</scale>
            <uri>model://cer/meshes/dae/colorful_fixed/sim_cer_mobilebase_r_tyre_prt.dae</uri>
          </mesh>
        </geometry>
      </visual>
    </link>
    <joint name="mobile_base_r_wheel" type="revolute">
      <child>mobile_base_r_tyre</child>
      <parent>mobile_base_body</parent>
      <axis>
        <xyz>0 1 0</xyz>
        <limit>
          <lower>-3.14</lower>
          <upper>3.14</upper>
        </limit>
        <dynamics>
          <damping>0.1</damping>
          <friction>0</friction>
          <spring_reference>0</spring_reference>
          <spring_stiffness>0</spring_stiffness>
        </dynamics>
        <use_parent_model_frame>1</use_parent_model_frame>
      </axis>
    </joint>
    <link name="torso_tripod_slider_dummy">
      <pose>0.074 0 0.221 0 -0 0</pose>
      <inertial>
        <pose>0 0 0.204 0 -0 0</pose>
        <mass>5</mass>
        <inertia>
          <ixx>0.0801667</ixx>
          <ixy>0</ixy>
          <ixz>0</ixz>
          <iyy>0.0801667</iyy>
          <iyz>0</iyz>
          <izz>0.02025</izz>
        </inertia>
      </inertial>
      <collision name="torso_tripod_slider_dummy_collision">
        <pose>-0.074 0 -0.221 0 -0 0</pose>
        <geometry>
          <mesh>
            <scale>0.001 0.001 0.001</scale>
            <uri>model://cer/meshes/dae/colorful_fixed/sim_cer_torso_tripod_slider_prt.dae</uri>
          </mesh>
        </geometry>
      </collision>
      <visual name="torso_tripod_slider_dummy_visual">
        <pose>-0.074 0 -0.221 0 -0 0</pose>
        <geometry>
          <mesh>
            <scale>0.001 0.001 0.001</scale>
            <uri>model://cer/meshes/dae/colorful_fixed/sim_cer_torso_tripod_slider_prt.dae</uri>
          </mesh>
        </geometry>
      </visual>
    </link>
    <joint name="torso_tripod_heave_dummy" type="prismatic">
      <child>torso_tripod_slider_dummy</child>
      <parent>mobile_base_body</parent>
      <axis>
        <xyz>0 0 1</xyz>
        <limit>
          <lower> -0.05 </lower>
          <upper> 0.15</upper>
          <effort>50000</effort>
          <velocity>50000</velocity>
        </limit>
        <dynamics>
          <damping>0.1</damping>
          <friction>0</friction>
          <spring_reference>0</spring_reference>
          <spring_stiffness>0</spring_stiffness>
        </dynamics>
        <use_parent_model_frame>1</use_parent_model_frame>
      </axis>
    </joint>
    <link name="torso_tripod_pin_dummy">
      <pose>0.074 0 0.63 3.14159 -0 0</pose>
      <inertial>
        <pose>0 0 0 0 -0 0</pose>
        <mass>0.0883573</mass>
        <inertia>
          <ixx>9.9402e-06</ixx>
          <ixy>0</ixy>
          <ixz>0</ixz>
          <iyy>7.86012e-05</iyy>
          <iyz>0</iyz>
          <izz>7.86012e-05</izz>
        </inertia>
      </inertial>
      <collision name="torso_tripod_pin_dummy_collision">
        <pose>0 0 0 0 -0 0</pose>
        <geometry>
          <mesh>
            <scale>0.001 0.001 0.001</scale>
            <uri>model://cer/meshes/dae/sim_cer_torso_tripod_pin_dummy_prt.dae</uri>
          </mesh>
        </geometry>
      </collision>
      <visual name="torso_tripod_pin_dummy_visual">
        <pose>0 0 0 0 -0 0</pose>
        <geometry>
          <mesh>
            <scale>0.001 0.001 0.001</scale>
            <uri>model://cer/meshes/dae/sim_cer_torso_tripod_pin_dummy_prt.dae</uri>
          </mesh>
        </geometry>
      </visual>
    </link>
    <joint name="torso_tripod_roll_dummy" type="revolute">
      <child>torso_tripod_pin_dummy</child>
      <parent>torso_tripod_slider_dummy</parent>
      <axis>
        <xyz>1 0 0</xyz>
        <limit>
          <lower>-0.523599</lower>
          <upper>0.523599</upper>
          <effort>50000</effort>
          <velocity>50000</velocity>
        </limit>
        <dynamics>
          <damping>0.1</damping>
          <friction>0</friction>
          <spring_reference>0</spring_reference>
          <spring_stiffness>0</spring_stiffness>
        </dynamics>
        <use_parent_model_frame>1</use_parent_model_frame>
      </axis>
    </joint>
    <link name="torso_tripod_platform">
      <pose>0.074 0 0.63 -2.44929e-16 -0 0</pose>
      <inertial>
        <pose>0 0 0 0 -0 0</pose>
        <mass>0.131528</mass>
        <inertia>
          <ixx>0.000134268</ixx>
          <ixy>0</ixy>
          <ixz>0</ixz>
          <iyy>0.000134268</iyy>
          <iyz>0</iyz>
          <izz>0.000266343</izz>
        </inertia>
      </inertial>
      <collision name="torso_tripod_platform_collision">
        <pose>-0.074 0 -0.63 0 -0 0</pose>
        <geometry>
          <mesh>
            <scale>0.001 0.001 0.001</scale>
            <uri>model://cer/meshes/dae/sim_cer_torso_tripod_platform_prt.dae</uri>
          </mesh>
        </geometry>
      </collision>
      <visual name="torso_tripod_platform_visual">
        <pose>-0.074 0 -0.63 0 -0 0</pose>
        <geometry>
          <mesh>
            <scale>0.001 0.001 0.001</scale>
            <uri>model://cer/meshes/dae/sim_cer_torso_tripod_platform_prt.dae</uri>
          </mesh>
        </geometry>
      </visual>
    </link>
    <joint name="torso_tripod_pitch_dummy" type="revolute">
      <child>torso_tripod_platform</child>
      <parent>torso_tripod_pin_dummy</parent>
      <axis>
        <xyz>0 1 -2.44929e-16</xyz>
        <limit>
          <lower>-0.523599</lower>
          <upper>0.523599</upper>
          <effort>50000</effort>
          <velocity>50000</velocity>
        </limit>
        <dynamics>
          <damping>0.1</damping>
          <friction>0</friction>
          <spring_reference>0</spring_reference>
          <spring_stiffness>0</spring_stiffness>
        </dynamics>
        <use_parent_model_frame>1</use_parent_model_frame>
      </axis>
    </joint>
    <link name="torso_chest">
      <pose>0.074 0 0.63 -2.44929e-16 -0 0</pose>
      <inertial>
        <pose>-0.0195 0 0.189068 0 -0 0</pose>
        <mass>10</mass>
        <inertia>
          <ixx>0.143904</ixx>
          <ixy>0</ixy>
          <ixz>0</ixz>
          <iyy>0.106565</iyy>
          <iyz>0</iyz>
          <izz>0.0650742</izz>
        </inertia>
      </inertial>
      <collision name="torso_chest_collision">
        <pose>-0.074 0 -0.63 0 -0 0</pose>
        <geometry>
          <mesh>
            <scale>0.001 0.001 0.001</scale>
            <uri>model://cer/meshes/dae/colorful_fixed/sim_cer_torso_chest_prt.dae</uri>
          </mesh>
        </geometry>
      </collision>
      <visual name="torso_chest_visual">
        <pose>-0.074 0 -0.63 0 -0 0</pose>
        <geometry>
          <mesh>
            <scale>0.001 0.001 0.001</scale>
            <uri>model://cer/meshes/dae/colorful_fixed/sim_cer_torso_chest_prt.dae</uri>
          </mesh>
        </geometry>
      </visual>
    </link>
    <joint name="torso_yaw" type="revolute">
      <child>torso_chest</child>
      <parent>torso_tripod_platform</parent>
      <axis>
        <xyz>0 2.44929e-16 1</xyz>
        <limit>
          <lower>-1.5708</lower>
          <upper>1.5708</upper>
          <effort>50000</effort>
          <velocity>50000</velocity>
        </limit>
        <dynamics>
          <damping>0.1</damping>
          <friction>0</friction>
          <spring_reference>0</spring_reference>
          <spring_stiffness>0</spring_stiffness>
        </dynamics>
        <use_parent_model_frame>1</use_parent_model_frame>
      </axis>
    </joint>
    <link name="l_clavicle">
      <pose>-0.01 0.157 0.97 -2.44929e-16 -0 0</pose>
      <inertial>
        <pose>0 0 0 0 -0 0</pose>
        <mass>0.0793454</mass>
        <inertia>
          <ixx>1.92382e-05</ixx>
          <ixy>0</ixy>
          <ixz>0</ixz>
          <iyy>1.95373e-05</iyy>
          <iyz>0</iyz>
          <izz>1.95373e-05</izz>
        </inertia>
      </inertial>
      <collision name="l_clavicle_collision">
        <pose>0.01 -0.157 -0.97 0 -0 0</pose>
        <geometry>
          <mesh>
            <scale>0.001 0.001 0.001</scale>
            <uri>model://cer/meshes/dae/sim_cer_l_clavicle_prt.dae</uri>
          </mesh>
        </geometry>
      </collision>
      <visual name="l_clavicle_visual">
        <pose>0.01 -0.157 -0.97 0 -0 0</pose>
        <geometry>
          <mesh>
            <scale>0.001 0.001 0.001</scale>
            <uri>model://cer/meshes/dae/sim_cer_l_clavicle_prt.dae</uri>
          </mesh>
        </geometry>
      </visual>
    </link>
    <joint name="l_shoulder_pitch" type="revolute">
      <child>l_clavicle</child>
      <parent>torso_chest</parent>
      <axis>
        <xyz>0 -0.984808 -0.173648</xyz>
        <limit>
          <lower>-0.349066</lower>
          <upper>1.74533</upper>
          <effort>50000</effort>
          <velocity>50000</velocity>
        </limit>
        <dynamics>
          <damping>0.1</damping>
          <friction>0</friction>
          <spring_reference>0</spring_reference>
          <spring_stiffness>0</spring_stiffness>
        </dynamics>
        <use_parent_model_frame>1</use_parent_model_frame>
      </axis>
    </joint>
    <link name="l_shoulder">
      <pose>-0.01 0.157 0.97 -2.44929e-16 -0 0</pose>
      <inertial>
        <pose>0 0.034 -0.055 0 -0 0</pose>
        <mass>1</mass>
        <inertia>
          <ixx>0.00140833</ixx>
          <ixy>0</ixy>
          <ixz>0</ixz>
          <iyy>0.00140833</iyy>
          <iyz>0</iyz>
          <izz>0.0008</izz>
        </inertia>
      </inertial>
      <collision name="l_shoulder_collision">
        <pose>0.01 -0.157 -0.97 0 -0 0</pose>
        <geometry>
          <mesh>
            <scale>0.001 0.001 0.001</scale>
            <uri>model://cer/meshes/dae/sim_cer_l_shoulder_prt.dae</uri>
          </mesh>
        </geometry>
      </collision>
      <visual name="l_shoulder_visual">
        <pose>0.01 -0.157 -0.97 0 -0 0</pose>
        <geometry>
          <mesh>
            <scale>0.001 0.001 0.001</scale>
            <uri>model://cer/meshes/dae/sim_cer_l_shoulder_prt.dae</uri>
          </mesh>
        </geometry>
      </visual>
    </link>
    <joint name="l_shoulder_roll" type="revolute">
      <child>l_shoulder</child>
      <parent>l_clavicle</parent>
      <axis>
        <xyz>1 0 0</xyz>
        <limit>
          <lower>-0.174533</lower>
          <upper>1.74533</upper>
          <effort>50000</effort>
          <velocity>50000</velocity>
        </limit>
        <dynamics>
          <damping>0.1</damping>
          <friction>0</friction>
          <spring_reference>0</spring_reference>
          <spring_stiffness>0</spring_stiffness>
        </dynamics>
        <use_parent_model_frame>1</use_parent_model_frame>
      </axis>
    </joint>
    <link name="l_upperarm">
      <pose>-0.01 0.191 0.86 -2.44929e-16 -0 0</pose>
      <inertial>
        <pose>0 0 -0.0705 0 -0 0</pose>
        <mass>1</mass>
        <inertia>
          <ixx>0.00200831</ixx>
          <ixy>0</ixy>
          <ixz>0</ixz>
          <iyy>0.00200831</iyy>
          <iyz>0</iyz>
          <izz>0.000703125</izz>
        </inertia>
      </inertial>
      <collision name="l_upperarm_collision">
        <pose>0.01 -0.191 -0.86 0 -0 0</pose>
        <geometry>
          <mesh>
            <scale>0.001 0.001 0.001</scale>
            <uri>model://cer/meshes/dae/sim_cer_l_upperarm_prt.dae</uri>
          </mesh>
        </geometry>
      </collision>
      <visual name="l_upperarm_visual">
        <pose>0.01 -0.191 -0.86 0 -0 0</pose>
        <geometry>
          <mesh>
            <scale>0.001 0.001 0.001</scale>
            <uri>model://cer/meshes/dae/sim_cer_l_upperarm_prt.dae</uri>
          </mesh>
        </geometry>
      </visual>
    </link>
    <joint name="l_shoulder_yaw" type="revolute">
      <child>l_upperarm</child>
      <parent>l_shoulder</parent>
      <axis>
        <xyz>0 2.44929e-16 1</xyz>
        <limit>
          <lower>-1.5708</lower>
          <upper>1.5708</upper>
          <effort>50000</effort>
          <velocity>50000</velocity>
        </limit>
        <dynamics>
          <damping>0.1</damping>
          <friction>0</friction>
          <spring_reference>0</spring_reference>
          <spring_stiffness>0</spring_stiffness>
        </dynamics>
        <use_parent_model_frame>1</use_parent_model_frame>
      </axis>
    </joint>
    <link name="l_forearm">
      <pose>-0.01 0.191 0.719 -2.44929e-16 -0 0</pose>
      <inertial>
        <pose>0 0 -0.0355 0 -0 0</pose>
        <mass>0.5</mass>
        <inertia>
          <ixx>0.000363167</ixx>
          <ixy>0</ixy>
          <ixz>0</ixz>
          <iyy>0.000363167</iyy>
          <iyz>0</iyz>
          <izz>0.00030625</izz>
        </inertia>
      </inertial>
      <collision name="l_forearm_collision">
        <pose>0.01 -0.191 -0.719 0 -0 0</pose>
        <geometry>
          <mesh>
            <scale>0.001 0.001 0.001</scale>
            <uri>model://cer/meshes/dae/sim_cer_l_forearm_prt.dae</uri>
          </mesh>
        </geometry>
      </collision>
      <visual name="l_forearm_visual">
        <pose>0.01 -0.191 -0.719 0 -0 0</pose>
        <geometry>
          <mesh>
            <scale>0.001 0.001 0.001</scale>
            <uri>model://cer/meshes/dae/sim_cer_l_forearm_prt.dae</uri>
          </mesh>
        </geometry>
      </visual>
    </link>
    <joint name="l_elbow" type="revolute">
      <child>l_forearm</child>
      <parent>l_upperarm</parent>
      <axis>
        <xyz>0 -1 2.44929e-16</xyz>
        <limit>
          <lower>0</lower>
          <upper>2.44346</upper>
          <effort>50000</effort>
          <velocity>50000</velocity>
        </limit>
        <dynamics>
          <damping>0.1</damping>
          <friction>0</friction>
          <spring_reference>0</spring_reference>
          <spring_stiffness>0</spring_stiffness>
        </dynamics>
        <use_parent_model_frame>1</use_parent_model_frame>
      </axis>
    </joint>
    <link name="l_wrist_tripod_base">
      <pose>-0.01 0.191 0.648 -2.44929e-16 -0 0</pose>
      <inertial>
        <pose>0 0 0 0 -0 0</pose>
        <mass>0.0795216</mass>
        <inertia>
          <ixx>4.09205e-05</ixx>
          <ixy>0</ixy>
          <ixz>0</ixz>
          <iyy>4.09205e-05</iyy>
          <iyz>0</iyz>
          <izz>8.05156e-05</izz>
        </inertia>
      </inertial>
      <collision name="l_wrist_tripod_base_collision">
        <pose>0.01 -0.191 -0.648 0 -0 0</pose>
        <geometry>
          <mesh>
            <scale>0.001 0.001 0.001</scale>
            <uri>model://cer/meshes/dae/sim_cer_l_wrist_tripod_base_prt.dae</uri>
          </mesh>
        </geometry>
      </collision>
      <visual name="l_wrist_tripod_base_visual">
        <pose>0.01 -0.191 -0.648 0 -0 0</pose>
        <geometry>
          <mesh>
            <scale>0.001 0.001 0.001</scale>
            <uri>model://cer/meshes/dae/sim_cer_l_wrist_tripod_base_prt.dae</uri>
          </mesh>
        </geometry>
      </visual>
    </link>
    <joint name="l_wrist_prosupination" type="revolute">
      <child>l_wrist_tripod_base</child>
      <parent>l_forearm</parent>
      <axis>
        <xyz>0 2.44929e-16 1</xyz>
        <limit>
          <lower>-1.5708</lower>
          <upper>1.5708</upper>
          <effort>50000</effort>
          <velocity>50000</velocity>
        </limit>
        <dynamics>
          <damping>0.1</damping>
          <friction>0</friction>
          <spring_reference>0</spring_reference>
          <spring_stiffness>0</spring_stiffness>
        </dynamics>
        <use_parent_model_frame>1</use_parent_model_frame>
      </axis>
    </joint>
    <link name="l_wrist_tripod_slider_dummy">
      <pose>-0.01 0.191 0.719 -2.44929e-16 -0 0</pose>
      <inertial>
        <pose>0 0 -0.181 0 -0 0</pose>
        <mass>0.2</mass>
        <inertia>
          <ixx>0.000886667</ixx>
          <ixy>0</ixy>
          <ixz>0</ixz>
          <iyy>0.000886667</iyy>
          <iyz>0</iyz>
          <izz>0.00016</izz>
        </inertia>
      </inertial>
      <collision name="l_wrist_tripod_slider_dummy_collision">
        <pose>0.01 -0.191 -0.719 0 -0 0</pose>
        <geometry>
          <mesh>
            <scale>0.001 0.001 0.001</scale>
            <uri>model://cer/meshes/dae/sim_cer_l_wrist_tripod_slider_prt.dae</uri>
          </mesh>
        </geometry>
      </collision>
      <visual name="l_wrist_tripod_slider_dummy_visual">
        <pose>0.01 -0.191 -0.719 0 -0 0</pose>
        <geometry>
          <mesh>
            <scale>0.001 0.001 0.001</scale>
            <uri>model://cer/meshes/dae/sim_cer_l_wrist_tripod_slider_prt.dae</uri>
          </mesh>
        </geometry>
      </visual>
    </link>
    <joint name="l_wrist_tripod_heave_dummy" type="prismatic">
      <child>l_wrist_tripod_slider_dummy</child>
      <parent>l_wrist_tripod_base</parent>
      <axis>
        <xyz>0 -2.44929e-16 -1</xyz>
        <limit>
          <lower>0</lower>
          <upper>0.12</upper>
          <effort>50000</effort>
          <velocity>50000</velocity>
        </limit>
        <dynamics>
          <damping>0.1</damping>
          <friction>0</friction>
          <spring_reference>0</spring_reference>
          <spring_stiffness>0</spring_stiffness>
        </dynamics>
        <use_parent_model_frame>1</use_parent_model_frame>
      </axis>
    </joint>
    <link name="l_wrist_tripod_pin_dummy">
      <pose>-0.01 0.191 0.428 -0.834363 1.57079 2.30723</pose>
      <inertial>
        <pose>0 0 0 0 -0 0</pose>
        <mass>0.0314159</mass>
        <inertia>
          <ixx>1.75406e-05</ixx>
          <ixy>0</ixy>
          <ixz>0</ixz>
          <iyy>1.75406e-05</iyy>
          <iyz>0</iyz>
          <izz>1.5708e-06</izz>
        </inertia>
      </inertial>
      <collision name="l_wrist_tripod_pin_dummy_collision">
        <pose>0 0 0 0 -0 0</pose>
        <geometry>
          <mesh>
            <scale>0.001 0.001 0.001</scale>
            <uri>model://cer/meshes/dae/sim_cer_l_wrist_tripod_pin_prt.dae</uri>
          </mesh>
        </geometry>
      </collision>
      <visual name="l_wrist_tripod_pin_dummy_visual">
        <pose>0 0 0 0 -0 0</pose>
        <geometry>
          <mesh>
            <scale>0.001 0.001 0.001</scale>
            <uri>model://cer/meshes/dae/sim_cer_l_wrist_tripod_pin_prt.dae</uri>
          </mesh>
        </geometry>
      </visual>
    </link>
    <joint name="l_wrist_tripod_roll_dummy" type="revolute">
      <child>l_wrist_tripod_pin_dummy</child>
      <parent>l_wrist_tripod_slider_dummy</parent>
      <axis>
        <xyz>1 1.22465e-16 2.22045e-16</xyz>
        <limit>
          <lower>-0.523599</lower>
          <upper>0.523599</upper>
          <effort>50000</effort>
          <velocity>50000</velocity>
        </limit>
        <dynamics>
          <damping>0.1</damping>
          <friction>0</friction>
          <spring_reference>0</spring_reference>
          <spring_stiffness>0</spring_stiffness>
        </dynamics>
        <use_parent_model_frame>1</use_parent_model_frame>
      </axis>
    </joint>
    <link name="l_hand">
      <pose>-0.01 0.19 0.428 -3.67394e-16 2.24964e-32 1.22465e-16</pose>
      <inertial>
        <pose>0 0.001 -0.029806 0 -0 0</pose>
        <mass>0.5</mass>
        <inertia>
          <ixx>0.000273315</ixx>
          <ixy>0</ixy>
          <ixz>0</ixz>
          <iyy>0.000273315</iyy>
          <iyz>0</iyz>
          <izz>0.000141352</izz>
        </inertia>
      </inertial>
      <collision name="l_hand_collision">
        <pose>0.01 -0.19 -0.428 0 -0 0</pose>
        <geometry>
          <mesh>
            <scale>0.001 0.001 0.001</scale>
            <uri>model://cer/meshes/dae/sim_cer_l_hand_prt.dae</uri>
          </mesh>
        </geometry>
      </collision>
      <visual name="l_hand_visual">
        <pose>0.01 -0.19 -0.428 0 -0 0</pose>
        <geometry>
          <mesh>
            <scale>0.001 0.001 0.001</scale>
            <uri>model://cer/meshes/dae/sim_cer_l_hand_prt.dae</uri>
          </mesh>
        </geometry>
      </visual>
    </link>
    <joint name="l_wrist_tripod_pitch_dummy" type="revolute">
      <child>l_hand</child>
      <parent>l_wrist_tripod_pin_dummy</parent>
      <axis>
        <xyz>1.22465e-16 -1 3.67394e-16</xyz>
        <limit>
          <lower>-0.523599</lower>
          <upper>0.523599</upper>
          <effort>50000</effort>
          <velocity>50000</velocity>
        </limit>
        <dynamics>
          <damping>0.1</damping>
          <friction>0</friction>
          <spring_reference>0</spring_reference>
          <spring_stiffness>0</spring_stiffness>
        </dynamics>
        <use_parent_model_frame>1</use_parent_model_frame>
      </axis>
    </joint>
    <link name="r_clavicle">
      <pose>-0.01 -0.157 0.97 -2.44929e-16 -0 0</pose>
      <inertial>
        <pose>0 0 0 0 -0 0</pose>
        <mass>0.0793454</mass>
        <inertia>
          <ixx>1.92382e-05</ixx>
          <ixy>0</ixy>
          <ixz>0</ixz>
          <iyy>1.95373e-05</iyy>
          <iyz>0</iyz>
          <izz>1.95373e-05</izz>
        </inertia>
      </inertial>
      <collision name="r_clavicle_collision">
        <pose>0.01 0.157 -0.97 0 -0 0</pose>
        <geometry>
          <mesh>
            <scale>0.001 0.001 0.001</scale>
            <uri>model://cer/meshes/dae/sim_cer_r_clavicle_prt.dae</uri>
          </mesh>
        </geometry>
      </collision>
      <visual name="r_clavicle_visual">
        <pose>0.01 0.157 -0.97 0 -0 0</pose>
        <geometry>
          <mesh>
            <scale>0.001 0.001 0.001</scale>
            <uri>model://cer/meshes/dae/sim_cer_r_clavicle_prt.dae</uri>
          </mesh>
        </geometry>
      </visual>
    </link>
    <joint name="r_shoulder_pitch" type="revolute">
      <child>r_clavicle</child>
      <parent>torso_chest</parent>
      <axis>
        <xyz>0 -0.984808 0.173648</xyz>
        <limit>
          <lower>-0.349066</lower>
          <upper>1.74533</upper>
          <effort>50000</effort>
          <velocity>50000</velocity>
        </limit>
        <dynamics>
          <damping>0.1</damping>
          <friction>0</friction>
          <spring_reference>0</spring_reference>
          <spring_stiffness>0</spring_stiffness>
        </dynamics>
        <use_parent_model_frame>1</use_parent_model_frame>
      </axis>
    </joint>
    <link name="r_shoulder">
      <pose>-0.01 -0.157 0.97 -2.44929e-16 -0 0</pose>
      <inertial>
        <pose>0 -0.034 -0.055 0 -0 0</pose>
        <mass>1</mass>
        <inertia>
          <ixx>0.00140833</ixx>
          <ixy>0</ixy>
          <ixz>0</ixz>
          <iyy>0.00140833</iyy>
          <iyz>0</iyz>
          <izz>0.0008</izz>
        </inertia>
      </inertial>
      <collision name="r_shoulder_collision">
        <pose>0.01 0.157 -0.97 0 -0 0</pose>
        <geometry>
          <mesh>
            <scale>0.001 0.001 0.001</scale>
            <uri>model://cer/meshes/dae/sim_cer_r_shoulder_prt.dae</uri>
          </mesh>
        </geometry>
      </collision>
      <visual name="r_shoulder_visual">
        <pose>0.01 0.157 -0.97 0 -0 0</pose>
        <geometry>
          <mesh>
            <scale>0.001 0.001 0.001</scale>
            <uri>model://cer/meshes/dae/sim_cer_r_shoulder_prt.dae</uri>
          </mesh>
        </geometry>
      </visual>
    </link>
    <joint name="r_shoulder_roll" type="revolute">
      <child>r_shoulder</child>
      <parent>r_clavicle</parent>
      <axis>
        <xyz>-1 0 -0</xyz>
        <limit>
          <lower>-0.174533</lower>
          <upper>1.74533</upper>
          <effort>50000</effort>
          <velocity>50000</velocity>
        </limit>
        <dynamics>
          <damping>0.1</damping>
          <friction>0</friction>
          <spring_reference>0</spring_reference>
          <spring_stiffness>0</spring_stiffness>
        </dynamics>
        <use_parent_model_frame>1</use_parent_model_frame>
      </axis>
    </joint>
    <link name="r_upperarm">
      <pose>-0.01 -0.191 0.86 -2.44929e-16 -0 0</pose>
      <inertial>
        <pose>0 0 -0.0705 0 -0 0</pose>
        <mass>1</mass>
        <inertia>
          <ixx>0.00200831</ixx>
          <ixy>0</ixy>
          <ixz>0</ixz>
          <iyy>0.00200831</iyy>
          <iyz>0</iyz>
          <izz>0.000703125</izz>
        </inertia>
      </inertial>
      <collision name="r_upperarm_collision">
        <pose>0.01 0.191 -0.86 0 -0 0</pose>
        <geometry>
          <mesh>
            <scale>0.001 0.001 0.001</scale>
            <uri>model://cer/meshes/dae/sim_cer_r_upperarm_prt.dae</uri>
          </mesh>
        </geometry>
      </collision>
      <visual name="r_upperarm_visual">
        <pose>0.01 0.191 -0.86 0 -0 0</pose>
        <geometry>
          <mesh>
            <scale>0.001 0.001 0.001</scale>
            <uri>model://cer/meshes/dae/sim_cer_r_upperarm_prt.dae</uri>
          </mesh>
        </geometry>
      </visual>
    </link>
    <joint name="r_shoulder_yaw" type="revolute">
      <child>r_upperarm</child>
      <parent>r_shoulder</parent>
      <axis>
        <xyz>0 -2.44929e-16 -1</xyz>
        <limit>
          <lower>-1.5708</lower>
          <upper>1.5708</upper>
          <effort>50000</effort>
          <velocity>50000</velocity>
        </limit>
        <dynamics>
          <damping>0.1</damping>
          <friction>0</friction>
          <spring_reference>0</spring_reference>
          <spring_stiffness>0</spring_stiffness>
        </dynamics>
        <use_parent_model_frame>1</use_parent_model_frame>
      </axis>
    </joint>
    <link name="r_forearm">
      <pose>-0.01 -0.191 0.719 -2.44929e-16 -0 0</pose>
      <inertial>
        <pose>0 0 -0.0355 0 -0 0</pose>
        <mass>0.5</mass>
        <inertia>
          <ixx>0.000363167</ixx>
          <ixy>0</ixy>
          <ixz>0</ixz>
          <iyy>0.000363167</iyy>
          <iyz>0</iyz>
          <izz>0.00030625</izz>
        </inertia>
      </inertial>
      <collision name="r_forearm_collision">
        <pose>0.01 0.191 -0.719 0 -0 0</pose>
        <geometry>
          <mesh>
            <scale>0.001 0.001 0.001</scale>
            <uri>model://cer/meshes/dae/sim_cer_r_forearm_prt.dae</uri>
          </mesh>
        </geometry>
      </collision>
      <visual name="r_forearm_visual">
        <pose>0.01 0.191 -0.719 0 -0 0</pose>
        <geometry>
          <mesh>
            <scale>0.001 0.001 0.001</scale>
            <uri>model://cer/meshes/dae/sim_cer_r_forearm_prt.dae</uri>
          </mesh>
        </geometry>
      </visual>
    </link>
    <joint name="r_elbow" type="revolute">
      <child>r_forearm</child>
      <parent>r_upperarm</parent>
      <axis>
        <xyz>0 -1 2.44929e-16</xyz>
        <limit>
          <lower>0</lower>
          <upper>2.44346</upper>
          <effort>50000</effort>
          <velocity>50000</velocity>
        </limit>
        <dynamics>
          <damping>0.1</damping>
          <friction>0</friction>
          <spring_reference>0</spring_reference>
          <spring_stiffness>0</spring_stiffness>
        </dynamics>
        <use_parent_model_frame>1</use_parent_model_frame>
      </axis>
    </joint>
    <link name="r_wrist_tripod_base">
      <pose>-0.01 -0.191 0.648 -2.44929e-16 -0 0</pose>
      <inertial>
        <pose>0 0 0 0 -0 0</pose>
        <mass>0.0795216</mass>
        <inertia>
          <ixx>4.09205e-05</ixx>
          <ixy>0</ixy>
          <ixz>0</ixz>
          <iyy>4.09205e-05</iyy>
          <iyz>0</iyz>
          <izz>8.05156e-05</izz>
        </inertia>
      </inertial>
      <collision name="r_wrist_tripod_base_collision">
        <pose>0.01 0.191 -0.648 0 -0 0</pose>
        <geometry>
          <mesh>
            <scale>0.001 0.001 0.001</scale>
            <uri>model://cer/meshes/dae/sim_cer_r_wrist_tripod_base_prt.dae</uri>
          </mesh>
        </geometry>
      </collision>
      <visual name="r_wrist_tripod_base_visual">
        <pose>0.01 0.191 -0.648 0 -0 0</pose>
        <geometry>
          <mesh>
            <scale>0.001 0.001 0.001</scale>
            <uri>model://cer/meshes/dae/sim_cer_r_wrist_tripod_base_prt.dae</uri>
          </mesh>
        </geometry>
      </visual>
    </link>
    <joint name="r_wrist_prosupination" type="revolute">
      <child>r_wrist_tripod_base</child>
      <parent>r_forearm</parent>
      <axis>
        <xyz>0 -2.44929e-16 -1</xyz>
        <limit>
          <lower>-1.5708</lower>
          <upper>1.5708</upper>
          <effort>50000</effort>
          <velocity>50000</velocity>
        </limit>
        <dynamics>
          <damping>0.1</damping>
          <friction>0</friction>
          <spring_reference>0</spring_reference>
          <spring_stiffness>0</spring_stiffness>
        </dynamics>
        <use_parent_model_frame>1</use_parent_model_frame>
      </axis>
    </joint>
    <link name="r_wrist_tripod_slider_dummy">
      <pose>-0.01 -0.191 0.719 -2.44929e-16 -0 0</pose>
      <inertial>
        <pose>0 0 -0.181 0 -0 0</pose>
        <mass>0.2</mass>
        <inertia>
          <ixx>0.000886667</ixx>
          <ixy>0</ixy>
          <ixz>0</ixz>
          <iyy>0.000886667</iyy>
          <iyz>0</iyz>
          <izz>0.00016</izz>
        </inertia>
      </inertial>
      <collision name="r_wrist_tripod_slider_dummy_collision">
        <pose>0.01 0.191 -0.719 0 -0 0</pose>
        <geometry>
          <mesh>
            <scale>0.001 0.001 0.001</scale>
            <uri>model://cer/meshes/dae/sim_cer_r_wrist_tripod_slider_prt.dae</uri>
          </mesh>
        </geometry>
      </collision>
      <visual name="r_wrist_tripod_slider_dummy_visual">
        <pose>0.01 0.191 -0.719 0 -0 0</pose>
        <geometry>
          <mesh>
            <scale>0.001 0.001 0.001</scale>
            <uri>model://cer/meshes/dae/sim_cer_r_wrist_tripod_slider_prt.dae</uri>
          </mesh>
        </geometry>
      </visual>
    </link>
    <joint name="r_wrist_tripod_heave_dummy" type="prismatic">
      <child>r_wrist_tripod_slider_dummy</child>
      <parent>r_wrist_tripod_base</parent>
      <axis>
        <xyz>0 -2.44929e-16 -1</xyz>
        <limit>
          <lower>0</lower>
          <upper>0.12</upper>
          <effort>50000</effort>
          <velocity>50000</velocity>
        </limit>
        <dynamics>
          <damping>0.1</damping>
          <friction>0</friction>
          <spring_reference>0</spring_reference>
          <spring_stiffness>0</spring_stiffness>
        </dynamics>
        <use_parent_model_frame>1</use_parent_model_frame>
      </axis>
    </joint>
    <link name="r_wrist_tripod_pin_dummy">
      <pose>-0.01 -0.191 0.428 3.14159 2.44929e-16 1.5708</pose>
      <inertial>
        <pose>0 0 0 0 -0 0</pose>
        <mass>0.0314159</mass>
        <inertia>
          <ixx>1.75406e-05</ixx>
          <ixy>0</ixy>
          <ixz>0</ixz>
          <iyy>1.5708e-06</iyy>
          <iyz>0</iyz>
          <izz>1.75406e-05</izz>
        </inertia>
      </inertial>
      <collision name="r_wrist_tripod_pin_dummy_collision">
        <pose>0 0 0 0 -0 0</pose>
        <geometry>
          <mesh>
            <scale>0.001 0.001 0.001</scale>
            <uri>model://cer/meshes/dae/sim_cer_r_wrist_tripod_pin_prt.dae</uri>
          </mesh>
        </geometry>
      </collision>
      <visual name="r_wrist_tripod_pin_dummy_visual">
        <pose>0 0 0 0 -0 0</pose>
        <geometry>
          <mesh>
            <scale>0.001 0.001 0.001</scale>
            <uri>model://cer/meshes/dae/sim_cer_r_wrist_tripod_pin_prt.dae</uri>
          </mesh>
        </geometry>
      </visual>
    </link>
    <joint name="r_wrist_tripod_roll_dummy" type="revolute">
      <child>r_wrist_tripod_pin_dummy</child>
      <parent>r_wrist_tripod_slider_dummy</parent>
      <axis>
        <xyz>-1 2.22045e-16 -1.22465e-16</xyz>
        <limit>
          <lower>-0.523599</lower>
          <upper>0.523599</upper>
          <effort>50000</effort>
          <velocity>50000</velocity>
        </limit>
        <dynamics>
          <damping>0.1</damping>
          <friction>0</friction>
          <spring_reference>0</spring_reference>
          <spring_stiffness>0</spring_stiffness>
        </dynamics>
        <use_parent_model_frame>1</use_parent_model_frame>
      </axis>
    </joint>
    <link name="r_hand">
      <pose>-0.01 -0.19 0.428 -3.67394e-16 -1.22465e-16 2.62458e-32</pose>
      <inertial>
        <pose>0 -0.001 -0.029806 0 -0 0</pose>
        <mass>0.5</mass>
        <inertia>
          <ixx>0.000273315</ixx>
          <ixy>0</ixy>
          <ixz>0</ixz>
          <iyy>0.000273315</iyy>
          <iyz>0</iyz>
          <izz>0.000141352</izz>
        </inertia>
      </inertial>
      <collision name="r_hand_collision">
        <pose>0.01 0.19 -0.428 0 -0 0</pose>
        <geometry>
          <mesh>
            <scale>0.001 0.001 0.001</scale>
            <uri>model://cer/meshes/dae/sim_cer_r_hand_prt.dae</uri>
          </mesh>
        </geometry>
      </collision>
      <visual name="r_hand_visual">
        <pose>0.01 0.19 -0.428 0 -0 0</pose>
        <geometry>
          <mesh>
            <scale>0.001 0.001 0.001</scale>
            <uri>model://cer/meshes/dae/sim_cer_r_hand_prt.dae</uri>
          </mesh>
        </geometry>
      </visual>
    </link>
    <joint name="r_wrist_tripod_pitch_dummy" type="revolute">
      <child>r_hand</child>
      <parent>r_wrist_tripod_pin_dummy</parent>
      <axis>
        <xyz>-1.8747e-32 -1 3.67394e-16</xyz>
        <limit>
          <lower>-0.523599</lower>
          <upper>0.523599</upper>
          <effort>50000</effort>
          <velocity>50000</velocity>
        </limit>
        <dynamics>
          <damping>0.1</damping>
          <friction>0</friction>
          <spring_reference>0</spring_reference>
          <spring_stiffness>0</spring_stiffness>
        </dynamics>
        <use_parent_model_frame>1</use_parent_model_frame>
      </axis>
    </joint>


    <plugin name="controlboard_torso_yaw" filename="libgazebo_yarp_controlboard.so">
      <yarpConfigurationFile>model://cer/conf/gazebo_cer_torso_yaw.ini</yarpConfigurationFile>
    </plugin>

    <!-- TORSO user view -->
    <plugin name="controlboard_torso" filename="libgazebo_yarp_controlboard.so">
      <yarpConfigurationFile>model://cer/conf/gazebo_cer_torso.ini</yarpConfigurationFile>
    </plugin>
    <!-- TORSO low level view -->
    <plugin name="controlboard_torso_tripod" filename="libgazeboTripod.so">
      <yarpConfigurationFile>model://cer/conf/gazebo_cer_torso_tripod.ini</yarpConfigurationFile>
    </plugin>


    <plugin name="controlboard_left_upper_arm" filename="libgazebo_yarp_controlboard.so">
      <yarpConfigurationFile>model://cer/conf/gazebo_cer_left_upper_arm.ini</yarpConfigurationFile>
    </plugin>
    <!-- LEFT WRIST user view -->  
    <plugin name="controlboard_left_wrist" filename="libgazebo_yarp_controlboard.so">
      <yarpConfigurationFile>model://cer/conf/gazebo_cer_left_wrist.ini</yarpConfigurationFile>
    </plugin>
    <!-- LEFT WRIST low level view -->
    <plugin name="controlboard_left_wrist_tripod" filename="libgazeboTripod.so">
      <yarpConfigurationFile>model://cer/conf/gazebo_cer_left_wrist_tripod.ini</yarpConfigurationFile>
    </plugin>


    <plugin name="controlboard_right_upper_arm" filename="libgazebo_yarp_controlboard.so">
      <yarpConfigurationFile>model://cer/conf/gazebo_cer_right_upper_arm.ini</yarpConfigurationFile>
    </plugin>
    <!-- RIGHT WRIST user view -->
    <plugin name="controlboard_right_wrist" filename="libgazebo_yarp_controlboard.so">
      <yarpConfigurationFile>model://cer/conf/gazebo_cer_right_wrist.ini</yarpConfigurationFile>
    </plugin>
    <!-- RIGHT WRIST low level view -->
    <plugin name="controlboard_right_wrist_tripod" filename="libgazeboTripod.so">
      <yarpConfigurationFile>model://cer/conf/gazebo_cer_right_wrist_tripod.ini</yarpConfigurationFile>
    </plugin>


<!--
    <plugin name='controlboard_head' filename='libgazebo_yarp_controlboard.so'>
      <yarpConfigurationFile>model://cer/conf/gazebo_cer_head.ini</yarpConfigurationFile>
    </plugin>
    <plugin name='controlboard_left_hand' filename='libgazebo_yarp_controlboard.so'>
      <yarpConfigurationFile>model://cer/conf/gazebo_cer_left_hand.ini</yarpConfigurationFile>
    </plugin>
    <plugin name='controlboard_right_hand' filename='libgazebo_yarp_controlboard.so'>
      <yarpConfigurationFile>model://cer/conf/gazebo_cer_right_hand.ini</yarpConfigurationFile>
    </plugin> 
-->

    <plugin name="controlboard_mobile_base" filename="libgazebo_yarp_controlboard.so">
      <yarpConfigurationFile>model://cer/conf/gazebo_cer_mobile_base.ini</yarpConfigurationFile>
    </plugin>
    <plugin name="controlboard_all" filename="libgazebo_yarp_controlboard.so">
      <yarpConfigurationFile>model://cer/conf/gazebo_cer_all.ini</yarpConfigurationFile>
    </plugin>
  </model>
</sdf>
