<?xml version="1.0" ?>
<sdf version='1.5'>
  <model name='SIM_CER_ROBOT'>
    <link name='mobile_base_body'>
      <pose>0 0 0 0 -0 0</pose>
      <inertial>
        <pose>0.016717 0 0.201998 0 -0 0</pose>
        <mass>16</mass>
        <inertia>
          <ixx>0.331884</ixx>
          <ixy>0</ixy>
          <ixz>-0.0448172</ixz>
          <iyy>0.34974</iyy>
          <iyz>0</iyz>
          <izz>0.21095</izz>
        </inertia>
      </inertial>
      <collision name='mobile_base_body_collision'>
        <pose>0 0 0 0 -0 0</pose>
        <geometry>
          <mesh>
            <scale>0.001 0.001 0.001</scale>
            <uri>model://cer/meshes/stl/sim_cer_mobilebase_body_prt.stl</uri>
          </mesh>
        </geometry>
        <surface>
            <friction>
              <ode>
                <mu>0.0</mu>
                <mu2>0.0</mu2>
                <slip1>1.0</slip1>
                <slip2>1.0</slip2>
              </ode>
            </friction>
         </surface>
      </collision>
      <visual name='mobile_base_body_visual'>
        <pose>0 0 0 0 -0 0</pose>
        <geometry>
          <mesh>
            <scale>0.001 0.001 0.001</scale>
            <uri>model://cer/meshes/stl/sim_cer_mobilebase_body_prt.stl</uri>
          </mesh>
        </geometry>
      </visual>
      <sensor name ='base_laser' type='ray'>
      <pose>0.3 0 0.1 0 0 0</pose>
      <visualize>true</visualize>
      <update_rate>40</update_rate>
      <ray>
        <scan>
          <horizontal>
            <samples>360</samples>
            <resolution>1</resolution>
            <min_angle>-3.14</min_angle>
            <max_angle>3.14</max_angle>
          </horizontal>
        </scan>
        <range>
          <min>0.10</min>
          <max>5.0</max>
          <resolution>0.01</resolution>
        </range>
        <noise>
          <type>gaussian</type>
          <mean>0.0</mean>
          <stddev>0.005</stddev>
        </noise>
      </ray>
        <plugin name='laser_sensor' filename='libgazebo_yarp_lasersensor.so'>
           <yarpConfigurationFile>model://cer/conf/gazebo_cer_laser_sensor.ini</yarpConfigurationFile>
        </plugin>
      </sensor>
    </link>
    <link name='mobile_base_l_tyre'>
      <pose>0 0.15 0.16 0 -0 0</pose>
      <inertial>
        <pose>0 0.034423 0 0 -0 0</pose>
        <mass>3</mass>
        <inertia>
          <ixx>0.0200167</ixx>
          <ixy>0</ixy>
          <ixz>0</ixz>
          <iyy>0.0376153</iyy>
          <iyz>0</iyz>
          <izz>0.0200167</izz>
        </inertia>
      </inertial>
      <collision name='mobile_base_l_tyre_collision'>
        <pose>0 -0.15 -0.16 0 -0 0</pose>
        <geometry>
          <mesh>
            <scale>0.001 0.001 0.001</scale>
            <uri>model://cer/meshes/stl/sim_cer_mobilebase_l_tyre_prt.stl</uri>
          </mesh>
        </geometry>
      </collision>
      <visual name='mobile_base_l_tyre_visual'>
        <pose>0 -0.15 -0.16 0 -0 0</pose>
        <geometry>
          <mesh>
            <scale>0.001 0.001 0.001</scale>
            <uri>model://cer/meshes/stl/sim_cer_mobilebase_l_tyre_prt.stl</uri>
          </mesh>
        </geometry>
      </visual>
    </link>
    <joint name='mobile_base_l_wheel' type='revolute'>
      <child>mobile_base_l_tyre</child>
      <parent>mobile_base_body</parent>
      <axis>
        <xyz>0 1 0</xyz>
        <limit>
        <!--  <lower>-17.4358</lower> -->
        <!--  <upper>17.4358</upper> -->
          <effort>100</effort>
          <velocity>50000</velocity>
        </limit>
        <dynamics>
          <damping>1</damping>
          <friction>0</friction>
          <spring_reference>0</spring_reference>
          <spring_stiffness>0</spring_stiffness>
        </dynamics>
        <use_parent_model_frame>1</use_parent_model_frame>
      </axis>
      <physics>
        <ode>
          <implicit_spring_damper>1</implicit_spring_damper>
          <cfm_damping>1</cfm_damping>
          <limit>
            <cfm>0</cfm>
            <erp>0.2</erp>
          </limit>
        </ode>
      </physics>
    </joint>
    <link name='mobile_base_r_tyre'>
      <pose>0 -0.15 0.16 0 -0 0</pose>
      <inertial>
        <pose>0 -0.034423 0 0 -0 0</pose>
        <mass>3</mass>
        <inertia>
          <ixx>0.0200167</ixx>
          <ixy>0</ixy>
          <ixz>0</ixz>
          <iyy>0.0376153</iyy>
          <iyz>0</iyz>
          <izz>0.0200167</izz>
        </inertia>
      </inertial>
      <collision name='mobile_base_r_tyre_collision'>
        <pose>0 0.15 -0.16 0 -0 0</pose>
        <geometry>
          <mesh>
            <scale>0.001 0.001 0.001</scale>
            <uri>model://cer/meshes/stl/sim_cer_mobilebase_r_tyre_prt.stl</uri>
          </mesh>
        </geometry>
      </collision>
      <visual name='mobile_base_r_tyre_visual'>
        <pose>0 0.15 -0.16 0 -0 0</pose>
        <geometry>
          <mesh>
            <scale>0.001 0.001 0.001</scale>
            <uri>model://cer/meshes/stl/sim_cer_mobilebase_r_tyre_prt.stl</uri>
          </mesh>
        </geometry>
      </visual>
    </link>
    <joint name='mobile_base_r_wheel' type='revolute'>
      <child>mobile_base_r_tyre</child>
      <parent>mobile_base_body</parent>
      <axis>
        <xyz>0 1 0</xyz>
        <limit>
          <!-- <lower>-17.4358</lower> -->
          <!-- <upper>17.4358</upper> -->
          <effort>100</effort>
          <velocity>50000</velocity>
        </limit>
        <dynamics>
          <damping>1</damping>
          <friction>0</friction>
          <spring_reference>0</spring_reference>
          <spring_stiffness>0</spring_stiffness>
        </dynamics>
        <use_parent_model_frame>1</use_parent_model_frame>
      </axis>
      <physics>
        <ode>
          <implicit_spring_damper>1</implicit_spring_damper>
          <cfm_damping>1</cfm_damping>
          <limit>
            <cfm>0</cfm>
            <erp>0.2</erp>
          </limit>
        </ode>
      </physics>
    </joint>
    <link name='torso_tripod_slider_eq'>
      <pose>0.074 0 0.231 0 -0 0</pose>
      <inertial>
        <pose>0.010986 9e-06 0.236044 0 -0 0</pose>
        <mass>2.5</mass>
        <inertia>
          <ixx>0.0334422</ixx>
          <ixy>0</ixy>
          <ixz>0.00203295</ixz>
          <iyy>0.0329538</iyy>
          <iyz>2.22187e-06</iyz>
          <izz>0.022808</izz>
        </inertia>
      </inertial>
      <collision name='torso_tripod_slider_eq_collision'>
        <pose>-0.074 0 -0.231 0 -0 0</pose>
        <geometry>
          <mesh>
            <scale>0.001 0.001 0.001</scale>
            <uri>model://cer/meshes/stl/sim_cer_torso_tripod_slider_eq_prt.stl</uri>
          </mesh>
        </geometry>
      </collision>
      <visual name='torso_tripod_slider_eq_visual'>
        <pose>-0.074 0 -0.231 0 -0 0</pose>
        <geometry>
          <mesh>
            <scale>0.001 0.001 0.001</scale>
            <uri>model://cer/meshes/stl/sim_cer_torso_tripod_slider_eq_prt.stl</uri>
          </mesh>
        </geometry>
      </visual>
    </link>
    <joint name='torso_tripod_heave_eq' type='prismatic'>
      <child>torso_tripod_slider_eq</child>
      <parent>mobile_base_body</parent>
      <axis>
        <xyz>0 0 1</xyz>
        <limit>
          <lower>-0.05</lower>
          <upper>0.15</upper>
          <effort>50000</effort>
          <velocity>50000</velocity>
        </limit>
        <dynamics>
          <damping>1000</damping>
          <friction>0</friction>
          <spring_reference>0</spring_reference>
          <spring_stiffness>0</spring_stiffness>
        </dynamics>
        <use_parent_model_frame>1</use_parent_model_frame>
      </axis>
      <physics>
        <ode>
          <implicit_spring_damper>1</implicit_spring_damper>
          <cfm_damping>1</cfm_damping>
          <limit>
            <cfm>0.1</cfm>
            <erp>0.2</erp>
          </limit>
        </ode>
      </physics>
    </joint>
    <link name='torso_tripod_pin_eq'>
      <pose>0.074 0 0.63 3.14159 -0 0</pose>
      <inertial>
        <pose>0 0 0 0 -0 0</pose>
        <mass>0.25</mass>
        <inertia>
          <ixx>2.8125e-05</ixx>
          <ixy>0</ixy>
          <ixz>0</ixz>
          <iyy>0.000222396</iyy>
          <iyz>0</iyz>
          <izz>0.000222396</izz>
        </inertia>
      </inertial>
      <collision name='torso_tripod_pin_eq_collision'>
        <pose>0 0 0 0 -0 0</pose>
        <geometry>
          <mesh>
            <scale>0.001 0.001 0.001</scale>
            <uri>model://cer/meshes/stl/sim_cer_torso_tripod_pin_eq_prt.stl</uri>
          </mesh>
        </geometry>
      </collision>
      <visual name='torso_tripod_pin_eq_visual'>
        <pose>0 0 0 0 -0 0</pose>
        <geometry>
          <mesh>
            <scale>0.001 0.001 0.001</scale>
            <uri>model://cer/meshes/stl/sim_cer_torso_tripod_pin_eq_prt.stl</uri>
          </mesh>
        </geometry>
      </visual>
    </link>
    <joint name='torso_tripod_roll_eq' type='revolute'>
      <child>torso_tripod_pin_eq</child>
      <parent>torso_tripod_slider_eq</parent>
      <axis>
        <xyz>1 0 0</xyz>
        <limit>
          <lower>-0.523599</lower>
          <upper>0.523599</upper>
          <effort>50000</effort>
          <velocity>50000</velocity>
        </limit>
        <dynamics>
          <damping>10</damping>
          <friction>0</friction>
          <spring_reference>0</spring_reference>
          <spring_stiffness>0</spring_stiffness>
        </dynamics>
        <use_parent_model_frame>1</use_parent_model_frame>
      </axis>
      <physics>
        <ode>
          <implicit_spring_damper>1</implicit_spring_damper>
          <cfm_damping>1</cfm_damping>
          <limit>
            <cfm>0.1</cfm>
            <erp>20</erp>
          </limit>
        </ode>
      </physics>
    </joint>
    <link name='torso_tripod_platform'>
      <pose>0.074 0 0.63 -0 -0 0</pose>
      <inertial>
        <pose>0 0 0 0 -0 0</pose>
        <mass>0.25</mass>
        <inertia>
          <ixx>0.000255208</ixx>
          <ixy>0</ixy>
          <ixz>0</ixz>
          <iyy>0.000255208</iyy>
          <iyz>0</iyz>
          <izz>0.00050625</izz>
        </inertia>
      </inertial>
      <collision name='torso_tripod_platform_collision'>
        <pose>-0.074 0 -0.63 0 -0 0</pose>
        <geometry>
          <mesh>
            <scale>0.001 0.001 0.001</scale>
            <uri>model://cer/meshes/stl/sim_cer_torso_tripod_platform_prt.stl</uri>
          </mesh>
        </geometry>
      </collision>
      <visual name='torso_tripod_platform_visual'>
        <pose>-0.074 0 -0.63 0 -0 0</pose>
        <geometry>
          <mesh>
            <scale>0.001 0.001 0.001</scale>
            <uri>model://cer/meshes/stl/sim_cer_torso_tripod_platform_prt.stl</uri>
          </mesh>
        </geometry>
      </visual>
    </link>
    <joint name='torso_tripod_pitch_eq' type='revolute'>
      <child>torso_tripod_platform</child>
      <parent>torso_tripod_pin_eq</parent>
      <axis>
        <xyz>0 1 -0</xyz>
        <limit>
          <lower>-0.523599</lower>
          <upper>0.523599</upper>
          <effort>50000</effort>
          <velocity>50000</velocity>
        </limit>
        <dynamics>
          <damping>1000</damping>
          <friction>0</friction>
          <spring_reference>0</spring_reference>
          <spring_stiffness>0</spring_stiffness>
        </dynamics>
        <use_parent_model_frame>1</use_parent_model_frame>
      </axis>
      <physics>
        <ode>
          <implicit_spring_damper>1</implicit_spring_damper>
          <cfm_damping>1</cfm_damping>
          <limit>
            <cfm>0</cfm>
            <erp>0.2</erp>
          </limit>
        </ode>
      </physics>
    </joint>
    <link name='torso_chest'>
      <pose>0.074 0 0.63 -0 -0 0</pose>
      <inertial>
        <pose>-0.036697 1e-05 0.206634 0 -0 0</pose>
        <mass>10</mass>
        <inertia>
          <ixx>0.187606</ixx>
          <ixy>0</ixy>
          <ixz>0.0385076</ixz>
          <iyy>0.16987</iyy>
          <iyz>-5.48478e-06</iyz>
          <izz>0.0906842</izz>
        </inertia>
      </inertial>
      <collision name='torso_chest_collision'>
        <pose>-0.074 0 -0.63 0 -0 0</pose>
        <geometry>
          <mesh>
            <scale>0.001 0.001 0.001</scale>
            <uri>model://cer/meshes/stl/sim_cer_torso_chest_prt.stl</uri>
          </mesh>
        </geometry>
      </collision>
      <visual name='torso_chest_visual'>
        <pose>-0.074 0 -0.63 0 -0 0</pose>
        <geometry>
          <mesh>
            <scale>0.001 0.001 0.001</scale>
            <uri>model://cer/meshes/stl/sim_cer_torso_chest_prt.stl</uri>
          </mesh>
        </geometry>
      </visual>
    </link>
    <joint name='torso_yaw' type='revolute'>
      <child>torso_chest</child>
      <parent>torso_tripod_platform</parent>
      <axis>
        <xyz>0 0 1</xyz>
        <limit>
          <lower>-1.0472</lower>
          <upper>1.0472</upper>
          <effort>50000</effort>
          <velocity>50000</velocity>
        </limit>
        <dynamics>
          <damping>1</damping>
          <friction>0</friction>
          <spring_reference>0</spring_reference>
          <spring_stiffness>0</spring_stiffness>
        </dynamics>
        <use_parent_model_frame>1</use_parent_model_frame>
      </axis>
      <physics>
        <ode>
          <implicit_spring_damper>1</implicit_spring_damper>
          <cfm_damping>1</cfm_damping>
          <limit>
            <cfm>0</cfm>
            <erp>0.2</erp>
          </limit>
        </ode>
      </physics>
    </joint>
    <link name='l_clavicle'>
      <pose>-0.01 0.17 0.97 -0 -0 0</pose>
      <inertial>
        <pose>0 0 0 0 -0 0</pose>
        <mass>0.2</mass>
        <inertia>
          <ixx>0.000288</ixx>
          <ixy>0</ixy>
          <ixz>0</ixz>
          <iyy>0.000288</iyy>
          <iyz>0</iyz>
          <izz>0.000288</izz>
        </inertia>
      </inertial>
      <collision name='l_clavicle_collision'>
        <pose>0.01 -0.17 -0.97 0 -0 0</pose>
        <geometry>
          <mesh>
            <scale>0.001 0.001 0.001</scale>
            <uri>model://cer/meshes/stl/sim_cer_l_clavicle_prt.stl</uri>
          </mesh>
        </geometry>
      </collision>
      <visual name='l_clavicle_visual'>
        <pose>0.01 -0.17 -0.97 0 -0 0</pose>
        <geometry>
          <mesh>
            <scale>0.001 0.001 0.001</scale>
            <uri>model://cer/meshes/stl/sim_cer_l_clavicle_prt.stl</uri>
          </mesh>
        </geometry>
      </visual>
    </link>
    <joint name='l_shoulder_pitch' type='revolute'>
      <child>l_clavicle</child>
      <parent>torso_chest</parent>
      <axis>
        <xyz>0 -0.970296 -0.241922</xyz>
        <limit>
          <lower>-0.349066</lower>
          <upper>1.74533</upper>
          <effort>50000</effort>
          <velocity>50000</velocity>
        </limit>
        <dynamics>
          <damping>1</damping>
          <friction>0</friction>
          <spring_reference>0</spring_reference>
          <spring_stiffness>0</spring_stiffness>
        </dynamics>
        <use_parent_model_frame>1</use_parent_model_frame>
      </axis>
      <physics>
        <ode>
          <implicit_spring_damper>1</implicit_spring_damper>
          <cfm_damping>1</cfm_damping>
          <limit>
            <cfm>0</cfm>
            <erp>0.2</erp>
          </limit>
        </ode>
      </physics>
    </joint>
    <link name='l_shoulder'>
      <pose>-0.01 0.17 0.97 -0 -0 0</pose>
      <inertial>
        <pose>0 0.034 -0.055 0 -0 0</pose>
        <mass>1</mass>
        <inertia>
          <ixx>0.00140833</ixx>
          <ixy>0</ixy>
          <ixz>0</ixz>
          <iyy>0.00140833</iyy>
          <iyz>0</iyz>
          <izz>0.0008</izz>
        </inertia>
      </inertial>
      <collision name='l_shoulder_collision'>
        <pose>0.01 -0.17 -0.97 0 -0 0</pose>
        <geometry>
          <mesh>
            <scale>0.001 0.001 0.001</scale>
            <uri>model://cer/meshes/stl/sim_cer_l_shoulder_prt.stl</uri>
          </mesh>
        </geometry>
      </collision>
      <visual name='l_shoulder_visual'>
        <pose>0.01 -0.17 -0.97 0 -0 0</pose>
        <geometry>
          <mesh>
            <scale>0.001 0.001 0.001</scale>
            <uri>model://cer/meshes/stl/sim_cer_l_shoulder_prt.stl</uri>
          </mesh>
        </geometry>
      </visual>
    </link>
    <joint name='l_shoulder_roll' type='revolute'>
      <child>l_shoulder</child>
      <parent>l_clavicle</parent>
      <axis>
        <xyz>1 0 0</xyz>
        <limit>
          <lower>-0.174533</lower>
          <upper>1.74533</upper>
          <effort>50000</effort>
          <velocity>50000</velocity>
        </limit>
        <dynamics>
          <damping>1</damping>
          <friction>0</friction>
          <spring_reference>0</spring_reference>
          <spring_stiffness>0</spring_stiffness>
        </dynamics>
        <use_parent_model_frame>1</use_parent_model_frame>
      </axis>
      <physics>
        <ode>
          <implicit_spring_damper>1</implicit_spring_damper>
          <cfm_damping>1</cfm_damping>
          <limit>
            <cfm>0</cfm>
            <erp>0.2</erp>
          </limit>
        </ode>
      </physics>
    </joint>
    <link name='l_upperarm'>
      <pose>-0.01 0.204 0.86 -0 -0 0</pose>
      <inertial>
        <pose>0 0 -0.0705 0 -0 0</pose>
        <mass>1</mass>
        <inertia>
          <ixx>0.00200831</ixx>
          <ixy>0</ixy>
          <ixz>0</ixz>
          <iyy>0.00200831</iyy>
          <iyz>0</iyz>
          <izz>0.000703125</izz>
        </inertia>
      </inertial>
      <collision name='l_upperarm_collision'>
        <pose>0.01 -0.204 -0.86 0 -0 0</pose>
        <geometry>
          <mesh>
            <scale>0.001 0.001 0.001</scale>
            <uri>model://cer/meshes/stl/sim_cer_l_upperarm_prt.stl</uri>
          </mesh>
        </geometry>
      </collision>
      <visual name='l_upperarm_visual'>
        <pose>0.01 -0.204 -0.86 0 -0 0</pose>
        <geometry>
          <mesh>
            <scale>0.001 0.001 0.001</scale>
            <uri>model://cer/meshes/stl/sim_cer_l_upperarm_prt.stl</uri>
          </mesh>
        </geometry>
      </visual>
    </link>
    <joint name='l_shoulder_yaw' type='revolute'>
      <child>l_upperarm</child>
      <parent>l_shoulder</parent>
      <axis>
        <xyz>0 0 1</xyz>
        <limit>
          <lower>-1.5708</lower>
          <upper>1.5708</upper>
          <effort>50000</effort>
          <velocity>50000</velocity>
        </limit>
        <dynamics>
          <damping>1</damping>
          <friction>0</friction>
          <spring_reference>0</spring_reference>
          <spring_stiffness>0</spring_stiffness>
        </dynamics>
        <use_parent_model_frame>1</use_parent_model_frame>
      </axis>
      <physics>
        <ode>
          <implicit_spring_damper>1</implicit_spring_damper>
          <cfm_damping>1</cfm_damping>
          <limit>
            <cfm>0</cfm>
            <erp>0.2</erp>
          </limit>
        </ode>
      </physics>
    </joint>
    <link name='l_forearm'>
      <pose>-0.01 0.204 0.719 -0 -0 0</pose>
      <inertial>
        <pose>0 0 -0.0355 0 -0 0</pose>
        <mass>0.5</mass>
        <inertia>
          <ixx>0.000363167</ixx>
          <ixy>0</ixy>
          <ixz>0</ixz>
          <iyy>0.000363167</iyy>
          <iyz>0</iyz>
          <izz>0.00030625</izz>
        </inertia>
      </inertial>
      <collision name='l_forearm_collision'>
        <pose>0.01 -0.204 -0.719 0 -0 0</pose>
        <geometry>
          <mesh>
            <scale>0.001 0.001 0.001</scale>
            <uri>model://cer/meshes/stl/sim_cer_l_forearm_prt.stl</uri>
          </mesh>
        </geometry>
      </collision>
      <visual name='l_forearm_visual'>
        <pose>0.01 -0.204 -0.719 0 -0 0</pose>
        <geometry>
          <mesh>
            <scale>0.001 0.001 0.001</scale>
            <uri>model://cer/meshes/stl/sim_cer_l_forearm_prt.stl</uri>
          </mesh>
        </geometry>
      </visual>
    </link>
    <joint name='l_elbow' type='revolute'>
      <child>l_forearm</child>
      <parent>l_upperarm</parent>
      <axis>
        <xyz>0 -1 0</xyz>
        <limit>
          <lower>0</lower>
          <upper>2.44346</upper>
          <effort>50000</effort>
          <velocity>50000</velocity>
        </limit>
        <dynamics>
          <damping>1</damping>
          <friction>0</friction>
          <spring_reference>0</spring_reference>
          <spring_stiffness>0</spring_stiffness>
        </dynamics>
        <use_parent_model_frame>1</use_parent_model_frame>
      </axis>
      <physics>
        <ode>
          <implicit_spring_damper>1</implicit_spring_damper>
          <cfm_damping>1</cfm_damping>
          <limit>
            <cfm>0</cfm>
            <erp>0.2</erp>
          </limit>
        </ode>
      </physics>
    </joint>
    <link name='l_wrist_tripod_base'>
      <pose>-0.01 0.204 0.648 -0 -0 0</pose>
      <inertial>
        <pose>0 0 0 0 -0 0</pose>
        <mass>0.2</mass>
        <inertia>
          <ixx>0.000102917</ixx>
          <ixy>0</ixy>
          <ixz>0</ixz>
          <iyy>0.000102917</iyy>
          <iyz>0</iyz>
          <izz>0.0002025</izz>
        </inertia>
      </inertial>
      <collision name='l_wrist_tripod_base_collision'>
        <pose>0.01 -0.204 -0.648 0 -0 0</pose>
        <geometry>
          <mesh>
            <scale>0.001 0.001 0.001</scale>
            <uri>model://cer/meshes/stl/sim_cer_l_wrist_tripod_base_prt.stl</uri>
          </mesh>
        </geometry>
      </collision>
      <visual name='l_wrist_tripod_base_visual'>
        <pose>0.01 -0.204 -0.648 0 -0 0</pose>
        <geometry>
          <mesh>
            <scale>0.001 0.001 0.001</scale>
            <uri>model://cer/meshes/stl/sim_cer_l_wrist_tripod_base_prt.stl</uri>
          </mesh>
        </geometry>
      </visual>
    </link>
    <joint name='l_wrist_prosupination' type='revolute'>
      <child>l_wrist_tripod_base</child>
      <parent>l_forearm</parent>
      <axis>
        <xyz>0 0 1</xyz>
        <limit>
          <lower>-1.5708</lower>
          <upper>1.5708</upper>
          <effort>50000</effort>
          <velocity>50000</velocity>
        </limit>
        <dynamics>
          <damping>1</damping>
          <friction>0</friction>
          <spring_reference>0</spring_reference>
          <spring_stiffness>0</spring_stiffness>
        </dynamics>
        <use_parent_model_frame>1</use_parent_model_frame>
      </axis>
      <physics>
        <ode>
          <implicit_spring_damper>1</implicit_spring_damper>
          <cfm_damping>1</cfm_damping>
          <limit>
            <cfm>0</cfm>
            <erp>0.2</erp>
          </limit>
        </ode>
      </physics>
    </joint>
    <link name='l_wrist_tripod_slider_eq'>
      <pose>-0.01 0.204 0.719 -0 -0 0</pose>
      <inertial>
        <pose>0 0 -0.181 0 -0 0</pose>
        <mass>0.2</mass>
        <inertia>
          <ixx>0.000886667</ixx>
          <ixy>0</ixy>
          <ixz>0</ixz>
          <iyy>0.000886667</iyy>
          <iyz>0</iyz>
          <izz>0.00016</izz>
        </inertia>
      </inertial>
      <collision name='l_wrist_tripod_slider_eq_collision'>
        <pose>0.01 -0.204 -0.719 0 -0 0</pose>
        <geometry>
          <mesh>
            <scale>0.001 0.001 0.001</scale>
            <uri>model://cer/meshes/stl/sim_cer_l_wrist_tripod_slider_prt.stl</uri>
          </mesh>
        </geometry>
      </collision>
      <visual name='l_wrist_tripod_slider_eq_visual'>
        <pose>0.01 -0.204 -0.719 0 -0 0</pose>
        <geometry>
          <mesh>
            <scale>0.001 0.001 0.001</scale>
            <uri>model://cer/meshes/stl/sim_cer_l_wrist_tripod_slider_prt.stl</uri>
          </mesh>
        </geometry>
      </visual>
    </link>
    <joint name='l_wrist_tripod_heave_eq' type='prismatic'>
      <child>l_wrist_tripod_slider_eq</child>
      <parent>l_wrist_tripod_base</parent>
      <axis>
        <xyz>0 -0 -1</xyz>
        <limit>
          <lower>0.0</lower>
          <upper>0.12</upper>
          <effort>50000</effort>
          <velocity>50000</velocity>
        </limit>
        <dynamics>
          <damping>1</damping>
          <friction>0</friction>
          <spring_reference>0</spring_reference>
          <spring_stiffness>0</spring_stiffness>
        </dynamics>
        <use_parent_model_frame>1</use_parent_model_frame>
      </axis>
      <physics>
        <ode>
          <implicit_spring_damper>1</implicit_spring_damper>
          <cfm_damping>1</cfm_damping>
          <limit>
            <cfm>0</cfm>
            <erp>0.2</erp>
          </limit>
        </ode>
      </physics>
    </joint>
    <link name='l_wrist_tripod_pin_eq'>
      <pose>-0.01 0.204 0.428 2.30723 1.57079 2.30723</pose>
      <inertial>
        <pose>0 0 0 0 -0 0</pose>
        <mass>0.2</mass>
        <inertia>
          <ixx>0.000111667</ixx>
          <ixy>0</ixy>
          <ixz>0</ixz>
          <iyy>0.000111667</iyy>
          <iyz>0</iyz>
          <izz>1e-05</izz>
        </inertia>
      </inertial>
      <collision name='l_wrist_tripod_pin_eq_collision'>
        <pose>0 0 0 0 -0 0</pose>
        <geometry>
          <mesh>
            <scale>0.001 0.001 0.001</scale>
            <uri>model://cer/meshes/stl/sim_cer_l_wrist_tripod_pin_eq_prt.stl</uri>
          </mesh>
        </geometry>
      </collision>
      <visual name='l_wrist_tripod_pin_eq_visual'>
        <pose>0 0 0 0 -0 0</pose>
        <geometry>
          <mesh>
            <scale>0.001 0.001 0.001</scale>
            <uri>model://cer/meshes/stl/sim_cer_l_wrist_tripod_pin_eq_prt.stl</uri>
          </mesh>
        </geometry>
      </visual>
    </link>
    <joint name='l_wrist_tripod_roll_eq' type='revolute'>
      <child>l_wrist_tripod_pin_eq</child>
      <parent>l_wrist_tripod_slider_eq</parent>
      <axis>
        <xyz>1 0 0</xyz>
        <limit>
          <lower>-0.523599</lower>
          <upper>0.523599</upper>
          <effort>50000</effort>
          <velocity>50000</velocity>
        </limit>
        <dynamics>
          <damping>1</damping>
          <friction>0</friction>
          <spring_reference>0</spring_reference>
          <spring_stiffness>0</spring_stiffness>
        </dynamics>
        <use_parent_model_frame>1</use_parent_model_frame>
      </axis>
      <physics>
        <ode>
          <implicit_spring_damper>1</implicit_spring_damper>
          <cfm_damping>1</cfm_damping>
          <limit>
            <cfm>0</cfm>
            <erp>0.2</erp>
          </limit>
        </ode>
      </physics>
    </joint>
    <link name='l_hand_root'>
      <pose>-0.01 0.205 0.428 -0 -0 0</pose>
      <inertial>
        <pose>0 -0.001 -0.030193 0 -0 0</pose>
        <mass>0.5</mass>
        <inertia>
          <ixx>0.000277843</ixx>
          <ixy>0</ixy>
          <ixz>0</ixz>
          <iyy>0.000277843</iyy>
          <iyz>0</iyz>
          <izz>0.000141191</izz>
        </inertia>
      </inertial>
      <collision name='l_hand_root_collision'>
        <pose>0.01 -0.205 -0.428 0 -0 0</pose>
        <geometry>
          <mesh>
            <scale>0.001 0.001 0.001</scale>
            <uri>model://cer/meshes/stl/sim_cer_l_hand_root_prt.stl</uri>
          </mesh>
        </geometry>
      </collision>
      <visual name='l_hand_root_visual'>
        <pose>0.01 -0.205 -0.428 0 -0 0</pose>
        <geometry>
          <mesh>
            <scale>0.001 0.001 0.001</scale>
            <uri>model://cer/meshes/stl/sim_cer_l_hand_root_prt.stl</uri>
          </mesh>
        </geometry>
      </visual>
    </link>
    <joint name='l_wrist_tripod_pitch_eq' type='revolute'>
      <child>l_hand_root</child>
      <parent>l_wrist_tripod_pin_eq</parent>
      <axis>
        <xyz>0 -1 0</xyz>
        <limit>
          <lower>-0.523599</lower>
          <upper>0.523599</upper>
          <effort>50000</effort>
          <velocity>50000</velocity>
        </limit>
        <dynamics>
          <damping>1</damping>
          <friction>0</friction>
          <spring_reference>0</spring_reference>
          <spring_stiffness>0</spring_stiffness>
        </dynamics>
        <use_parent_model_frame>1</use_parent_model_frame>
      </axis>
      <physics>
        <ode>
          <implicit_spring_damper>1</implicit_spring_damper>
          <cfm_damping>1</cfm_damping>
          <limit>
            <cfm>0</cfm>
            <erp>0.2</erp>
          </limit>
        </ode>
      </physics>
    </joint>
    <link name='l_hand_paddle'>
      <pose>-0.01 0.19139 0.360023 -0 -0 0</pose>
      <inertial>
        <pose>0 0 -0.0387 0 -0 0</pose>
        <mass>0.1</mass>
        <inertia>
          <ixx>7.95585e-05</ixx>
          <ixy>0</ixy>
          <ixz>0</ixz>
          <iyy>0.000102575</iyy>
          <iyz>0</iyz>
          <izz>2.78549e-05</izz>
        </inertia>
      </inertial>
      <collision name='l_hand_paddle_collision'>
        <pose>0.01 -0.19139 -0.360023 0 -0 0</pose>
        <geometry>
          <mesh>
            <scale>0.001 0.001 0.001</scale>
            <uri>model://cer/meshes/stl/sim_cer_l_hand_paddle_prt.stl</uri>
          </mesh>
        </geometry>
      </collision>
      <visual name='l_hand_paddle_visual'>
        <pose>0.01 -0.19139 -0.360023 0 -0 0</pose>
        <geometry>
          <mesh>
            <scale>0.001 0.001 0.001</scale>
            <uri>model://cer/meshes/stl/sim_cer_l_hand_paddle_prt.stl</uri>
          </mesh>
        </geometry>
      </visual>
    </link>
    <joint name='l_hand_paddle_joint' type='revolute'>
      <child>l_hand_paddle</child>
      <parent>l_hand_root</parent>
      <axis>
        <xyz>-1 0 -0</xyz>
        <limit>
          <lower>0</lower>
          <upper>1.0472</upper>
          <effort>50000</effort>
          <velocity>50000</velocity>
        </limit>
        <dynamics>
          <damping>1</damping>
          <friction>0</friction>
          <spring_reference>0</spring_reference>
          <spring_stiffness>0</spring_stiffness>
        </dynamics>
        <use_parent_model_frame>1</use_parent_model_frame>
      </axis>
      <physics>
        <ode>
          <implicit_spring_damper>1</implicit_spring_damper>
          <cfm_damping>1</cfm_damping>
          <limit>
            <cfm>0</cfm>
            <erp>0.2</erp>
          </limit>
        </ode>
      </physics>
    </joint>
    <link name='l_hand_thumb'>
      <pose>-0.01 0.184352 0.385156 -0 -0 0</pose>
      <inertial>
        <pose>0 -0.025716 -0.018464 0 -0 0</pose>
        <mass>0.1</mass>
        <inertia>
          <ixx>5.68818e-05</ixx>
          <ixy>0</ixy>
          <ixz>0</ixz>
          <iyy>2.87259e-05</iyy>
          <iyz>-2.49756e-05</iyz>
          <izz>3.69449e-05</izz>
        </inertia>
      </inertial>
      <collision name='l_hand_thumb_collision'>
        <pose>0.01 -0.184352 -0.385156 0 -0 0</pose>
        <geometry>
          <mesh>
            <scale>0.001 0.001 0.001</scale>
            <uri>model://cer/meshes/stl/sim_cer_l_hand_thumb_prt.stl</uri>
          </mesh>
        </geometry>
      </collision>
      <visual name='l_hand_thumb_visual'>
        <pose>0.01 -0.184352 -0.385156 0 -0 0</pose>
        <geometry>
          <mesh>
            <scale>0.001 0.001 0.001</scale>
            <uri>model://cer/meshes/stl/sim_cer_l_hand_thumb_prt.stl</uri>
          </mesh>
        </geometry>
      </visual>
    </link>
    <joint name='l_hand_thumb_joint' type='revolute'>
      <child>l_hand_thumb</child>
      <parent>l_hand_root</parent>
      <axis>
        <xyz>1 0 0</xyz>
        <limit>
          <lower>0</lower>
          <upper>1.22173</upper>
          <effort>50000</effort>
          <velocity>50000</velocity>
        </limit>
        <dynamics>
          <damping>1</damping>
          <friction>0</friction>
          <spring_reference>0</spring_reference>
          <spring_stiffness>0</spring_stiffness>
        </dynamics>
        <use_parent_model_frame>1</use_parent_model_frame>
      </axis>
      <physics>
        <ode>
          <implicit_spring_damper>1</implicit_spring_damper>
          <cfm_damping>1</cfm_damping>
          <limit>
            <cfm>0</cfm>
            <erp>0.2</erp>
          </limit>
        </ode>
      </physics>
    </joint>
    <link name='neck'>
      <pose>-0.02 0.000647 1 -0 -0 0</pose>
      <inertial>
        <pose>0.005658 -0.000647 0.06232 0 -0 0</pose>
        <mass>0.5</mass>
        <inertia>
          <ixx>0.00110442</ixx>
          <ixy>0</ixy>
          <ixz>-6.96774e-05</ixz>
          <iyy>0.00111727</iyy>
          <iyz>0</iyz>
          <izz>0.000112854</izz>
        </inertia>
      </inertial>
      <collision name='neck_collision'>
        <pose>0.02 -0.000647 -1 0 -0 0</pose>
        <geometry>
          <mesh>
            <scale>0.001 0.001 0.001</scale>
            <uri>model://cer/meshes/stl/sim_cer_neck_prt.stl</uri>
          </mesh>
        </geometry>
      </collision>
      <visual name='neck_visual'>
        <pose>0.02 -0.000647 -1 0 -0 0</pose>
        <geometry>
          <mesh>
            <scale>0.001 0.001 0.001</scale>
            <uri>model://cer/meshes/stl/sim_cer_neck_prt.stl</uri>
          </mesh>
        </geometry>
      </visual>
    </link>
    <joint name='neck_pitch' type='revolute'>
      <child>neck</child>
      <parent>torso_chest</parent>
      <axis>
        <xyz>0 1 -0</xyz>
        <limit>
          <lower>-0.523599</lower>
          <upper>1.39626</upper>
          <effort>50000</effort>
          <velocity>50000</velocity>
        </limit>
        <dynamics>
          <damping>1</damping>
          <friction>0</friction>
          <spring_reference>0</spring_reference>
          <spring_stiffness>0</spring_stiffness>
        </dynamics>
        <use_parent_model_frame>1</use_parent_model_frame>
      </axis>
      <physics>
        <ode>
          <implicit_spring_damper>1</implicit_spring_damper>
          <cfm_damping>1</cfm_damping>
          <limit>
            <cfm>0</cfm>
            <erp>0.2</erp>
          </limit>
        </ode>
      </physics>
    </joint>
    <link name='head'>
      <pose>-0.008321 0 1.15838 -0 -0 0</pose>
      <inertial>
        <pose>0.048654 -2e-06 -0.00409 0 -0 0</pose>
        <mass>2</mass>
        <inertia>
          <ixx>0.0133792</ixx>
          <ixy>-1.68274e-07</ixy>
          <ixz>0.000330609</ixz>
          <iyy>0.00439722</iyy>
          <iyz>0</iyz>
          <izz>0.0119116</izz>
        </inertia>
      </inertial>
      <collision name='head_collision'>
        <pose>0.008321 0 -1.15838 0 -0 0</pose>
        <geometry>
          <mesh>
            <scale>0.001 0.001 0.001</scale>
            <uri>model://cer/meshes/stl/sim_cer_head_prt.stl</uri>
          </mesh>
        </geometry>
        <surface>
          <contact>
            <ode/>
          </contact>
          <friction>
            <ode/>
          </friction>
        </surface>
        <surface>
          <contact>
            <ode/>
          </contact>
          <friction>
            <ode/>
          </friction>
        </surface>
        <surface>
          <contact>
            <ode/>
          </contact>
          <friction>
            <ode/>
          </friction>
        </surface>
      </collision>
      <visual name='head_visual'>
        <pose>0.008321 0 -1.15838 0 -0 0</pose>
        <geometry>
          <mesh>
            <scale>0.001 0.001 0.001</scale>
            <uri>model://cer/meshes/stl/sim_cer_head_prt.stl</uri>
          </mesh>
        </geometry>
      </visual>
      <velocity_decay/>
      <sensor name='left_camera' type='camera'>
        <always_on>1</always_on>
        <update_rate>30</update_rate>
        <pose>0.066821 0.0325 -0.06838 0 -0 0</pose>
        <camera name='__default__'>
          <horizontal_fov>1.5708</horizontal_fov>
          <image>
            <width>320</width>
            <height>240</height>
          </image>
          <clip>
            <near>0.1</near>
            <far>100</far>
          </clip>
        </camera>
        <plugin name='left_camera_plugin' filename='libgazebo_yarp_camera.so'>
          <yarpConfigurationFile>model://cer/conf/gazebo_cer_left_camera.ini</yarpConfigurationFile>
        </plugin>
      </sensor>
      <velocity_decay/>
      <sensor name='right_camera' type='camera'>
        <always_on>1</always_on>
        <update_rate>30</update_rate>
        <pose>0.066821 -0.0325 -0.06838 0 -0 0</pose>
        <camera name='__default__'>
          <horizontal_fov>1.5708</horizontal_fov>
          <image>
            <width>320</width>
            <height>240</height>
          </image>
          <clip>
            <near>0.1</near>
            <far>100</far>
          </clip>
        </camera>
        <plugin name='right_camera_plugin' filename='libgazebo_yarp_camera.so'>
          <yarpConfigurationFile>model://cer/conf/gazebo_cer_right_camera.ini</yarpConfigurationFile>
        </plugin>
      </sensor>
      <gravity>1</gravity>
      <velocity_decay/>
      <self_collide>0</self_collide>
      <sensor name='asus_xtion' type='depth'>
        <always_on>1</always_on>
        <update_rate>30</update_rate>
        <pose>0.077021 0 0.04662 0 -0 0</pose>
        <camera name='__default__'>
          <horizontal_fov> 1.022593333 </horizontal_fov>
          <image>
            <width>320</width>
            <height>240</height>
            <format>R8G8B8</format>
          </image>
          <clip>
            <near>0.02</near>
            <far>3000</far>
          </clip>
        </camera>
   <!--     <plugin name='depth_camera_plugin' filename='libgazebo_yarp_depthCamera.so'>
          <yarpConfigurationFile>model://cer/conf/gazebo_cer_depthCamera.ini</yarpConfigurationFile>
        </plugin> -->
      </sensor>
    </link>
    <joint name='neck_yaw' type='revolute'>
      <child>head</child>
      <parent>neck</parent>
      <axis>
        <xyz>0.173648 0 0.984808</xyz>
        <limit>
          <lower>-1.39626</lower>
          <upper>1.39626</upper>
          <effort>50000</effort>
          <velocity>50000</velocity>
        </limit>
        <dynamics>
          <damping>1</damping>
          <friction>0</friction>
          <spring_reference>0</spring_reference>
          <spring_stiffness>0</spring_stiffness>
        </dynamics>
        <use_parent_model_frame>1</use_parent_model_frame>
      </axis>
      <physics>
        <ode>
          <implicit_spring_damper>1</implicit_spring_damper>
          <cfm_damping>1</cfm_damping>
          <limit>
            <cfm>0</cfm>
            <erp>0.2</erp>
          </limit>
        </ode>
      </physics>
    </joint>
    <link name='r_clavicle'>
      <pose>-0.01 -0.17 0.97 -0 -0 0</pose>
      <inertial>
        <pose>0 0 0 0 -0 0</pose>
        <mass>0.2</mass>
        <inertia>
          <ixx>0.000288</ixx>
          <ixy>0</ixy>
          <ixz>0</ixz>
          <iyy>0.000288</iyy>
          <iyz>0</iyz>
          <izz>0.000288</izz>
        </inertia>
      </inertial>
      <collision name='r_clavicle_collision'>
        <pose>0.01 0.17 -0.97 0 -0 0</pose>
        <geometry>
          <mesh>
            <scale>0.001 0.001 0.001</scale>
            <uri>model://cer/meshes/stl/sim_cer_r_clavicle_prt.stl</uri>
          </mesh>
        </geometry>
      </collision>
      <visual name='r_clavicle_visual'>
        <pose>0.01 0.17 -0.97 0 -0 0</pose>
        <geometry>
          <mesh>
            <scale>0.001 0.001 0.001</scale>
            <uri>model://cer/meshes/stl/sim_cer_r_clavicle_prt.stl</uri>
          </mesh>
        </geometry>
      </visual>
    </link>
    <joint name='r_shoulder_pitch' type='revolute'>
      <child>r_clavicle</child>
      <parent>torso_chest</parent>
      <axis>
        <xyz>0 -0.970296 0.241922</xyz>
        <limit>
          <lower>-0.349066</lower>
          <upper>1.74533</upper>
          <effort>50000</effort>
          <velocity>50000</velocity>
        </limit>
        <dynamics>
          <damping>1</damping>
          <friction>0</friction>
          <spring_reference>0</spring_reference>
          <spring_stiffness>0</spring_stiffness>
        </dynamics>
        <use_parent_model_frame>1</use_parent_model_frame>
      </axis>
      <physics>
        <ode>
          <implicit_spring_damper>1</implicit_spring_damper>
          <cfm_damping>1</cfm_damping>
          <limit>
            <cfm>0</cfm>
            <erp>0.2</erp>
          </limit>
        </ode>
      </physics>
    </joint>
    <link name='r_shoulder'>
      <pose>-0.01 -0.17 0.97 -0 -0 0</pose>
      <inertial>
        <pose>0 -0.034 -0.055 0 -0 0</pose>
        <mass>1</mass>
        <inertia>
          <ixx>0.00140833</ixx>
          <ixy>0</ixy>
          <ixz>0</ixz>
          <iyy>0.00140833</iyy>
          <iyz>0</iyz>
          <izz>0.0008</izz>
        </inertia>
      </inertial>
      <collision name='r_shoulder_collision'>
        <pose>0.01 0.17 -0.97 0 -0 0</pose>
        <geometry>
          <mesh>
            <scale>0.001 0.001 0.001</scale>
            <uri>model://cer/meshes/stl/sim_cer_r_shoulder_prt.stl</uri>
          </mesh>
        </geometry>
      </collision>
      <visual name='r_shoulder_visual'>
        <pose>0.01 0.17 -0.97 0 -0 0</pose>
        <geometry>
          <mesh>
            <scale>0.001 0.001 0.001</scale>
            <uri>model://cer/meshes/stl/sim_cer_r_shoulder_prt.stl</uri>
          </mesh>
        </geometry>
      </visual>
    </link>
    <joint name='r_shoulder_roll' type='revolute'>
      <child>r_shoulder</child>
      <parent>r_clavicle</parent>
      <axis>
        <xyz>-1 0 -0</xyz>
        <limit>
          <lower>-0.174533</lower>
          <upper>1.74533</upper>
          <effort>50000</effort>
          <velocity>50000</velocity>
        </limit>
        <dynamics>
          <damping>1</damping>
          <friction>0</friction>
          <spring_reference>0</spring_reference>
          <spring_stiffness>0</spring_stiffness>
        </dynamics>
        <use_parent_model_frame>1</use_parent_model_frame>
      </axis>
      <physics>
        <ode>
          <implicit_spring_damper>1</implicit_spring_damper>
          <cfm_damping>1</cfm_damping>
          <limit>
            <cfm>0</cfm>
            <erp>0.2</erp>
          </limit>
        </ode>
      </physics>
    </joint>
    <link name='r_upperarm'>
      <pose>-0.01 -0.204 0.86 -0 -0 0</pose>
      <inertial>
        <pose>0 0 -0.0705 0 -0 0</pose>
        <mass>1</mass>
        <inertia>
          <ixx>0.00200831</ixx>
          <ixy>0</ixy>
          <ixz>0</ixz>
          <iyy>0.00200831</iyy>
          <iyz>0</iyz>
          <izz>0.000703125</izz>
        </inertia>
      </inertial>
      <collision name='r_upperarm_collision'>
        <pose>0.01 0.204 -0.86 0 -0 0</pose>
        <geometry>
          <mesh>
            <scale>0.001 0.001 0.001</scale>
            <uri>model://cer/meshes/stl/sim_cer_r_upperarm_prt.stl</uri>
          </mesh>
        </geometry>
      </collision>
      <visual name='r_upperarm_visual'>
        <pose>0.01 0.204 -0.86 0 -0 0</pose>
        <geometry>
          <mesh>
            <scale>0.001 0.001 0.001</scale>
            <uri>model://cer/meshes/stl/sim_cer_r_upperarm_prt.stl</uri>
          </mesh>
        </geometry>
      </visual>
    </link>
    <joint name='r_shoulder_yaw' type='revolute'>
      <child>r_upperarm</child>
      <parent>r_shoulder</parent>
      <axis>
        <xyz>0 -0 -1</xyz>
        <limit>
          <lower>-1.5708</lower>
          <upper>1.5708</upper>
          <effort>50000</effort>
          <velocity>50000</velocity>
        </limit>
        <dynamics>
          <damping>1</damping>
          <friction>0</friction>
          <spring_reference>0</spring_reference>
          <spring_stiffness>0</spring_stiffness>
        </dynamics>
        <use_parent_model_frame>1</use_parent_model_frame>
      </axis>
      <physics>
        <ode>
          <implicit_spring_damper>1</implicit_spring_damper>
          <cfm_damping>1</cfm_damping>
          <limit>
            <cfm>0</cfm>
            <erp>0.2</erp>
          </limit>
        </ode>
      </physics>
    </joint>
    <link name='r_forearm'>
      <pose>-0.01 -0.204 0.719 -0 -0 0</pose>
      <inertial>
        <pose>0 0 -0.0355 0 -0 0</pose>
        <mass>0.5</mass>
        <inertia>
          <ixx>0.000363167</ixx>
          <ixy>0</ixy>
          <ixz>0</ixz>
          <iyy>0.000363167</iyy>
          <iyz>0</iyz>
          <izz>0.00030625</izz>
        </inertia>
      </inertial>
      <collision name='r_forearm_collision'>
        <pose>0.01 0.204 -0.719 0 -0 0</pose>
        <geometry>
          <mesh>
            <scale>0.001 0.001 0.001</scale>
            <uri>model://cer/meshes/stl/sim_cer_r_forearm_prt.stl</uri>
          </mesh>
        </geometry>
      </collision>
      <visual name='r_forearm_visual'>
        <pose>0.01 0.204 -0.719 0 -0 0</pose>
        <geometry>
          <mesh>
            <scale>0.001 0.001 0.001</scale>
            <uri>model://cer/meshes/stl/sim_cer_r_forearm_prt.stl</uri>
          </mesh>
        </geometry>
      </visual>
    </link>
    <joint name='r_elbow' type='revolute'>
      <child>r_forearm</child>
      <parent>r_upperarm</parent>
      <axis>
        <xyz>0 -1 0</xyz>
        <limit>
          <lower>0</lower>
          <upper>2.44346</upper>
          <effort>50000</effort>
          <velocity>50000</velocity>
        </limit>
        <dynamics>
          <damping>1</damping>
          <friction>0</friction>
          <spring_reference>0</spring_reference>
          <spring_stiffness>0</spring_stiffness>
        </dynamics>
        <use_parent_model_frame>1</use_parent_model_frame>
      </axis>
      <physics>
        <ode>
          <implicit_spring_damper>1</implicit_spring_damper>
          <cfm_damping>1</cfm_damping>
          <limit>
            <cfm>0</cfm>
            <erp>0.2</erp>
          </limit>
        </ode>
      </physics>
    </joint>
    <link name='r_wrist_tripod_base'>
      <pose>-0.01 -0.204 0.648 -0 -0 0</pose>
      <inertial>
        <pose>0 0 0 0 -0 0</pose>
        <mass>0.2</mass>
        <inertia>
          <ixx>0.000102917</ixx>
          <ixy>0</ixy>
          <ixz>0</ixz>
          <iyy>0.000102917</iyy>
          <iyz>0</iyz>
          <izz>0.0002025</izz>
        </inertia>
      </inertial>
      <collision name='r_wrist_tripod_base_collision'>
        <pose>0.01 0.204 -0.648 0 -0 0</pose>
        <geometry>
          <mesh>
            <scale>0.001 0.001 0.001</scale>
            <uri>model://cer/meshes/stl/sim_cer_r_wrist_tripod_base_prt.stl</uri>
          </mesh>
        </geometry>
      </collision>
      <visual name='r_wrist_tripod_base_visual'>
        <pose>0.01 0.204 -0.648 0 -0 0</pose>
        <geometry>
          <mesh>
            <scale>0.001 0.001 0.001</scale>
            <uri>model://cer/meshes/stl/sim_cer_r_wrist_tripod_base_prt.stl</uri>
          </mesh>
        </geometry>
      </visual>
    </link>
    <joint name='r_wrist_prosupination' type='revolute'>
      <child>r_wrist_tripod_base</child>
      <parent>r_forearm</parent>
      <axis>
        <xyz>0 -0 -1</xyz>
        <limit>
          <lower>-1.5708</lower>
          <upper>1.5708</upper>
          <effort>50000</effort>
          <velocity>50000</velocity>
        </limit>
        <dynamics>
          <damping>1</damping>
          <friction>0</friction>
          <spring_reference>0</spring_reference>
          <spring_stiffness>0</spring_stiffness>
        </dynamics>
        <use_parent_model_frame>1</use_parent_model_frame>
      </axis>
      <physics>
        <ode>
          <implicit_spring_damper>1</implicit_spring_damper>
          <cfm_damping>1</cfm_damping>
          <limit>
            <cfm>0</cfm>
            <erp>0.2</erp>
          </limit>
        </ode>
      </physics>
    </joint>
    <link name='r_wrist_tripod_slider_eq'>
      <pose>-0.01 -0.204 0.719 -0 -0 0</pose>
      <inertial>
        <pose>0 0 -0.181 0 -0 0</pose>
        <mass>0.2</mass>
        <inertia>
          <ixx>0.000886667</ixx>
          <ixy>0</ixy>
          <ixz>0</ixz>
          <iyy>0.000886667</iyy>
          <iyz>0</iyz>
          <izz>0.00016</izz>
        </inertia>
      </inertial>
      <collision name='r_wrist_tripod_slider_eq_collision'>
        <pose>0.01 0.204 -0.719 0 -0 0</pose>
        <geometry>
          <mesh>
            <scale>0.001 0.001 0.001</scale>
            <uri>model://cer/meshes/stl/sim_cer_r_wrist_tripod_slider_prt.stl</uri>
          </mesh>
        </geometry>
      </collision>
      <visual name='r_wrist_tripod_slider_eq_visual'>
        <pose>0.01 0.204 -0.719 0 -0 0</pose>
        <geometry>
          <mesh>
            <scale>0.001 0.001 0.001</scale>
            <uri>model://cer/meshes/stl/sim_cer_r_wrist_tripod_slider_prt.stl</uri>
          </mesh>
        </geometry>
      </visual>
    </link>
    <joint name='r_wrist_tripod_heave_eq' type='prismatic'>
      <child>r_wrist_tripod_slider_eq</child>
      <parent>r_wrist_tripod_base</parent>
      <axis>
        <xyz>0 -0 -1</xyz>
        <limit>
          <lower>0.0</lower>
          <upper>0.12</upper>
          <effort>50000</effort>
          <velocity>50000</velocity>
        </limit>
        <dynamics>
          <damping>1</damping>
          <friction>0</friction>
          <spring_reference>0</spring_reference>
          <spring_stiffness>0</spring_stiffness>
        </dynamics>
        <use_parent_model_frame>1</use_parent_model_frame>
      </axis>
      <physics>
        <ode>
          <implicit_spring_damper>1</implicit_spring_damper>
          <cfm_damping>1</cfm_damping>
          <limit>
            <cfm>0</cfm>
            <erp>0.2</erp>
          </limit>
        </ode>
      </physics>
    </joint>
    <link name='r_wrist_tripod_pin_eq'>
      <pose>-0.01 -0.204 0.428 3.14159 0 1.5708</pose>
      <inertial>
        <pose>0 0 0 0 -0 0</pose>
        <mass>0.2</mass>
        <inertia>
          <ixx>0.000111667</ixx>
          <ixy>0</ixy>
          <ixz>0</ixz>
          <iyy>1e-05</iyy>
          <iyz>0</iyz>
          <izz>0.000111667</izz>
        </inertia>
      </inertial>
      <collision name='r_wrist_tripod_pin_eq_collision'>
        <pose>0 0 0 0 -0 0</pose>
        <geometry>
          <mesh>
            <scale>0.001 0.001 0.001</scale>
            <uri>model://cer/meshes/stl/sim_cer_r_wrist_tripod_pin_eq_prt.stl</uri>
          </mesh>
        </geometry>
      </collision>
      <visual name='r_wrist_tripod_pin_eq_visual'>
        <pose>0 0 0 0 -0 0</pose>
        <geometry>
          <mesh>
            <scale>0.001 0.001 0.001</scale>
            <uri>model://cer/meshes/stl/sim_cer_r_wrist_tripod_pin_eq_prt.stl</uri>
          </mesh>
        </geometry>
      </visual>
    </link>
    <joint name='r_wrist_tripod_roll_eq' type='revolute'>
      <child>r_wrist_tripod_pin_eq</child>
      <parent>r_wrist_tripod_slider_eq</parent>
      <axis>
        <xyz>-1 0 -0</xyz>
        <limit>
          <lower>-0.523599</lower>
          <upper>0.523599</upper>
          <effort>50000</effort>
          <velocity>50000</velocity>
        </limit>
        <dynamics>
          <damping>1</damping>
          <friction>0</friction>
          <spring_reference>0</spring_reference>
          <spring_stiffness>0</spring_stiffness>
        </dynamics>
        <use_parent_model_frame>1</use_parent_model_frame>
      </axis>
      <physics>
        <ode>
          <implicit_spring_damper>1</implicit_spring_damper>
          <cfm_damping>1</cfm_damping>
          <limit>
            <cfm>0</cfm>
            <erp>0.2</erp>
          </limit>
        </ode>
      </physics>
    </joint>
    <link name='r_hand_root'>
      <pose>-0.01 -0.203 0.428 -0 -0 0</pose>
      <inertial>
        <pose>0 -0.001 -0.030193 0 -0 0</pose>
        <mass>0.5</mass>
        <inertia>
          <ixx>0.000277843</ixx>
          <ixy>0</ixy>
          <ixz>0</ixz>
          <iyy>0.000277843</iyy>
          <iyz>0</iyz>
          <izz>0.000141191</izz>
        </inertia>
      </inertial>
      <collision name='r_hand_root_collision'>
        <pose>0.01 0.203 -0.428 0 -0 0</pose>
        <geometry>
          <mesh>
            <scale>0.001 0.001 0.001</scale>
            <uri>model://cer/meshes/stl/sim_cer_r_hand_root_prt.stl</uri>
          </mesh>
        </geometry>
      </collision>
      <visual name='r_hand_root_visual'>
        <pose>0.01 0.203 -0.428 0 -0 0</pose>
        <geometry>
          <mesh>
            <scale>0.001 0.001 0.001</scale>
            <uri>model://cer/meshes/stl/sim_cer_r_hand_root_prt.stl</uri>
          </mesh>
        </geometry>
      </visual>
    </link>
    <joint name='r_wrist_tripod_pitch_eq' type='revolute'>
      <child>r_hand_root</child>
      <parent>r_wrist_tripod_pin_eq</parent>
      <axis>
        <xyz>-0 -1 0</xyz>
        <limit>
          <lower>-0.523599</lower>
          <upper>0.523599</upper>
          <effort>50000</effort>
          <velocity>50000</velocity>
        </limit>
        <dynamics>
          <damping>1</damping>
          <friction>0</friction>
          <spring_reference>0</spring_reference>
          <spring_stiffness>0</spring_stiffness>
        </dynamics>
        <use_parent_model_frame>1</use_parent_model_frame>
      </axis>
      <physics>
        <ode>
          <implicit_spring_damper>1</implicit_spring_damper>
          <cfm_damping>1</cfm_damping>
          <limit>
            <cfm>0</cfm>
            <erp>0.2</erp>
          </limit>
        </ode>
      </physics>
    </joint>
    <link name='r_hand_paddle'>
      <pose>-0.01 -0.19139 0.360023 -0 -0 0</pose>
      <inertial>
        <pose>0 0 -0.0387 0 -0 0</pose>
        <mass>0.1</mass>
        <inertia>
          <ixx>7.95585e-05</ixx>
          <ixy>0</ixy>
          <ixz>0</ixz>
          <iyy>0.000102575</iyy>
          <iyz>0</iyz>
          <izz>2.78549e-05</izz>
        </inertia>
      </inertial>
      <collision name='r_hand_paddle_collision'>
        <pose>0.01 0.19139 -0.360023 0 -0 0</pose>
        <geometry>
          <mesh>
            <scale>0.001 0.001 0.001</scale>
            <uri>model://cer/meshes/stl/sim_cer_r_hand_paddle_prt.stl</uri>
          </mesh>
        </geometry>
      </collision>
      <visual name='r_hand_paddle_visual'>
        <pose>0.01 0.19139 -0.360023 0 -0 0</pose>
        <geometry>
          <mesh>
            <scale>0.001 0.001 0.001</scale>
            <uri>model://cer/meshes/stl/sim_cer_r_hand_paddle_prt.stl</uri>
          </mesh>
        </geometry>
      </visual>
    </link>
    <joint name='r_hand_paddle_joint' type='revolute'>
      <child>r_hand_paddle</child>
      <parent>r_hand_root</parent>
      <axis>
        <xyz>1 0 0</xyz>
        <limit>
          <lower>0</lower>
          <upper>1.0472</upper>
          <effort>50000</effort>
          <velocity>50000</velocity>
        </limit>
        <dynamics>
          <damping>1</damping>
          <friction>0</friction>
          <spring_reference>0</spring_reference>
          <spring_stiffness>0</spring_stiffness>
        </dynamics>
        <use_parent_model_frame>1</use_parent_model_frame>
      </axis>
      <physics>
        <ode>
          <implicit_spring_damper>1</implicit_spring_damper>
          <cfm_damping>1</cfm_damping>
          <limit>
            <cfm>0</cfm>
            <erp>0.2</erp>
          </limit>
        </ode>
      </physics>
    </joint>
    <link name='r_hand_thumb'>
      <pose>-0.01 -0.184352 0.385156 -0 -0 0</pose>
      <inertial>
        <pose>0 0.025716 -0.018464 0 -0 0</pose>
        <mass>0.1</mass>
        <inertia>
          <ixx>5.68818e-05</ixx>
          <ixy>0</ixy>
          <ixz>0</ixz>
          <iyy>2.8726e-05</iyy>
          <iyz>2.49756e-05</iyz>
          <izz>3.69448e-05</izz>
        </inertia>
      </inertial>
      <collision name='r_hand_thumb_collision'>
        <pose>0.01 0.184352 -0.385156 0 -0 0</pose>
        <geometry>
          <mesh>
            <scale>0.001 0.001 0.001</scale>
            <uri>model://cer/meshes/stl/sim_cer_r_hand_thumb_prt.stl</uri>
          </mesh>
        </geometry>
      </collision>
      <visual name='r_hand_thumb_visual'>
        <pose>0.01 0.184352 -0.385156 0 -0 0</pose>
        <geometry>
          <mesh>
            <scale>0.001 0.001 0.001</scale>
            <uri>model://cer/meshes/stl/sim_cer_r_hand_thumb_prt.stl</uri>
          </mesh>
        </geometry>
      </visual>
    </link>
    <joint name='r_hand_thumb_joint' type='revolute'>
      <child>r_hand_thumb</child>
      <parent>r_hand_root</parent>
      <axis>
        <xyz>-1 -0 -0</xyz>
        <limit>
          <lower>0</lower>
          <upper>1.22173</upper>
          <effort>50000</effort>
          <velocity>50000</velocity>
        </limit>
        <dynamics>
          <damping>1</damping>
          <friction>0</friction>
          <spring_reference>0</spring_reference>
          <spring_stiffness>0</spring_stiffness>
        </dynamics>
        <use_parent_model_frame>1</use_parent_model_frame>
      </axis>
      <physics>
        <ode>
          <implicit_spring_damper>1</implicit_spring_damper>
          <cfm_damping>1</cfm_damping>
          <limit>
            <cfm>0</cfm>
            <erp>0.2</erp>
          </limit>
        </ode>
      </physics>
    </joint>
    <static>0</static>
    <plugin name='controlboard_torso_yaw' filename='libgazebo_yarp_controlboard.so'>
      <yarpConfigurationFile>model://cer/conf/gazebo_cer_torso_yaw.ini</yarpConfigurationFile>
    </plugin>
    <plugin name='controlboard_torso' filename='libgazebo_yarp_controlboard.so'>
      <yarpConfigurationFile>model://cer/conf/gazebo_cer_torso.ini</yarpConfigurationFile>
    </plugin>
    <plugin name='controlboard_torso_tripod' filename='tripodMotionControl.so'>
      <yarpConfigurationFile>model://cer/conf/gazebo_cer_torso_tripod.ini</yarpConfigurationFile>
    </plugin>
    <plugin name='controlboard_left_upper_arm' filename='libgazebo_yarp_controlboard.so'>
      <yarpConfigurationFile>model://cer/conf/gazebo_cer_left_upper_arm.ini</yarpConfigurationFile>
    </plugin>
    <plugin name='controlboard_left_wrist' filename='libgazebo_yarp_controlboard.so'>
      <yarpConfigurationFile>model://cer/conf/gazebo_cer_left_wrist.ini</yarpConfigurationFile>
    </plugin>
    <plugin name='controlboard_left_wrist_tripod' filename='tripodMotionControl.so'>
      <yarpConfigurationFile>model://cer/conf/gazebo_cer_left_wrist_tripod.ini</yarpConfigurationFile>
    </plugin>
    <plugin name='controlboard_right_upper_arm' filename='libgazebo_yarp_controlboard.so'>
      <yarpConfigurationFile>model://cer/conf/gazebo_cer_right_upper_arm.ini</yarpConfigurationFile>
    </plugin>
    <plugin name='controlboard_right_wrist' filename='libgazebo_yarp_controlboard.so'>
      <yarpConfigurationFile>model://cer/conf/gazebo_cer_right_wrist.ini</yarpConfigurationFile>
    </plugin>
    <plugin name='controlboard_right_wrist_tripod' filename='tripodMotionControl.so'>
      <yarpConfigurationFile>model://cer/conf/gazebo_cer_right_wrist_tripod.ini</yarpConfigurationFile>
    </plugin>
    <plugin name='controlboard_head' filename='libgazebo_yarp_controlboard.so'>
      <yarpConfigurationFile>model://cer/conf/gazebo_cer_head.ini</yarpConfigurationFile>
    </plugin>
    <plugin name='controlboard_left_hand' filename='libgazebo_yarp_controlboard.so'>
      <yarpConfigurationFile>model://cer/conf/gazebo_cer_left_hand.ini</yarpConfigurationFile>
    </plugin>
    <plugin name='controlboard_right_hand' filename='libgazebo_yarp_controlboard.so'>
      <yarpConfigurationFile>model://cer/conf/gazebo_cer_right_hand.ini</yarpConfigurationFile>
    </plugin>
    <plugin name='controlboard_mobile_base' filename='libgazebo_yarp_controlboard.so'>
      <yarpConfigurationFile>model://cer/conf/gazebo_cer_mobile_base.ini</yarpConfigurationFile>
    </plugin>
    <plugin name='controlboard_all' filename='libgazebo_yarp_controlboard.so'>
      <yarpConfigurationFile>model://cer/conf/gazebo_cer_all.ini</yarpConfigurationFile>
    </plugin>
    <plugin name='world_interface' filename='libgazebo_yarp_worldinterface.so'>
      <yarpConfigurationFile>model://cer_low_res/conf/worldInterface.ini</yarpConfigurationFile>
    </plugin>
  </model>
</sdf>
