<robot name="SIM_CER_ROBOT">
  <link name="mobile_base_body">
    <inertial>
      <origin xyz="0.0167169 0 0.201998" rpy="0 0 0"/>
      <mass value="16.0"/>
      <inertia ixx="0.331884" ixy="0.0" ixz="-0.0448172" iyy="0.34974" iyz="0.0" izz="0.21095"/>
    </inertial>
    <visual>
      <origin xyz="0 0 0" rpy="0 0 0"/>
      <geometry>
        <mesh filename="model://cer/meshes/stl/sim_cer_mobilebase_body_prt.stl" scale="0.001 0.001 0.001"/>
      </geometry>
      <material name="green">
        <color rgba="0 1 0 1"/>
      </material>
    </visual>
    <collision>
      <origin xyz="0 0 0" rpy="0 0 0"/>
      <geometry>
        <mesh filename="model://cer/meshes/stl/sim_cer_mobilebase_body_prt.stl" scale="0.001 0.001 0.001"/>
      </geometry>
    </collision>
  </link>
  <link name="base_link"/>
  <joint name="base_link_fixed_joint" type="fixed">
    <origin xyz="0.074 0 0.63" rpy="0 0 0"/>
    <parent link="mobile_base_body"/>
    <child link="base_link"/>
    <dynamics damping="0.1"/>
  </joint>
  <link name="base_center"/>
  <joint name="base_center_fixed_joint" type="fixed">
    <origin xyz="0 0 0.16" rpy="0 0 0"/>
    <parent link="mobile_base_body"/>
    <child link="base_center"/>
    <dynamics damping="0.1"/>
  </joint>
  <link name="mobile_base_r_tyre">
    <inertial>
      <origin xyz="0 -0.034423 0" rpy="0 0 0"/>
      <mass value="3.0"/>
      <inertia ixx="0.0200167" ixy="0.0" ixz="0.0" iyy="0.0376153" iyz="0.0" izz="0.0200167"/>
    </inertial>
    <visual>
      <origin xyz="0 0.15 -0.16" rpy="0 0 0"/>
      <geometry>
        <mesh filename="model://cer/meshes/stl/sim_cer_mobilebase_r_tyre_prt.stl" scale="0.001 0.001 0.001"/>
      </geometry>
      <material name="black">
        <color rgba="0 0 0 1"/>
      </material>
    </visual>
    <collision>
      <origin xyz="0 0.15 -0.16" rpy="0 0 0"/>
      <geometry>
        <mesh filename="model://cer/meshes/stl/sim_cer_mobilebase_r_tyre_prt.stl" scale="0.001 0.001 0.001"/>
      </geometry>
    </collision>
  </link>
  <joint name="mobile_base_r_wheel" type="revolute">
    <origin xyz="0 -0.15 0.16" rpy="0 0 0"/>
    <axis xyz="0.0 1.0 0.0"/>
    <parent link="mobile_base_body"/>
    <child link="mobile_base_r_tyre"/>
    <limit effort="50000" lower="-17.43583922742335" upper="17.43583922742335" velocity="50000"/>
    <dynamics damping="1.0"/>
  </joint>
  <link name="mobile_base_l_tyre">
    <inertial>
      <origin xyz="0 0.034423 0" rpy="0 0 0"/>
      <mass value="3.0"/>
      <inertia ixx="0.0200167" ixy="0.0" ixz="0.0" iyy="0.0376153" iyz="0.0" izz="0.0200167"/>
    </inertial>
    <visual>
      <origin xyz="0 -0.15 -0.16" rpy="0 0 0"/>
      <geometry>
        <mesh filename="model://cer/meshes/stl/sim_cer_mobilebase_l_tyre_prt.stl" scale="0.001 0.001 0.001"/>
      </geometry>
      <material name="red">
        <color rgba="1 0 0 1"/>
      </material>
    </visual>
    <collision>
      <origin xyz="0 -0.15 -0.16" rpy="0 0 0"/>
      <geometry>
        <mesh filename="model://cer/meshes/stl/sim_cer_mobilebase_l_tyre_prt.stl" scale="0.001 0.001 0.001"/>
      </geometry>
    </collision>
  </link>
  <joint name="mobile_base_l_wheel" type="revolute">
    <origin xyz="0 0.15 0.16" rpy="0 0 0"/>
    <axis xyz="0.0 1.0 0.0"/>
    <parent link="mobile_base_body"/>
    <child link="mobile_base_l_tyre"/>
    <limit effort="50000" lower="-17.43583922742335" upper="17.43583922742335" velocity="50000"/>
    <dynamics damping="1.0"/>
  </joint>
  <link name="torso_tripod_slider_eq">
    <inertial>
      <origin xyz="0.0109861 9.13935e-06 0.236044" rpy="0 0 0"/>
      <mass value="2.5"/>
      <inertia ixx="0.0334422" ixy="0.0" ixz="0.00203295" iyy="0.0329538" iyz="2.22187e-06" izz="0.022808"/>
    </inertial>
    <visual>
      <origin xyz="-0.074 0 -0.231" rpy="0 0 0"/>
      <geometry>
        <mesh filename="model://cer/meshes/stl/sim_cer_torso_tripod_slider_eq_prt.stl" scale="0.001 0.001 0.001"/>
      </geometry>
      <material name="blue">
        <color rgba="0 0 1 1"/>
      </material>
    </visual>
    <collision>
      <origin xyz="-0.074 0 -0.231" rpy="0 0 0"/>
      <geometry>
        <mesh filename="model://cer/meshes/stl/sim_cer_torso_tripod_slider_eq_prt.stl" scale="0.001 0.001 0.001"/>
      </geometry>
    </collision>
  </link>
  <joint name="torso_tripod_heave_eq" type="prismatic">
    <origin xyz="0.074 0 0.231" rpy="0 0 0"/>
    <axis xyz="0.0 0.0 1.0"/>
    <parent link="mobile_base_body"/>
    <child link="torso_tripod_slider_eq"/>
    <limit effort="50000" lower="-0.05" upper="0.15" velocity="50000"/>
    <dynamics damping="1.0"/>
  </joint>
  <link name="torso_tripod_pin_eq">
    <inertial>
      <origin xyz="0 0 0" rpy="0 0 0"/>
      <mass value="0.25"/>
      <inertia ixx="2.8125e-05" ixy="0.0" ixz="0.0" iyy="0.000222396" iyz="0.0" izz="0.000222396"/>
    </inertial>
    <visual>
      <origin xyz="0 0 0" rpy="0 0 0"/>
      <geometry>
        <mesh filename="model://cer/meshes/stl/sim_cer_torso_tripod_pin_eq_prt.stl" scale="0.001 0.001 0.001"/>
      </geometry>
      <material name="yellow">
        <color rgba="1 1 0 1"/>
      </material>
    </visual>
    <collision>
      <origin xyz="0 0 0" rpy="0 0 0"/>
      <geometry>
        <mesh filename="model://cer/meshes/stl/sim_cer_torso_tripod_pin_eq_prt.stl" scale="0.001 0.001 0.001"/>
      </geometry>
    </collision>
  </link>
  <joint name="torso_tripod_roll_eq" type="revolute">
    <origin xyz="0 0 0.399" rpy="3.141592653589793 0 0"/>
    <axis xyz="1.0 0.0 0.0"/>
    <parent link="torso_tripod_slider_eq"/>
    <child link="torso_tripod_pin_eq"/>
    <limit effort="50000" lower="-0.5235987755982988" upper="0.5235987755982988" velocity="50000"/>
    <dynamics damping="1.0"/>
  </joint>
  <link name="torso_tripod_platform">
    <inertial>
      <origin xyz="0 0 0" rpy="0 0 0"/>
      <mass value="0.25"/>
      <inertia ixx="0.000255208" ixy="0.0" ixz="0.0" iyy="0.000255208" iyz="0.0" izz="0.00050625"/>
    </inertial>
    <visual>
      <origin xyz="-0.074 0 -0.63" rpy="0 0 0"/>
      <geometry>
        <mesh filename="model://cer/meshes/stl/sim_cer_torso_tripod_platform_prt.stl" scale="0.001 0.001 0.001"/>
      </geometry>
      <material name="pink">
        <color rgba="1 0 1 1"/>
      </material>
    </visual>
    <collision>
      <origin xyz="-0.074 0 -0.63" rpy="0 0 0"/>
      <geometry>
        <mesh filename="model://cer/meshes/stl/sim_cer_torso_tripod_platform_prt.stl" scale="0.001 0.001 0.001"/>
      </geometry>
    </collision>
  </link>
  <joint name="torso_tripod_pitch_eq" type="revolute">
    <origin xyz="0 0 0" rpy="3.141592653589793 0 0"/>
    <axis xyz="0.0 1.0 0.0"/>
    <parent link="torso_tripod_pin_eq"/>
    <child link="torso_tripod_platform"/>
    <limit effort="50000" lower="-0.5235987755982988" upper="0.5235987755982988" velocity="50000"/>
    <dynamics damping="1.0"/>
  </joint>
  <link name="oriented_xfw_ylf_zup_torso_tripod_platform"/>
  <joint name="oriented_xfw_ylf_zup_torso_tripod_platform_fixed_joint" type="fixed">
    <origin xyz="0 0 0" rpy="0 0 0"/>
    <parent link="torso_tripod_platform"/>
    <child link="oriented_xfw_ylf_zup_torso_tripod_platform"/>
    <dynamics damping="0.1"/>
  </joint>
  <link name="oriented_xbk_yrg_zup_torso_tripod_platform"/>
  <joint name="oriented_xbk_yrg_zup_torso_tripod_platform_fixed_joint" type="fixed">
    <origin xyz="0 0 0" rpy="0 0 3.141592653589793"/>
    <parent link="torso_tripod_platform"/>
    <child link="oriented_xbk_yrg_zup_torso_tripod_platform"/>
    <dynamics damping="0.1"/>
  </joint>
  <link name="torso_chest">
    <inertial>
      <origin xyz="-0.0366965 9.62228e-06 0.206634" rpy="0 0 0"/>
      <mass value="10.0"/>
      <inertia ixx="0.187606" ixy="0.0" ixz="0.0385076" iyy="0.16987" iyz="-5.48478e-06" izz="0.0906842"/>
    </inertial>
    <visual>
      <origin xyz="-0.074 0 -0.63" rpy="0 0 0"/>
      <geometry>
        <mesh filename="model://cer/meshes/stl/sim_cer_torso_chest_prt.stl" scale="0.001 0.001 0.001"/>
      </geometry>
      <material name="cyan">
        <color rgba="0 1 1 1"/>
      </material>
    </visual>
    <collision>
      <origin xyz="-0.074 0 -0.63" rpy="0 0 0"/>
      <geometry>
        <mesh filename="model://cer/meshes/stl/sim_cer_torso_chest_prt.stl" scale="0.001 0.001 0.001"/>
      </geometry>
    </collision>
  </link>
  <joint name="torso_yaw" type="revolute">
    <origin xyz="0 0 0" rpy="0 0 0"/>
    <axis xyz="0.0 0.0 1.0"/>
    <parent link="torso_tripod_platform"/>
    <child link="torso_chest"/>
    <limit effort="50000" lower="-1.0471975511965976" upper="1.0471975511965976" velocity="50000"/>
    <dynamics damping="1.0"/>
  </joint>
  <link name="torso"/>
  <joint name="torso_fixed_joint" type="fixed">
    <origin xyz="-0.042 0 0.17" rpy="0 0 0"/>
    <parent link="torso_chest"/>
    <child link="torso"/>
    <dynamics damping="0.1"/>
  </joint>
  <link name="l_clavicle">
    <inertial>
      <origin xyz="0 0 0" rpy="0 0 0"/>
      <mass value="0.2"/>
      <inertia ixx="0.000288" ixy="0.0" ixz="0.0" iyy="0.000288" iyz="0.0" izz="0.000288"/>
    </inertial>
    <visual>
      <origin xyz="0.01 -0.17 -0.97" rpy="0 0 0"/>
      <geometry>
        <mesh filename="model://cer/meshes/stl/sim_cer_l_clavicle_prt.stl" scale="0.001 0.001 0.001"/>
      </geometry>
      <material name="green"/>
    </visual>
    <collision>
      <origin xyz="0.01 -0.17 -0.97" rpy="0 0 0"/>
      <geometry>
        <mesh filename="model://cer/meshes/stl/sim_cer_l_clavicle_prt.stl" scale="0.001 0.001 0.001"/>
      </geometry>
    </collision>
  </link>
  <joint name="l_shoulder_pitch" type="revolute">
    <origin xyz="-0.084 0.17 0.34" rpy="0 0 0"/>
    <axis xyz="0.0 -0.970296 -0.241922"/>
    <parent link="torso_chest"/>
    <child link="l_clavicle"/>
    <limit effort="50000" lower="-0.3490658503988659" upper="1.7453292519943295" velocity="50000"/>
    <dynamics damping="1.0"/>
  </joint>
  <link name="l_shoulder">
    <inertial>
      <origin xyz="0 0.034 -0.055" rpy="0 0 0"/>
      <mass value="1.0"/>
      <inertia ixx="0.00140833" ixy="0.0" ixz="0.0" iyy="0.00140833" iyz="0.0" izz="0.0008"/>
    </inertial>
    <visual>
      <origin xyz="0.01 -0.17 -0.97" rpy="0 0 0"/>
      <geometry>
        <mesh filename="model://cer/meshes/stl/sim_cer_l_shoulder_prt.stl" scale="0.001 0.001 0.001"/>
      </geometry>
      <material name="white">
        <color rgba="1 1 1 1"/>
      </material>
    </visual>
    <collision>
      <origin xyz="0.01 -0.17 -0.97" rpy="0 0 0"/>
      <geometry>
        <mesh filename="model://cer/meshes/stl/sim_cer_l_shoulder_prt.stl" scale="0.001 0.001 0.001"/>
      </geometry>
    </collision>
  </link>
  <joint name="l_shoulder_roll" type="revolute">
    <origin xyz="0 0 0" rpy="0 0 0"/>
    <axis xyz="1.0 0.0 0.0"/>
    <parent link="l_clavicle"/>
    <child link="l_shoulder"/>
    <limit effort="50000" lower="-0.17453292519943295" upper="1.7453292519943295" velocity="50000"/>
    <dynamics damping="1.0"/>
  </joint>
  <link name="l_upperarm">
    <inertial>
      <origin xyz="0 0 -0.0705" rpy="0 0 0"/>
      <mass value="1.0"/>
      <inertia ixx="0.00200831" ixy="0.0" ixz="0.0" iyy="0.00200831" iyz="0.0" izz="0.000703125"/>
    </inertial>
    <visual>
      <origin xyz="0.01 -0.204 -0.86" rpy="0 0 0"/>
      <geometry>
        <mesh filename="model://cer/meshes/stl/sim_cer_l_upperarm_prt.stl" scale="0.001 0.001 0.001"/>
      </geometry>
      <material name="dblue">
        <color rgba="0 0 0.8 1"/>
      </material>
    </visual>
    <collision>
      <origin xyz="0.01 -0.204 -0.86" rpy="0 0 0"/>
      <geometry>
        <mesh filename="model://cer/meshes/stl/sim_cer_l_upperarm_prt.stl" scale="0.001 0.001 0.001"/>
      </geometry>
    </collision>
  </link>
  <joint name="l_shoulder_yaw" type="revolute">
    <origin xyz="0 0.034 -0.11" rpy="0 0 0"/>
    <axis xyz="0.0 0.0 1.0"/>
    <parent link="l_shoulder"/>
    <child link="l_upperarm"/>
    <limit effort="50000" lower="-1.5707963267948966" upper="1.5707963267948966" velocity="50000"/>
    <dynamics damping="1.0"/>
  </joint>
  <link name="l_forearm">
    <inertial>
      <origin xyz="0 0 -0.0355" rpy="0 0 0"/>
      <mass value="0.5"/>
      <inertia ixx="0.000363167" ixy="0.0" ixz="0.0" iyy="0.000363167" iyz="0.0" izz="0.00030625"/>
    </inertial>
    <visual>
      <origin xyz="0.01 -0.204 -0.719" rpy="0 0 0"/>
      <geometry>
        <mesh filename="model://cer/meshes/stl/sim_cer_l_forearm_prt.stl" scale="0.001 0.001 0.001"/>
      </geometry>
      <material name="dgreen">
        <color rgba="0.1 0.8 0.1 1"/>
      </material>
    </visual>
    <collision>
      <origin xyz="0.01 -0.204 -0.719" rpy="0 0 0"/>
      <geometry>
        <mesh filename="model://cer/meshes/stl/sim_cer_l_forearm_prt.stl" scale="0.001 0.001 0.001"/>
      </geometry>
    </collision>
  </link>
  <joint name="l_elbow" type="revolute">
    <origin xyz="0 0 -0.141" rpy="0 0 0"/>
    <axis xyz="0.0 -1.0 0.0"/>
    <parent link="l_upperarm"/>
    <child link="l_forearm"/>
    <limit effort="50000" lower="0.0" upper="2.443460952792061" velocity="50000"/>
    <dynamics damping="1.0"/>
  </joint>
  <link name="l_wrist_tripod_base">
    <inertial>
      <origin xyz="0 0 0" rpy="0 0 0"/>
      <mass value="0.2"/>
      <inertia ixx="0.000102917" ixy="0.0" ixz="0.0" iyy="0.000102917" iyz="0.0" izz="0.0002025"/>
    </inertial>
    <visual>
      <origin xyz="0.01 -0.204 -0.648" rpy="0 0 0"/>
      <geometry>
        <mesh filename="model://cer/meshes/stl/sim_cer_l_wrist_tripod_base_prt.stl" scale="0.001 0.001 0.001"/>
      </geometry>
      <material name="gray">
        <color rgba="0.5 0.5 0.5 1"/>
      </material>
    </visual>
    <collision>
      <origin xyz="0.01 -0.204 -0.648" rpy="0 0 0"/>
      <geometry>
        <mesh filename="model://cer/meshes/stl/sim_cer_l_wrist_tripod_base_prt.stl" scale="0.001 0.001 0.001"/>
      </geometry>
    </collision>
  </link>
  <joint name="l_wrist_prosupination" type="revolute">
    <origin xyz="0 0 -0.071" rpy="0 0 0"/>
    <axis xyz="0.0 0.0 1.0"/>
    <parent link="l_forearm"/>
    <child link="l_wrist_tripod_base"/>
    <limit effort="50000" lower="-1.5707963267948966" upper="1.5707963267948966" velocity="50000"/>
    <dynamics damping="1.0"/>
  </joint>
  <link name="oriented_l_wrist_tripodbase"/>
  <joint name="oriented_l_wrist_tripodbase_fixed_joint" type="fixed">
    <origin xyz="0 0 0" rpy="3.141592653589793 0 -1.5707963267948966"/>
    <parent link="l_wrist_tripod_base"/>
    <child link="oriented_l_wrist_tripodbase"/>
    <dynamics damping="0.1"/>
  </joint>
  <link name="l_wrist_tripod_slider_eq">
    <inertial>
      <origin xyz="0 0 -0.181" rpy="0 0 0"/>
      <mass value="0.2"/>
      <inertia ixx="0.000886667" ixy="0.0" ixz="0.0" iyy="0.000886667" iyz="0.0" izz="0.00016"/>
    </inertial>
    <visual>
      <origin xyz="0.01 -0.204 -0.719" rpy="0 0 0"/>
      <geometry>
        <mesh filename="model://cer/meshes/stl/sim_cer_l_wrist_tripod_slider_prt.stl" scale="0.001 0.001 0.001"/>
      </geometry>
      <material name="green"/>
    </visual>
    <collision>
      <origin xyz="0.01 -0.204 -0.719" rpy="0 0 0"/>
      <geometry>
        <mesh filename="model://cer/meshes/stl/sim_cer_l_wrist_tripod_slider_prt.stl" scale="0.001 0.001 0.001"/>
      </geometry>
    </collision>
  </link>
  <joint name="l_wrist_tripod_heave_eq" type="prismatic">
    <origin xyz="0 0 0.071" rpy="0 0 0"/>
    <axis xyz="0.0 0.0 -1.0"/>
    <parent link="l_wrist_tripod_base"/>
    <child link="l_wrist_tripod_slider_eq"/>
    <limit effort="50000" lower="0.0" upper="0.12" velocity="50000"/>
    <dynamics damping="1.0"/>
  </joint>
  <link name="l_wrist_tripod_pin_eq">
    <inertial>
      <origin xyz="0 0 0" rpy="0 0 0"/>
      <mass value="0.2"/>
      <inertia ixx="0.000111667" ixy="0.0" ixz="0.0" iyy="0.000111667" iyz="0.0" izz="1e-05"/>
    </inertial>
    <visual>
      <origin xyz="0 0 0" rpy="0 0 0"/>
      <geometry>
        <mesh filename="model://cer/meshes/stl/sim_cer_l_wrist_tripod_pin_eq_prt.stl" scale="0.001 0.001 0.001"/>
      </geometry>
      <material name="black"/>
    </visual>
    <collision>
      <origin xyz="0 0 0" rpy="0 0 0"/>
      <geometry>
        <mesh filename="model://cer/meshes/stl/sim_cer_l_wrist_tripod_pin_eq_prt.stl" scale="0.001 0.001 0.001"/>
      </geometry>
    </collision>
  </link>
  <joint name="l_wrist_tripod_roll_eq" type="revolute">
    <origin xyz="0 0 -0.291" rpy="0 1.5707963267948966 0"/>
    <axis xyz="0.0 0.0 1.0"/>
    <parent link="l_wrist_tripod_slider_eq"/>
    <child link="l_wrist_tripod_pin_eq"/>
    <limit effort="50000" lower="-0.5235987755982988" upper="0.5235987755982988" velocity="50000"/>
    <dynamics damping="1.0"/>
  </joint>
  <link name="l_hand_root">
    <inertial>
      <origin xyz="0 -0.001 -0.030193" rpy="0 0 0"/>
      <mass value="0.5"/>
      <inertia ixx="0.000277843" ixy="0.0" ixz="0.0" iyy="0.000277843" iyz="0.0" izz="0.000141191"/>
    </inertial>
    <visual>
      <origin xyz="0.01 -0.205 -0.428" rpy="0 0 0"/>
      <geometry>
        <mesh filename="model://cer/meshes/stl/sim_cer_l_hand_root_prt.stl" scale="0.001 0.001 0.001"/>
      </geometry>
      <material name="red"/>
    </visual>
    <collision>
      <origin xyz="0.01 -0.205 -0.428" rpy="0 0 0"/>
      <geometry>
        <mesh filename="model://cer/meshes/stl/sim_cer_l_hand_root_prt.stl" scale="0.001 0.001 0.001"/>
      </geometry>
    </collision>
  </link>
  <joint name="l_wrist_tripod_pitch_eq" type="revolute">
    <origin xyz="0 0.001 0" rpy="0 -1.5707963267948966 0"/>
    <axis xyz="0.0 -1.0 0.0"/>
    <parent link="l_wrist_tripod_pin_eq"/>
    <child link="l_hand_root"/>
    <limit effort="50000" lower="-0.5235987755982988" upper="0.5235987755982988" velocity="50000"/>
    <dynamics damping="1.0"/>
  </joint>
  <link name="l_wrist"/>
  <joint name="l_wrist_fixed_joint" type="fixed">
    <origin xyz="0 -0.001 0" rpy="0 0 0"/>
    <parent link="l_hand_root"/>
    <child link="l_wrist"/>
    <dynamics damping="0.1"/>
  </joint>
  <link name="l_gripper"/>
  <joint name="l_gripper_fixed_joint" type="fixed">
    <origin xyz="0 -0.024941 -0.065778" rpy="3.141592653589793 1.221730955967807 -1.5707963267948968"/>
    <parent link="l_hand_root"/>
    <child link="l_gripper"/>
    <dynamics damping="0.1"/>
  </joint>
  <link name="l_hand_thumb">
    <inertial>
      <origin xyz="0 -0.0257160000315 -0.0184639999562" rpy="0 0 0"/>
      <mass value="0.1"/>
      <inertia ixx="5.68818e-05" ixy="0.0" ixz="0.0" iyy="2.87259e-05" iyz="-2.49756e-05" izz="3.69449e-05"/>
    </inertial>
    <visual>
      <origin xyz="0.01 -0.184352 -0.385156" rpy="0 0 0"/>
      <geometry>
        <mesh filename="model://cer/meshes/stl/sim_cer_l_hand_thumb_prt.stl" scale="0.001 0.001 0.001"/>
      </geometry>
      <material name="blue"/>
    </visual>
    <collision>
      <origin xyz="0.01 -0.184352 -0.385156" rpy="0 0 0"/>
      <geometry>
        <mesh filename="model://cer/meshes/stl/sim_cer_l_hand_thumb_prt.stl" scale="0.001 0.001 0.001"/>
      </geometry>
    </collision>
  </link>
  <joint name="l_hand_thumb_joint" type="revolute">
    <origin xyz="0 -0.020648 -0.042844" rpy="0 0 0"/>
    <axis xyz="1.0 0.0 0.0"/>
    <parent link="l_hand_root"/>
    <child link="l_hand_thumb"/>
    <limit effort="50000" lower="0.0" upper="1.2217304763960306" velocity="50000"/>
    <dynamics damping="1.0"/>
  </joint>
  <link name="l_hand_thumb_tip"/>
  <joint name="l_hand_thumb_tip_fixed_joint" type="fixed">
    <origin xyz="0 -0.0513860000782 -0.0458929999125" rpy="3.141592653589793 1.2217309542643466 -1.570796326794897"/>
    <parent link="l_hand_thumb"/>
    <child link="l_hand_thumb_tip"/>
    <dynamics damping="0.1"/>
  </joint>
  <link name="l_hand_paddle">
    <inertial>
      <origin xyz="0 0 -0.0387" rpy="0 0 0"/>
      <mass value="0.1"/>
      <inertia ixx="7.95585e-05" ixy="0.0" ixz="0.0" iyy="0.000102575" iyz="0.0" izz="2.78549e-05"/>
    </inertial>
    <visual>
      <origin xyz="0.01 -0.19139 -0.360023" rpy="0 0 0"/>
      <geometry>
        <mesh filename="model://cer/meshes/stl/sim_cer_l_hand_paddle_prt.stl" scale="0.001 0.001 0.001"/>
      </geometry>
      <material name="yellow"/>
    </visual>
    <collision>
      <origin xyz="0.01 -0.19139 -0.360023" rpy="0 0 0"/>
      <geometry>
        <mesh filename="model://cer/meshes/stl/sim_cer_l_hand_paddle_prt.stl" scale="0.001 0.001 0.001"/>
      </geometry>
    </collision>
  </link>
  <joint name="l_hand_paddle_joint" type="revolute">
    <origin xyz="0 -0.01361 -0.067977" rpy="0 0 0"/>
    <axis xyz="-1.0 0.0 0.0"/>
    <parent link="l_hand_root"/>
    <child link="l_hand_paddle"/>
    <limit effort="50000" lower="0.0" upper="1.0471975511965976" velocity="50000"/>
    <dynamics damping="1.0"/>
  </joint>
  <link name="l_hand_paddle_tip"/>
  <joint name="l_hand_paddle_tip_fixed_joint" type="fixed">
    <origin xyz="0 0 -0.084994" rpy="3.141592653589793 1.221730955967807 -1.5707963267948968"/>
    <parent link="l_hand_paddle"/>
    <child link="l_hand_paddle_tip"/>
    <dynamics damping="0.1"/>
  </joint>
  <link name="r_clavicle">
    <inertial>
      <origin xyz="0 0 0" rpy="0 0 0"/>
      <mass value="0.2"/>
      <inertia ixx="0.000288" ixy="0.0" ixz="0.0" iyy="0.000288" iyz="0.0" izz="0.000288"/>
    </inertial>
    <visual>
      <origin xyz="0.01 0.17 -0.97" rpy="0 0 0"/>
      <geometry>
        <mesh filename="model://cer/meshes/stl/sim_cer_r_clavicle_prt.stl" scale="0.001 0.001 0.001"/>
      </geometry>
      <material name="pink"/>
    </visual>
    <collision>
      <origin xyz="0.01 0.17 -0.97" rpy="0 0 0"/>
      <geometry>
        <mesh filename="model://cer/meshes/stl/sim_cer_r_clavicle_prt.stl" scale="0.001 0.001 0.001"/>
      </geometry>
    </collision>
  </link>
  <joint name="r_shoulder_pitch" type="revolute">
    <origin xyz="-0.084 -0.17 0.34" rpy="0 0 0"/>
    <axis xyz="0.0 -0.970296 0.241922"/>
    <parent link="torso_chest"/>
    <child link="r_clavicle"/>
    <limit effort="50000" lower="-0.3490658503988659" upper="1.7453292519943295" velocity="50000"/>
    <dynamics damping="1.0"/>
  </joint>
  <link name="r_shoulder">
    <inertial>
      <origin xyz="0 -0.034 -0.055" rpy="0 0 0"/>
      <mass value="1.0"/>
      <inertia ixx="0.00140833" ixy="0.0" ixz="0.0" iyy="0.00140833" iyz="0.0" izz="0.0008"/>
    </inertial>
    <visual>
      <origin xyz="0.01 0.17 -0.97" rpy="0 0 0"/>
      <geometry>
        <mesh filename="model://cer/meshes/stl/sim_cer_r_shoulder_prt.stl" scale="0.001 0.001 0.001"/>
      </geometry>
      <material name="cyan"/>
    </visual>
    <collision>
      <origin xyz="0.01 0.17 -0.97" rpy="0 0 0"/>
      <geometry>
        <mesh filename="model://cer/meshes/stl/sim_cer_r_shoulder_prt.stl" scale="0.001 0.001 0.001"/>
      </geometry>
    </collision>
  </link>
  <joint name="r_shoulder_roll" type="revolute">
    <origin xyz="0 0 0" rpy="0 0 0"/>
    <axis xyz="-1.0 0.0 0.0"/>
    <parent link="r_clavicle"/>
    <child link="r_shoulder"/>
    <limit effort="50000" lower="-0.17453292519943295" upper="1.7453292519943295" velocity="50000"/>
    <dynamics damping="1.0"/>
  </joint>
  <link name="r_upperarm">
    <inertial>
      <origin xyz="0 0 -0.0705" rpy="0 0 0"/>
      <mass value="1.0"/>
      <inertia ixx="0.00200831" ixy="0.0" ixz="0.0" iyy="0.00200831" iyz="0.0" izz="0.000703125"/>
    </inertial>
    <visual>
      <origin xyz="0.01 0.204 -0.86" rpy="0 0 0"/>
      <geometry>
        <mesh filename="model://cer/meshes/stl/sim_cer_r_upperarm_prt.stl" scale="0.001 0.001 0.001"/>
      </geometry>
      <material name="green"/>
    </visual>
    <collision>
      <origin xyz="0.01 0.204 -0.86" rpy="0 0 0"/>
      <geometry>
        <mesh filename="model://cer/meshes/stl/sim_cer_r_upperarm_prt.stl" scale="0.001 0.001 0.001"/>
      </geometry>
    </collision>
  </link>
  <joint name="r_shoulder_yaw" type="revolute">
    <origin xyz="0 -0.034 -0.11" rpy="0 0 0"/>
    <axis xyz="0.0 0.0 -1.0"/>
    <parent link="r_shoulder"/>
    <child link="r_upperarm"/>
    <limit effort="50000" lower="-1.5707963267948966" upper="1.5707963267948966" velocity="50000"/>
    <dynamics damping="1.0"/>
  </joint>
  <link name="r_forearm">
    <inertial>
      <origin xyz="0 0 -0.0355" rpy="0 0 0"/>
      <mass value="0.5"/>
      <inertia ixx="0.000363167" ixy="0.0" ixz="0.0" iyy="0.000363167" iyz="0.0" izz="0.00030625"/>
    </inertial>
    <visual>
      <origin xyz="0.01 0.204 -0.719" rpy="0 0 0"/>
      <geometry>
        <mesh filename="model://cer/meshes/stl/sim_cer_r_forearm_prt.stl" scale="0.001 0.001 0.001"/>
      </geometry>
      <material name="white"/>
    </visual>
    <collision>
      <origin xyz="0.01 0.204 -0.719" rpy="0 0 0"/>
      <geometry>
        <mesh filename="model://cer/meshes/stl/sim_cer_r_forearm_prt.stl" scale="0.001 0.001 0.001"/>
      </geometry>
    </collision>
  </link>
  <joint name="r_elbow" type="revolute">
    <origin xyz="0 0 -0.141" rpy="0 0 0"/>
    <axis xyz="0.0 -1.0 0.0"/>
    <parent link="r_upperarm"/>
    <child link="r_forearm"/>
    <limit effort="50000" lower="0.0" upper="2.443460952792061" velocity="50000"/>
    <dynamics damping="1.0"/>
  </joint>
  <link name="r_wrist_tripod_base">
    <inertial>
      <origin xyz="0 0 0" rpy="0 0 0"/>
      <mass value="0.2"/>
      <inertia ixx="0.000102917" ixy="0.0" ixz="0.0" iyy="0.000102917" iyz="0.0" izz="0.0002025"/>
    </inertial>
    <visual>
      <origin xyz="0.01 0.204 -0.648" rpy="0 0 0"/>
      <geometry>
        <mesh filename="model://cer/meshes/stl/sim_cer_r_wrist_tripod_base_prt.stl" scale="0.001 0.001 0.001"/>
      </geometry>
      <material name="dblue"/>
    </visual>
    <collision>
      <origin xyz="0.01 0.204 -0.648" rpy="0 0 0"/>
      <geometry>
        <mesh filename="model://cer/meshes/stl/sim_cer_r_wrist_tripod_base_prt.stl" scale="0.001 0.001 0.001"/>
      </geometry>
    </collision>
  </link>
  <joint name="r_wrist_prosupination" type="revolute">
    <origin xyz="0 0 -0.071" rpy="0 0 0"/>
    <axis xyz="0.0 0.0 -1.0"/>
    <parent link="r_forearm"/>
    <child link="r_wrist_tripod_base"/>
    <limit effort="50000" lower="-1.5707963267948966" upper="1.5707963267948966" velocity="50000"/>
    <dynamics damping="1.0"/>
  </joint>
  <link name="oriented_r_wrist_tripodbase"/>
  <joint name="oriented_r_wrist_tripodbase_fixed_joint" type="fixed">
    <origin xyz="0 0 0" rpy="3.141592653589793 0 1.5707963267948966"/>
    <parent link="r_wrist_tripod_base"/>
    <child link="oriented_r_wrist_tripodbase"/>
    <dynamics damping="0.1"/>
  </joint>
  <link name="r_wrist_tripod_slider_eq">
    <inertial>
      <origin xyz="0 0 -0.181" rpy="0 0 0"/>
      <mass value="0.2"/>
      <inertia ixx="0.000886667" ixy="0.0" ixz="0.0" iyy="0.000886667" iyz="0.0" izz="0.00016"/>
    </inertial>
    <visual>
      <origin xyz="0.01 0.204 -0.719" rpy="0 0 0"/>
      <geometry>
        <mesh filename="model://cer/meshes/stl/sim_cer_r_wrist_tripod_slider_prt.stl" scale="0.001 0.001 0.001"/>
      </geometry>
      <material name="dgreen"/>
    </visual>
    <collision>
      <origin xyz="0.01 0.204 -0.719" rpy="0 0 0"/>
      <geometry>
        <mesh filename="model://cer/meshes/stl/sim_cer_r_wrist_tripod_slider_prt.stl" scale="0.001 0.001 0.001"/>
      </geometry>
    </collision>
  </link>
  <joint name="r_wrist_tripod_heave_eq" type="prismatic">
    <origin xyz="0 0 0.071" rpy="0 0 0"/>
    <axis xyz="0.0 0.0 -1.0"/>
    <parent link="r_wrist_tripod_base"/>
    <child link="r_wrist_tripod_slider_eq"/>
    <limit effort="50000" lower="0.0" upper="0.12" velocity="50000"/>
    <dynamics damping="1.0"/>
  </joint>
  <link name="r_wrist_tripod_pin_eq">
    <inertial>
      <origin xyz="0 0 0" rpy="0 0 0"/>
      <mass value="0.2"/>
      <inertia ixx="0.000111667" ixy="0.0" ixz="0.0" iyy="1e-05" iyz="0.0" izz="0.000111667"/>
    </inertial>
    <visual>
      <origin xyz="0 0 0" rpy="0 0 0"/>
      <geometry>
        <mesh filename="model://cer/meshes/stl/sim_cer_r_wrist_tripod_pin_eq_prt.stl" scale="0.001 0.001 0.001"/>
      </geometry>
      <material name="gray"/>
    </visual>
    <collision>
      <origin xyz="0 0 0" rpy="0 0 0"/>
      <geometry>
        <mesh filename="model://cer/meshes/stl/sim_cer_r_wrist_tripod_pin_eq_prt.stl" scale="0.001 0.001 0.001"/>
      </geometry>
    </collision>
  </link>
  <joint name="r_wrist_tripod_roll_eq" type="revolute">
    <origin xyz="0 0 -0.291" rpy="3.141592653589793 0 1.5707963267948966"/>
    <axis xyz="0.0 -1.0 0.0"/>
    <parent link="r_wrist_tripod_slider_eq"/>
    <child link="r_wrist_tripod_pin_eq"/>
    <limit effort="50000" lower="-0.5235987755982988" upper="0.5235987755982988" velocity="50000"/>
    <dynamics damping="1.0"/>
  </joint>
  <link name="r_hand_root">
    <inertial>
      <origin xyz="0 -0.001 -0.030193" rpy="0 0 0"/>
      <mass value="0.5"/>
      <inertia ixx="0.000277843" ixy="0.0" ixz="0.0" iyy="0.000277843" iyz="0.0" izz="0.000141191"/>
    </inertial>
    <visual>
      <origin xyz="0.01 0.203 -0.428" rpy="0 0 0"/>
      <geometry>
        <mesh filename="model://cer/meshes/stl/sim_cer_r_hand_root_prt.stl" scale="0.001 0.001 0.001"/>
      </geometry>
      <material name="green"/>
    </visual>
    <collision>
      <origin xyz="0.01 0.203 -0.428" rpy="0 0 0"/>
      <geometry>
        <mesh filename="model://cer/meshes/stl/sim_cer_r_hand_root_prt.stl" scale="0.001 0.001 0.001"/>
      </geometry>
    </collision>
  </link>
  <joint name="r_wrist_tripod_pitch_eq" type="revolute">
    <origin xyz="0.001 0 0" rpy="3.141592653589793 0 1.5707963267948966"/>
    <axis xyz="0.0 -1.0 0.0"/>
    <parent link="r_wrist_tripod_pin_eq"/>
    <child link="r_hand_root"/>
    <limit effort="50000" lower="-0.5235987755982988" upper="0.5235987755982988" velocity="50000"/>
    <dynamics damping="1.0"/>
  </joint>
  <link name="r_wrist"/>
  <joint name="r_wrist_fixed_joint" type="fixed">
    <origin xyz="0 -0.001 0" rpy="0 0 0"/>
    <parent link="r_hand_root"/>
    <child link="r_wrist"/>
    <dynamics damping="0.1"/>
  </joint>
  <link name="r_gripper"/>
  <joint name="r_gripper_fixed_joint" type="fixed">
    <origin xyz="0 0.022941 -0.065778" rpy="0 1.221730955967806 1.5707963267948957"/>
    <parent link="r_hand_root"/>
    <child link="r_gripper"/>
    <dynamics damping="0.1"/>
  </joint>
  <link name="r_hand_paddle">
    <inertial>
      <origin xyz="0 0 -0.0387" rpy="0 0 0"/>
      <mass value="0.1"/>
      <inertia ixx="7.95585e-05" ixy="0.0" ixz="0.0" iyy="0.000102575" iyz="0.0" izz="2.78549e-05"/>
    </inertial>
    <visual>
      <origin xyz="0.01 0.19139 -0.360023" rpy="0 0 0"/>
      <geometry>
        <mesh filename="model://cer/meshes/stl/sim_cer_r_hand_paddle_prt.stl" scale="0.001 0.001 0.001"/>
      </geometry>
      <material name="black"/>
    </visual>
    <collision>
      <origin xyz="0.01 0.19139 -0.360023" rpy="0 0 0"/>
      <geometry>
        <mesh filename="model://cer/meshes/stl/sim_cer_r_hand_paddle_prt.stl" scale="0.001 0.001 0.001"/>
      </geometry>
    </collision>
  </link>
  <joint name="r_hand_paddle_joint" type="revolute">
    <origin xyz="0 0.01161 -0.067977" rpy="0 0 0"/>
    <axis xyz="1.0 0.0 0.0"/>
    <parent link="r_hand_root"/>
    <child link="r_hand_paddle"/>
    <limit effort="50000" lower="0.0" upper="1.0471975511965976" velocity="50000"/>
    <dynamics damping="1.0"/>
  </joint>
  <link name="r_hand_paddle_tip"/>
  <joint name="r_hand_paddle_tip_fixed_joint" type="fixed">
    <origin xyz="0 0 -0.084994" rpy="0 1.221730955967806 1.5707963267948957"/>
    <parent link="r_hand_paddle"/>
    <child link="r_hand_paddle_tip"/>
    <dynamics damping="0.1"/>
  </joint>
  <link name="r_hand_thumb">
    <inertial>
      <origin xyz="0 0.025716 -0.018464" rpy="0 0 0"/>
      <mass value="0.1"/>
      <inertia ixx="5.68818e-05" ixy="0.0" ixz="0.0" iyy="2.8726e-05" iyz="2.49756e-05" izz="3.69448e-05"/>
    </inertial>
    <visual>
      <origin xyz="0.01 0.184352 -0.385156" rpy="0 0 0"/>
      <geometry>
        <mesh filename="model://cer/meshes/stl/sim_cer_r_hand_thumb_prt.stl" scale="0.001 0.001 0.001"/>
      </geometry>
      <material name="red"/>
    </visual>
    <collision>
      <origin xyz="0.01 0.184352 -0.385156" rpy="0 0 0"/>
      <geometry>
        <mesh filename="model://cer/meshes/stl/sim_cer_r_hand_thumb_prt.stl" scale="0.001 0.001 0.001"/>
      </geometry>
    </collision>
  </link>
  <joint name="r_hand_thumb_joint" type="revolute">
    <origin xyz="0 0.018648 -0.042844" rpy="0 0 0"/>
    <axis xyz="-1.0 0.0 0.0"/>
    <parent link="r_hand_root"/>
    <child link="r_hand_thumb"/>
    <limit effort="50000" lower="0.0" upper="1.2217304763960306" velocity="50000"/>
    <dynamics damping="1.0"/>
  </joint>
  <link name="r_hand_thumb_tip"/>
  <joint name="r_hand_thumb_tip_fixed_joint" type="fixed">
    <origin xyz="0 0.051386 -0.045893" rpy="0 1.221730955967806 1.5707963267948957"/>
    <parent link="r_hand_thumb"/>
    <child link="r_hand_thumb_tip"/>
    <dynamics damping="0.1"/>
  </joint>
  <link name="neck">
    <inertial>
      <origin xyz="0.0056578 -0.000646677 0.06232" rpy="0 0 0"/>
      <mass value="0.5"/>
      <inertia ixx="0.00110442" ixy="0.0" ixz="-6.96774e-05" iyy="0.00111727" iyz="0.0" izz="0.000112854"/>
    </inertial>
    <visual>
      <origin xyz="0.02 -0.000646677 -1.0" rpy="0 0 0"/>
      <geometry>
        <mesh filename="model://cer/meshes/stl/sim_cer_neck_prt.stl" scale="0.001 0.001 0.001"/>
      </geometry>
      <material name="blue"/>
    </visual>
    <collision>
      <origin xyz="0.02 -0.000646677 -1.0" rpy="0 0 0"/>
      <geometry>
        <mesh filename="model://cer/meshes/stl/sim_cer_neck_prt.stl" scale="0.001 0.001 0.001"/>
      </geometry>
    </collision>
  </link>
  <joint name="neck_pitch" type="revolute">
    <origin xyz="-0.094 0.000646677 0.37" rpy="0 0 0"/>
    <axis xyz="0.0 1.0 0.0"/>
    <parent link="torso_chest"/>
    <child link="neck"/>
    <limit effort="50000" lower="-0.5235987755982988" upper="1.3962634015954636" velocity="50000"/>
    <dynamics damping="1.0"/>
  </joint>
  <link name="head">
    <inertial>
      <origin xyz="0.04865391 -1.77681e-06 -0.00409" rpy="0 0 0"/>
      <mass value="2.0"/>
      <inertia ixx="0.0133792" ixy="-1.68274e-07" ixz="0.000330609" iyy="0.00439722" iyz="0.0" izz="0.0119116"/>
    </inertial>
    <visual>
      <origin xyz="0.00832051 0 -1.15838" rpy="0 0 0"/>
      <geometry>
        <mesh filename="model://cer/meshes/stl/sim_cer_head_prt.stl" scale="0.001 0.001 0.001"/>
      </geometry>
      <material name="head_color">
        <color rgba="0.368932 0.368932 0.368932 1.0"/>
      </material>
    </visual>
    <collision>
      <origin xyz="0.00832051 0 -1.15838" rpy="0 0 0"/>
      <geometry>
        <mesh filename="model://cer/meshes/stl/sim_cer_head_prt.stl" scale="0.001 0.001 0.001"/>
      </geometry>
    </collision>
  </link>
  <joint name="neck_yaw" type="revolute">
    <origin xyz="0.01167949 -0.000646677 0.15838" rpy="0 0 0"/>
    <axis xyz="0.173648 0.0 0.984808"/>
    <parent link="neck"/>
    <child link="head"/>
    <limit effort="50000" lower="-1.3962634015954636" upper="1.3962634015954636" velocity="50000"/>
    <dynamics damping="1.0"/>
  </joint>
  <link name="asus_xtion"/>
  <joint name="asus_xtion_fixed_joint" type="fixed">
    <origin xyz="0.07702051 0 0.04662" rpy="0 0 0"/>
    <parent link="head"/>
    <child link="asus_xtion"/>
    <dynamics damping="0.1"/>
  </joint>
  <link name="right_camera"/>
  <joint name="right_camera_fixed_joint" type="fixed">
    <origin xyz="0.06682051 -0.0325 -0.06838" rpy="0 0 0"/>
    <parent link="head"/>
    <child link="right_camera"/>
    <dynamics damping="0.1"/>
  </joint>
  <link name="left_camera"/>
  <joint name="left_camera_fixed_joint" type="fixed">
    <origin xyz="0.06682051 0.0325 -0.06838" rpy="0 0 0"/>
    <parent link="head"/>
    <child link="left_camera"/>
    <dynamics damping="0.1"/>
  </joint>
  <link name="gaze"/>
  <joint name="gaze_fixed_joint" type="fixed">
    <origin xyz="0 0 0" rpy="0 0 0"/>
    <parent link="head"/>
    <child link="gaze"/>
    <dynamics damping="0.1"/>
  </joint>
  <gazebo reference="head">
    <sensor name="left_camera" type="camera">
      <always_on>1</always_on>
      <update_rate>30</update_rate>
      <pose>0.06682051 0.0325 -0.06838 0.0 -0.0 0.0</pose>
      <camera>
    <horizontal_fov>1.5708</horizontal_fov>
    <image>
        <width>320</width>
        <height>240</height>
    </image>
    <clip>
        <near>0.1</near>
        <far>100</far>
    </clip>
</camera>
      <plugin filename="libgazebo_yarp_camera.so" name="left_camera_plugin">
    <yarpConfigurationFile>model://cer/conf/gazebo_cer_left_camera.ini</yarpConfigurationFile>
</plugin>
    </sensor>
  </gazebo>
  <gazebo reference="head">
    <sensor name="right_camera" type="camera">
      <always_on>1</always_on>
      <update_rate>30</update_rate>
      <pose>0.06682051 -0.0325 -0.06838 0.0 -0.0 0.0</pose>
      <camera>
    <horizontal_fov>1.5708</horizontal_fov>
    <image>
        <width>320</width>
        <height>240</height>
    </image>
    <clip>
        <near>0.1</near>
        <far>100</far>
    </clip>
</camera>
      <plugin filename="libgazebo_yarp_camera.so" name="right_camera_plugin">
    <yarpConfigurationFile>model://cer/conf/gazebo_cer_right_camera.ini</yarpConfigurationFile>
</plugin>
    </sensor>
  </gazebo>
  <gazebo reference="head">
    <sensor name="asus_xtion" type="depth">
      <always_on>1</always_on>
      <update_rate>30</update_rate>
      <pose>0.07702051 0.0 0.04662 0.0 -0.0 0.0</pose>
      <camera>
    <horizontal_fov>1.3962634</horizontal_fov>
    <image>
        <width>320</width>
        <height>240</height>
        <format>R8G8B8</format>
    </image>
    <clip>
        <near>0.02</near>
        <far>3000</far>
    </clip>
</camera>
      <plugin filename="libgazebo_yarp_depthCamera.so" name="depth_camera_plugin">
    <yarpConfigurationFile>model://cer/conf/gazebo_cer_depthCamera.ini</yarpConfigurationFile>
</plugin>
    </sensor>
  </gazebo>
  <gazebo>
<plugin name="controlboard_torso_yaw" filename="libgazebo_yarp_controlboard.so">
  <yarpConfigurationFile>model://cer/conf/gazebo_cer_torso_yaw.ini</yarpConfigurationFile>
</plugin>

<!-- TORSO user view -->
<plugin name="controlboard_torso" filename="libgazebo_yarp_controlboard.so">
  <yarpConfigurationFile>model://cer/conf/gazebo_cer_torso.ini</yarpConfigurationFile>
</plugin>
<!-- TORSO low level view -->
<plugin name="controlboard_torso_tripod" filename="libgazeboTripod.so">
  <yarpConfigurationFile>model://cer/conf/gazebo_cer_torso_tripod.ini</yarpConfigurationFile>
</plugin>


<plugin name="controlboard_left_upper_arm" filename="libgazebo_yarp_controlboard.so">
  <yarpConfigurationFile>model://cer/conf/gazebo_cer_left_upper_arm.ini</yarpConfigurationFile>
</plugin>
<!-- LEFT WRIST user view -->  
<plugin name="controlboard_left_wrist" filename="libgazebo_yarp_controlboard.so">
  <yarpConfigurationFile>model://cer/conf/gazebo_cer_left_wrist.ini</yarpConfigurationFile>
</plugin>
<!-- LEFT WRIST low level view -->
<plugin name="controlboard_left_wrist_tripod" filename="libgazeboTripod.so">
  <yarpConfigurationFile>model://cer/conf/gazebo_cer_left_wrist_tripod.ini</yarpConfigurationFile>
</plugin>


<plugin name="controlboard_right_upper_arm" filename="libgazebo_yarp_controlboard.so">
  <yarpConfigurationFile>model://cer/conf/gazebo_cer_right_upper_arm.ini</yarpConfigurationFile>
</plugin>
<!-- RIGHT WRIST user view -->
<plugin name="controlboard_right_wrist" filename="libgazebo_yarp_controlboard.so">
  <yarpConfigurationFile>model://cer/conf/gazebo_cer_right_wrist.ini</yarpConfigurationFile>
</plugin>
<!-- RIGHT WRIST low level view -->
<plugin name="controlboard_right_wrist_tripod" filename="libgazeboTripod.so">
  <yarpConfigurationFile>model://cer/conf/gazebo_cer_right_wrist_tripod.ini</yarpConfigurationFile>
</plugin>


<plugin name="controlboard_head" filename="libgazebo_yarp_controlboard.so">
  <yarpConfigurationFile>model://cer/conf/gazebo_cer_head.ini</yarpConfigurationFile>
</plugin>

<plugin name="controlboard_left_hand" filename="libgazebo_yarp_controlboard.so">
  <yarpConfigurationFile>model://cer/conf/gazebo_cer_left_hand.ini</yarpConfigurationFile>
</plugin>

<plugin name="controlboard_right_hand" filename="libgazebo_yarp_controlboard.so">
  <yarpConfigurationFile>model://cer/conf/gazebo_cer_right_hand.ini</yarpConfigurationFile>
</plugin> 

<plugin name="controlboard_mobile_base" filename="libgazebo_yarp_controlboard.so">
  <yarpConfigurationFile>model://cer/conf/gazebo_cer_mobile_base.ini</yarpConfigurationFile>
</plugin>
<plugin name="controlboard_all" filename="libgazebo_yarp_controlboard.so">
  <yarpConfigurationFile>model://cer/conf/gazebo_cer_all.ini</yarpConfigurationFile>
</plugin>
</gazebo>
  <gazebo reference="mobile_base_l_wheel">
  <implicitSpringDamper>1</implicitSpringDamper>
</gazebo>
  <gazebo reference="mobile_base_r_wheel">
  <implicitSpringDamper>1</implicitSpringDamper>
</gazebo>
  <gazebo reference="torso_tripod_heave_eq">
  <implicitSpringDamper>1</implicitSpringDamper>
</gazebo>
  <gazebo reference="torso_tripod_roll_eq">
  <implicitSpringDamper>1</implicitSpringDamper>
</gazebo>
  <gazebo reference="torso_tripod_pitch_eq">
  <implicitSpringDamper>1</implicitSpringDamper>
</gazebo>
  <gazebo reference="torso_yaw">
  <implicitSpringDamper>1</implicitSpringDamper>
</gazebo>
  <gazebo reference="neck_pitch">
  <implicitSpringDamper>1</implicitSpringDamper>
</gazebo>
  <gazebo reference="neck_yaw">
  <implicitSpringDamper>1</implicitSpringDamper>
</gazebo>
  <gazebo reference="l_shoulder_pitch">
  <implicitSpringDamper>1</implicitSpringDamper>
</gazebo>
  <gazebo reference="l_shoulder_roll">
  <implicitSpringDamper>1</implicitSpringDamper>
</gazebo>
  <gazebo reference="l_shoulder_yaw">
  <implicitSpringDamper>1</implicitSpringDamper>
</gazebo>
  <gazebo reference="l_elbow">
  <implicitSpringDamper>1</implicitSpringDamper>
</gazebo>
  <gazebo reference="l_wrist_prosupination">
  <implicitSpringDamper>1</implicitSpringDamper>
</gazebo>
  <gazebo reference="l_wrist_tripod_heave_eq">
  <implicitSpringDamper>1</implicitSpringDamper>
</gazebo>
  <gazebo reference="l_wrist_tripod_roll_eq">
  <implicitSpringDamper>1</implicitSpringDamper>
</gazebo>
  <gazebo reference="l_wrist_tripod_pitch_eq">
  <implicitSpringDamper>1</implicitSpringDamper>
</gazebo>
  <gazebo reference="l_hand_paddle_joint">
  <implicitSpringDamper>1</implicitSpringDamper>
</gazebo>
  <gazebo reference="l_hand_thumb_joint">
  <implicitSpringDamper>1</implicitSpringDamper>
</gazebo>
  <gazebo reference="r_shoulder_pitch">
  <implicitSpringDamper>1</implicitSpringDamper>
</gazebo>
  <gazebo reference="r_shoulder_roll">
  <implicitSpringDamper>1</implicitSpringDamper>
</gazebo>
  <gazebo reference="r_shoulder_yaw">
  <implicitSpringDamper>1</implicitSpringDamper>
</gazebo>
  <gazebo reference="r_elbow">
  <implicitSpringDamper>1</implicitSpringDamper>
</gazebo>
  <gazebo reference="r_wrist_prosupination">
  <implicitSpringDamper>1</implicitSpringDamper>
</gazebo>
  <gazebo reference="r_wrist_tripod_heave_eq">
  <implicitSpringDamper>1</implicitSpringDamper>
</gazebo>
  <gazebo reference="r_wrist_tripod_roll_eq">
  <implicitSpringDamper>1</implicitSpringDamper>
</gazebo>
  <gazebo reference="r_wrist_tripod_pitch_eq">
  <implicitSpringDamper>1</implicitSpringDamper>
</gazebo>
  <gazebo reference="r_hand_paddle_joint">
  <implicitSpringDamper>1</implicitSpringDamper>
</gazebo>
  <gazebo reference="r_hand_thumb_joint">
  <implicitSpringDamper>1</implicitSpringDamper>
</gazebo>
</robot>
