<?xml version=1.0 ?>
<sdf version='1.6'>
  <model name='SIM_CER_ROBOT'>
    <link name='mobile_base_body_link'>
      <pose frame=''>0 0 0 0 -0 0</pose>
      <inertial>
        <pose frame=''>0.003532 0 0.062803 0 -0 0</pose>
        <mass>14</mass>
        <inertia>
          <ixx>0.342401</ixx>
          <ixy>0</ixy>
          <ixz>-0.0396992</ixz>
          <iyy>0.362542</iyy>
          <iyz>0</iyz>
          <izz>0.168981</izz>
        </inertia>
      </inertial>
      <collision name='mobile_base_body_link_collision'>
        <pose frame=''>0 0 -0.16 0 -0 0</pose>
        <geometry>
          <mesh>
            <scale>0.001 0.001 0.001</scale>
            <uri>model://cer/meshes/obj/sim_cer_mobilebase_body.obj</uri>
          </mesh>
        </geometry>
        <surface>
          <contact>
            <ode/>
          </contact>
          <friction>
            <ode>
              <mu>0</mu>
              <mu2>0</mu2>
            </ode>
          </friction>
        </surface>
      </collision>
      <visual name='mobile_base_body_link_visual'>
        <pose frame=''>0 0 -0.16 0 -0 0</pose>
        <geometry>
          <mesh>
            <scale>0.001 0.001 0.001</scale>
            <uri>model://cer/meshes/obj/sim_cer_mobilebase_body.obj</uri>
          </mesh>
        </geometry>
        <material>
          <script>
            <uri>__default__</uri>
            <name>__default__</name>
          </script>
        </material>
      </visual>
      <velocity_decay/>
      <sensor name='base_laser' type='ray'>
        <always_on>1</always_on>
        <update_rate>40</update_rate>
        <pose frame=''>0.00 0 0.38 0 -0 0</pose>
        <visualize>true</visualize>
        <ray>
          <scan>
            <horizontal>
              <samples>360</samples>
              <resolution>2</resolution>
              <min_angle>0</min_angle>
              <max_angle>6.28</max_angle>
            </horizontal>
          </scan>
          <range>
            <min>0.04</min>
            <max>5</max>
            <resolution>0.01</resolution>
          </range>
          <noise>
            <type>gaussian</type>
            <mean>0</mean>
            <stddev>0.005</stddev>
          </noise>
        </ray>
        <plugin name='laser_sensor' filename='libgazebo_yarp_lasersensor.so'>
          <yarpConfigurationFile>model://cer/conf/gazebo_cer_lasersensor/gazebo_cer_lasersensor360.ini</yarpConfigurationFile>
        </plugin>
      </sensor>    
      <gravity>1</gravity>
      <velocity_decay/>
    </link>
    <link name='mobile_base_l_tyre_link'>
      <pose frame=''>0 0.139 0 0 -0 0</pose>
      <inertial>
        <pose frame=''>0 0.034425 9e-06 0 -0 0</pose>
        <mass>3</mass>
        <inertia>
          <ixx>0.0200196</ixx>
          <ixy>0</ixy>
          <ixz>0</ixz>
          <iyy>0.0376169</iyy>
          <iyz>-8.28446e-07</iyz>
          <izz>0.0200156</izz>
        </inertia>
      </inertial>
      <collision name='mobile_base_l_tyre_link_collision'>
        <pose frame=''>0 0.03 0 1.5708 -0 0</pose>
        <geometry>
          <cylinder>
            <length>0.005</length>
            <radius>0.16</radius>
          </cylinder>
        </geometry>
      </collision>
      <visual name='mobile_base_l_tyre_link_visual'>
        <pose frame=''>0 -0.139 -0.16 0 -0 0</pose>
        <geometry>
          <mesh>
            <scale>0.001 0.001 0.001</scale>
            <uri>model://cer/meshes/dae/sim_cer_mobilebase_l_tyre.dae</uri>
          </mesh>
        </geometry>
      </visual>
    </link>
    <joint name='mobile_base_l_wheel_joint' type='revolute'>
      <child>mobile_base_l_tyre_link</child>
      <parent>mobile_base_body_link</parent>
      <axis>
        <xyz>0 1 0</xyz>
        <limit>
          <lower>-1e+16</lower>
          <upper>1e+16</upper>
        </limit>
        <dynamics>
          <damping>0.5</damping>
          <friction>0</friction>
          <spring_reference>0</spring_reference>
          <spring_stiffness>0</spring_stiffness>
        </dynamics>
        <use_parent_model_frame>1</use_parent_model_frame>
      </axis>
      <physics>
        <ode>
          <implicit_spring_damper>1</implicit_spring_damper>
          <cfm_damping>1</cfm_damping>
          <limit>
            <cfm>0</cfm>
            <erp>0.2</erp>
          </limit>
        </ode>
      </physics>
    </joint>
    <link name='mobile_base_r_tyre_link'>
      <pose frame=''>0 -0.139 0 0 -0 0</pose>
      <inertial>
        <pose frame=''>0 -0.034425 9e-06 0 -0 0</pose>
        <mass>3</mass>
        <inertia>
          <ixx>0.0200196</ixx>
          <ixy>0</ixy>
          <ixz>0</ixz>
          <iyy>0.0376169</iyy>
          <iyz>8.28101e-07</iyz>
          <izz>0.0200156</izz>
        </inertia>
      </inertial>
      <collision name='mobile_base_r_tyre_link_collision'>
        <pose frame=''>0 -0.03 0 1.5708 -0 0</pose>
        <geometry>
          <cylinder>
            <length>0.005</length>
            <radius>0.16</radius>
          </cylinder>
        </geometry>
      </collision>
      <visual name='mobile_base_r_tyre_link_visual'>
        <pose frame=''>0 0.139 -0.16 0 -0 0</pose>
        <geometry>
          <mesh>
            <scale>0.001 0.001 0.001</scale>
            <uri>model://cer/meshes/dae/sim_cer_mobilebase_r_tyre.dae</uri>
          </mesh>
        </geometry>
      </visual>
    </link>
    <joint name='mobile_base_r_wheel_joint' type='revolute'>
      <child>mobile_base_r_tyre_link</child>
      <parent>mobile_base_body_link</parent>
      <axis>
        <xyz>0 1 0</xyz>
        <limit>
          <lower>-1e+16</lower>
          <upper>1e+16</upper>
        </limit>
        <dynamics>
          <damping>0.5</damping>
          <friction>0</friction>
          <spring_reference>0</spring_reference>
          <spring_stiffness>0</spring_stiffness>
        </dynamics>
        <use_parent_model_frame>1</use_parent_model_frame>
      </axis>
      <physics>
        <ode>
          <implicit_spring_damper>1</implicit_spring_damper>
          <cfm_damping>1</cfm_damping>
          <limit>
            <cfm>0</cfm>
            <erp>0.2</erp>
          </limit>
        </ode>
      </physics>
    </joint>

    <plugin name='controlboard_mobile_base' filename='libgazebo_yarp_controlboard.so'>
      <yarpConfigurationFile>model://cer/conf/gazebo_cer_mobile_base/gazebo_cer_mobile_base.ini</yarpConfigurationFile>
    </plugin>
    <plugin name='world_interface' filename='libgazebo_yarp_worldinterface.so'>
      <yarpConfigurationFile>model://cer/conf/worldInterface.ini</yarpConfigurationFile>
    </plugin>
    <plugin name="robotinterface" filename="libgazebo_yarp_robotinterface.so">
      <yarpRobotInterfaceConfigurationFile>model://cer_base_only360/cer_base_only360.xml</yarpRobotInterfaceConfigurationFile>
    </plugin>
    <static>0</static>
    <pose frame=''>0 0 0.16 0 -0 0</pose>
  </model>
</sdf>
