<?xml version = '1.0' ?>
<sdf version = '1.0'>
    <model name = "cart">

        <static>false</static>
        <link name = 'mobile_base_body'>
            <pose> 0 0 .1  0 0 0 </pose>
            <inertial>
                <mass>75</mass>
            </inertial>

            <collision name = 'table_top_collision'>
            <pose> 0 0 0.7 0 0 0 </pose>
                <geometry>
                    <box>
                        <size> 0.5 0.5 0.03 </size>
                    </box>
                </geometry>
            </collision>
            <collision name = 'handle_collision'>
                <pose> 0 -0.35 0.6 0 1.57 0 </pose>
                <geometry>
                    <cylinder>
                        <radius>0.0125 </radius>
                        <length>0.7 </length>
                    </cylinder>
                </geometry>
            </collision>
            <collision name = 'handle_left_collision'>
                <pose> 0.35 -0.35 0.6 0 1.57 0 </pose>
                <geometry>
                    <cylinder>
                        <radius>0.05 </radius>
                        <length>0.015 </length>
                    </cylinder>
                </geometry>
            </collision>
            <collision name = 'handle_right_collision'>
                <pose> -0.35 -0.35 0.6 0 1.57 0 </pose>
                <geometry>
                    <cylinder>
                        <radius>0.05 </radius>
                        <length>0.015 </length>
                    </cylinder>
                </geometry>
            </collision>

            <visual name = 'table_bottom'>
                <pose> 0 0 0 0 0 0 </pose>
                <geometry>
                    <box>
                        <size> 0.5 0.5 0.03 </size>
                    </box>
                </geometry>
            </visual>
            <visual name = 'table_middle'>
                <pose> 0 0 0.35 0 0 0 </pose>
                <geometry>
                    <box>
                        <size> 0.5 0.5 0.03 </size>
                    </box>
                </geometry>
            </visual>
            <visual name = 'table_top'>
                <pose> 0 0 0.7 0 0 0 </pose>
                <geometry>
                    <box>
                        <size> 0.5 0.5 0.03 </size>
                    </box>
                </geometry>
            </visual>
            <visual name = 'c1'>
                <pose> 0.21 0.21 0.35 0 0 0 </pose>
                <geometry>
                    <box>
                        <size> 0.04 0.04 0.7 </size>
                    </box>
                </geometry>
            </visual>
            <visual name = 'c2'>
                <pose> 0.21 -0.21 0.35 0 0 0 </pose>
                <geometry>
                    <box>
                        <size> 0.04 0.04 0.7 </size>
                    </box>
                </geometry>
            </visual>
            <visual name = 'c3'>
                <pose> -0.21 0.21 0.35 0 0 0 </pose>
                <geometry>
                    <box>
                        <size> 0.04 0.04 0.7 </size>
                    </box>
                </geometry>
            </visual>
            <visual name = 'c4'>
                <pose> -0.21 -0.21 0.35 0 0 0 </pose>
                <geometry>
                    <box>
                        <size> 0.04 0.04 0.7 </size>
                    </box>
                </geometry>
            </visual>
            <visual name = 'handle'>
                <pose> 0 -0.35 0.6 0 1.57 0 </pose>
                <geometry>
                    <cylinder>
                        <radius>0.0125 </radius>
                        <length>0.7 </length>
                    </cylinder>
                </geometry>
            </visual>
       <!--     <visual name = 'handle_left'>
                <pose> 0.35 -0.35 0.6 0 1.57 0 </pose>
                <geometry>
                    <cylinder>
                        <radius>0.05 </radius>
                        <length>0.015 </length>
                    </cylinder>
                </geometry>
            </visual>
            <visual name = 'handle_right'>
                <pose> -0.35 -0.35 0.6 0 1.57 0 </pose>
                <geometry>
                    <cylinder>
                        <radius>0.05 </radius>
                        <length>0.015 </length>
                    </cylinder>
                </geometry>
            </visual> -->
            <visual name = 'h1'>
                <pose> -0.21 -0.28 0.6 1.57 0 0 </pose>
                <geometry>
                    <cylinder>
                        <radius>0.0125 </radius>
                        <length>0.15 </length>
                    </cylinder>
                </geometry>
            </visual>
            <visual name = 'h2'>
                <pose> 0.21 -0.28 0.6 1.57 0 0 </pose>
                <geometry>
                    <cylinder>
                        <radius>0.0125 </radius>
                        <length>0.15 </length>
                    </cylinder>
                </geometry>
            </visual>
            
            <visual name = 'sphere1'>
                <pose> 0.21 0.21 -0.06 0 0 0 </pose>
                <geometry>
                    <sphere>
                        <radius> 0.04 </radius>
                    </sphere>
                </geometry>
            </visual>
            <visual name = 'sphere2'>
                <pose> -0.21 -0.21 -0.06 0 0 0 </pose>
                <geometry>
                    <sphere>
                        <radius> 0.04 </radius>
                    </sphere>
                </geometry>
            </visual>
            <visual name = 'sphere3'>
                <pose> 0.21 -0.21 -0.06 0 0 0 </pose>
                <geometry>
                    <sphere>
                        <radius> 0.04 </radius>
                    </sphere>
                </geometry>
            </visual>
            <visual name = 'sphere4'>
                <pose> -0.21 0.21 -0.06 0 0 0 </pose>
                <geometry>
                    <sphere>
                        <radius> 0.04 </radius>
                    </sphere>
                </geometry>
            </visual>
        </link>


        <link name = 'a_wheel'>
            <pose> -0.273 0 0.0625 0 -1.5707 0 </pose>
            <collision name ='a_wheel_collision'>
                <geometry>
                    <cylinder>
                        <radius> .0625 </radius>
                        <length> .001 </length>
                    </cylinder>
                </geometry>
                <surface>
                    <friction>
                        <ode>
                            <fdir1>0 0 1</fdir1>
                            <mu>0.0005</mu>
                            <mu2>0.8</mu2>
                        </ode>
                    </friction>
                </surface>
            </collision>     
           <!-- <visual name = 'a_wheel_visual'>
                <geometry>
                    <cylinder>
                        <radius> .0625 </radius>
                        <length> .025 </length>
                    </cylinder>
                </geometry>
            </visual> -->
        </link>

        <link name = 'b_wheel'>
            <pose> 0.1365 0.2364 0.0625 0 1.5707 1.0472 </pose>
            <collision name ='b_wheel_collision'>
                <geometry>
                    <cylinder>
                        <radius> .0625 </radius>
                        <length> .001 </length>
                    </cylinder>
                </geometry>
                <surface>
                    <friction>
                        <ode>
                            <fdir1>0 0 1</fdir1>
                            <mu>0.0005</mu>
                            <mu2>0.8</mu2>
                        </ode>
                    </friction>
                </surface>
            </collision>
            <!-- <visual name = 'b_wheel_visual'>
                <geometry>
                    <cylinder>
                        <radius> .0625 </radius>
                        <length> .025 </length>
                    </cylinder>
                </geometry> 
            </visual> -->
        </link>

        <link name = 'c_wheel'>
            <pose> 0.1365 -0.2364 0.0625 0 1.5707 -1.0472 </pose>
            <collision name ='c_wheel_collision'>
                <geometry>
                    <cylinder>
                        <radius> .0625 </radius>
                        <length> .001 </length>
                    </cylinder>
                </geometry>
                <surface>
                    <friction>
                        <ode>
                            <fdir1>0 0 1</fdir1>
                            <mu>0.0005</mu>
                            <mu2>0.8</mu2>
                        </ode>
                    </friction>
                </surface>
            </collision>     
            <!-- <visual name = 'c_wheel_visual'>
                <geometry>
                    <cylinder>
                        <radius> .0625 </radius>
                        <length> .025 </length>
                    </cylinder>
                </geometry>
            </visual> -->
        </link>

        <joint name='a_wheel_joint' type='revolute'>
            <child>a_wheel</child>
            <parent>mobile_base_body</parent>
            <axis>
                <xyz>0 0 1</xyz>
                <limit>
                    <effort>30</effort>
                    <velocity>50</velocity>
                </limit>
                <dynamics>
                    <damping>1</damping>
                    <friction>0</friction>
                    <spring_reference>0</spring_reference>
                    <spring_stiffness>0</spring_stiffness>
                </dynamics>
                <use_parent_model_frame>0</use_parent_model_frame>
            </axis>
            <physics>
                <ode>
                    <implicit_spring_damper>1</implicit_spring_damper>
                    <cfm_damping>1</cfm_damping>
                    <limit>
                        <cfm>0</cfm>
                        <erp>0.2</erp>
                    </limit>
                </ode>
            </physics>
        </joint>


        <joint name='b_wheel_joint' type='revolute'>
            <child>b_wheel</child>
            <parent>mobile_base_body</parent>
            <axis>
                <xyz>0 0 1</xyz>
                <limit>
                    <effort>30</effort>
                    <velocity>50</velocity>
                </limit>
                <dynamics>
                    <damping>1</damping>
                    <friction>0</friction>
                    <spring_reference>0</spring_reference>
                    <spring_stiffness>0</spring_stiffness>
                </dynamics>
                <use_parent_model_frame>0</use_parent_model_frame>
            </axis>
            <physics>
                <ode>
                    <implicit_spring_damper>1</implicit_spring_damper>
                    <cfm_damping>1</cfm_damping>
                    <limit>
                        <cfm>0</cfm>
                        <erp>0.2</erp>
                    </limit>
                </ode>
            </physics>
        </joint>

        <joint name='c_wheel_joint' type='revolute'>
            <child>c_wheel</child>
            <parent>mobile_base_body</parent>
            <axis>
                <xyz> 0 0 1</xyz>
                <limit>
                    <effort>30</effort>
                    <velocity>50</velocity>
                </limit>
                <dynamics>
                    <damping>1</damping>
                    <friction>0</friction>
                    <spring_reference>0</spring_reference>
                    <spring_stiffness>0</spring_stiffness>
                </dynamics>
                <use_parent_model_frame>0</use_parent_model_frame>
            </axis>
            <physics>
                <ode>
                    <implicit_spring_damper>1</implicit_spring_damper>
                    <cfm_damping>1</cfm_damping>
                    <limit>
                        <cfm>0</cfm>
                        <erp>0.2</erp>
                    </limit>
                </ode>
            </physics>
        </joint>


    </model>
</sdf>
